<?xml version="1.0" ?>
<robot name="sloan" xmlns:xacro="http://www.ros.org/wiki/xacro">

<xacro:include filename="$(find sloan_description)/urdf/materials.xacro" />
<xacro:include filename="$(find sloan_description)/urdf/sloan.trans" />
<!-- <xacro:include filename="$(find sloan_description)/urdf/sloan.gazebo" /> -->
<link name="base_link">
  <inertial>
    <origin xyz="8.613621438953387e-16 0.0 0.006315916409147712" rpy="0 0 0"/>
    <mass value="0.35992295303903776"/>
    <inertia ixx="0.000606" iyy="0.000606" izz="0.001181" ixy="0.0" iyz="0.0" ixz="0.0"/>
  </inertial>
  <visual>
    <origin xyz="0 0 0" rpy="0 0 0"/>
    <geometry>
      <mesh filename="package://sloan_description/meshes/base_link.stl" scale="0.001 0.001 0.001"/>
    </geometry>
    <material name="silver"/>
  </visual>
  <collision>
    <origin xyz="0 0 0" rpy="0 0 0"/>
    <geometry>
      <mesh filename="package://sloan_description/meshes/base_link.stl" scale="0.001 0.001 0.001"/>
    </geometry>
  </collision>
</link>

<link name="01_Modular_joint_v2_1">
  <inertial>
    <origin xyz="-5.685106769771774e-17 -0.0012801722364952173 -0.0887198630073406" rpy="0 0 0"/>
    <mass value="1.1806411332101794"/>
    <inertia ixx="0.003504" iyy="0.003454" izz="0.001712" ixy="0.0" iyz="-4.5e-05" ixz="-0.0"/>
  </inertial>
  <visual>
    <origin xyz="-0.0 -0.0 -0.0" rpy="0 0 0"/>
    <geometry>
      <mesh filename="package://sloan_description/meshes/01_Modular_joint_v2_1.stl" scale="0.001 0.001 0.001"/>
    </geometry>
    <material name="silver"/>
  </visual>
  <collision>
    <origin xyz="-0.0 -0.0 -0.0" rpy="0 0 0"/>
    <geometry>
      <mesh filename="package://sloan_description/meshes/01_Modular_joint_v2_1.stl" scale="0.001 0.001 0.001"/>
    </geometry>
  </collision>
</link>

<link name="02_big_segment_v1_Component_MESH_v1_1">
  <inertial>
    <origin xyz="-4.3520742565306136e-16 -0.05000000019395925 -0.18249999999999966" rpy="0 0 0"/>
    <mass value="3.0347768251666976"/>
    <inertia ixx="0.101506" iyy="0.101745" izz="0.005289" ixy="0.0" iyz="-0.0" ixz="-0.0"/>
  </inertial>
  <visual>
    <origin xyz="0.0 0.052 0.1185" rpy="0 0 0"/>
    <geometry>
      <mesh filename="package://sloan_description/meshes/02_big_segment_v1_Component_MESH_v1_1.stl" scale="0.001 0.001 0.001"/>
    </geometry>
    <material name="silver"/>
  </visual>
  <collision>
    <origin xyz="0.0 0.052 0.1185" rpy="0 0 0"/>
    <geometry>
      <mesh filename="package://sloan_description/meshes/02_big_segment_v1_Component_MESH_v1_1.stl" scale="0.001 0.001 0.001"/>
    </geometry>
  </collision>
</link>

<link name="03_modular_v2_1">
  <inertial>
    <origin xyz="-4.1179594189214495e-16 0.05071982776350518 0.029780136992659856" rpy="0 0 0"/>
    <mass value="0.9358740690080692"/>
    <inertia ixx="0.002778" iyy="0.002738" izz="0.001357" ixy="0.0" iyz="-3.6e-05" ixz="-0.0"/>
  </inertial>
  <visual>
    <origin xyz="0.0 0.052 0.4835" rpy="0 0 0"/>
    <geometry>
      <mesh filename="package://sloan_description/meshes/03_modular_v2_1.stl" scale="0.001 0.001 0.001"/>
    </geometry>
    <material name="silver"/>
  </visual>
  <collision>
    <origin xyz="0.0 0.052 0.4835" rpy="0 0 0"/>
    <geometry>
      <mesh filename="package://sloan_description/meshes/03_modular_v2_1.stl" scale="0.001 0.001 0.001"/>
    </geometry>
  </collision>
</link>

<link name="04_2nd_segment__MESH_v1_1">
  <inertial>
    <origin xyz="4.4160290535444345e-10 8.496675363289796e-11 0.24324948338696065" rpy="0 0 0"/>
    <mass value="1.2629885104687113"/>
    <inertia ixx="0.008138" iyy="0.00823" izz="0.002194" ixy="0.0" iyz="0.0" ixz="-0.0"/>
  </inertial>
  <visual>
    <origin xyz="0.0 -0.0 0.365" rpy="0 0 0"/>
    <geometry>
      <mesh filename="package://sloan_description/meshes/04_2nd_segment__MESH_v1_1.stl" scale="0.001 0.001 0.001"/>
    </geometry>
    <material name="silver"/>
  </visual>
  <collision>
    <origin xyz="0.0 -0.0 0.365" rpy="0 0 0"/>
    <geometry>
      <mesh filename="package://sloan_description/meshes/04_2nd_segment__MESH_v1_1.stl" scale="0.001 0.001 0.001"/>
    </geometry>
  </collision>
</link>

<link name="05_jointt_v2_1">
  <inertial>
    <origin xyz="-0.029780136992659734 -0.050719827763503936 5.273559366969494e-16" rpy="0 0 0"/>
    <mass value="0.7774953804067037"/>
    <inertia ixx="0.001128" iyy="0.002274" izz="0.002308" ixy="-3e-05" iyz="-0.0" ixz="-0.0"/>
  </inertial>
  <visual>
    <origin xyz="0.0 0.05 0.097" rpy="0 0 0"/>
    <geometry>
      <mesh filename="package://sloan_description/meshes/05_jointt_v2_1.stl" scale="0.001 0.001 0.001"/>
    </geometry>
    <material name="silver"/>
  </visual>
  <collision>
    <origin xyz="0.0 0.05 0.097" rpy="0 0 0"/>
    <geometry>
      <mesh filename="package://sloan_description/meshes/05_jointt_v2_1.stl" scale="0.001 0.001 0.001"/>
    </geometry>
  </collision>
</link>

<link name="06_end_effector_MESH_v1_1">
  <inertial>
    <origin xyz="-0.10737661503148149 4.918640968629151e-05 -5.7383148094572456e-05" rpy="0 0 0"/>
    <mass value="0.9144999769378596"/>
    <inertia ixx="0.001589" iyy="0.004541" izz="0.003483" ixy="-1e-06" iyz="-1e-06" ixz="7e-06"/>
  </inertial>
  <visual>
    <origin xyz="0.1185 0.102 0.097" rpy="0 0 0"/>
    <geometry>
      <mesh filename="package://sloan_description/meshes/06_end_effector_MESH_v1_1.stl" scale="0.001 0.001 0.001"/>
    </geometry>
    <material name="silver"/>
  </visual>
  <collision>
    <origin xyz="0.1185 0.102 0.097" rpy="0 0 0"/>
    <geometry>
      <mesh filename="package://sloan_description/meshes/06_end_effector_MESH_v1_1.stl" scale="0.001 0.001 0.001"/>
    </geometry>
  </collision>
</link>

<joint name="Revolute 1" type="continuous">
  <origin xyz="0.0 0.0 0.0" rpy="0 0 0"/>
  <parent link="base_link"/>
  <child link="01_Modular_joint_v2_1"/>
  <axis xyz="0.0 0.0 -1.0"/>
</joint>

<joint name="Revolute 2" type="continuous">
  <origin xyz="-0.0 -0.052 -0.1185" rpy="0 0 0"/>
  <parent link="01_Modular_joint_v2_1"/>
  <child link="02_big_segment_v1_Component_MESH_v1_1"/>
  <axis xyz="0.0 -1.0 0.0"/>
</joint>

<joint name="Revolute 3" type="continuous">
  <origin xyz="0.0 0.0 -0.365" rpy="0 0 0"/>
  <parent link="02_big_segment_v1_Component_MESH_v1_1"/>
  <child link="03_modular_v2_1"/>
  <axis xyz="-0.0 1.0 -0.0"/>
</joint>

<joint name="Revolute 4" type="continuous">
  <origin xyz="0.0 0.052 0.1185" rpy="0 0 0"/>
  <parent link="03_modular_v2_1"/>
  <child link="04_2nd_segment__MESH_v1_1"/>
  <axis xyz="-0.0 0.0 1.0"/>
</joint>

<joint name="Revolute 5" type="continuous">
  <origin xyz="0.0 -0.05 0.268" rpy="0 0 0"/>
  <parent link="04_2nd_segment__MESH_v1_1"/>
  <child link="05_jointt_v2_1"/>
  <axis xyz="0.0 -1.0 0.0"/>
</joint>

<joint name="Revolute 6" type="continuous">
  <origin xyz="-0.1185 -0.052 0.0" rpy="0 0 0"/>
  <parent link="05_jointt_v2_1"/>
  <child link="06_end_effector_MESH_v1_1"/>
  <axis xyz="-1.0 -0.0 -0.0"/>
</joint>

</robot>
