<?xml version="1.0" ?>
<!-- =================================================================================== -->
<!-- |    This document was autogenerated by xacro from astra.urdf.xacro               | -->
<!-- |    EDITING THIS FILE BY HAND IS NOT RECOMMENDED                                 | -->
<!-- =================================================================================== -->
<robot name="astra">
  <!-- ======================================================================================================================== -->
  <!-- ==========CONSANTS========== -->
  <!-- base_link is rover -->
  <!-- ======================================================================================================================== -->
  <!-- ==========LINKS========== -->
  <!-- base_link -->
  <link name="base_link">
    <visual>
      <geometry>
        <box size="0.6 0.5 0.16125"/>
      </geometry>
      <origin xyz="0 0 0"/>
    </visual>
    <collision>
      <geometry>
        <box size="0.6 0.5 0.16125"/>
      </geometry>
      <origin xyz="0 0 0"/>
    </collision>

    <inertial>
      <mass value="0.1" />
      <origin xyz="0 0 0" rpy="0 0 0" />
       <inertia ixx="0.001" ixy="0" ixz="0" iyy="0.001" iyz="0" izz="0.001" />
    </inertial>

  </link>
  <!-- link1 -->
  <link name="link1">
    <visual>
      <geometry>
        <box size="0.08 0.1505 0.138"/>
      </geometry>
      <origin xyz="0 -0.018750000000000003 0.069"/>
    </visual>
    <collision>
      <geometry>
        <box size="0.08 0.1505 0.138"/>
      </geometry>
      <origin xyz="0 -0.018750000000000003 0.069"/>
    </collision>

    <inertial>
      <mass value="100" />
      <origin xyz="0 0 0" rpy="0 0 0" />
       <inertia ixx="0.001" ixy="0" ixz="0" iyy="0.001" iyz="0" izz="0.001" />
    </inertial>


  </link>
  <!-- link2 -->
  <link name="link2">
    <visual>
      <geometry>
        <box size="0.096 0.07 0.487225"/>
      </geometry>
      <origin xyz="0 0 0.19561250000000002"/>
    </visual>
    <collision>
      <geometry>
        <box size="0.096 0.07 0.487225"/>
      </geometry>
      <origin xyz="0 0 0.19561250000000002"/>
    </collision>

    <inertial>
      <mass value="0.1" />
      <origin xyz="0 0 0" rpy="0 0 0" />
       <inertia ixx="0.001" ixy="0" ixz="0" iyy="0.001" iyz="0" izz="0.001" />
    </inertial>

  </link>
  <!-- motor_j3 -->
  <link name="motor_j3">
    <visual>
      <geometry>
        <box size="0.09 0.07 0.3"/>
      </geometry>
      <origin xyz="-0.084225 0 0.004388"/>
    </visual>
    <collision>
      <geometry>
        <box size="0.09 0.07 0.3"/>
      </geometry>
      <origin xyz="-0.084225 0 0.004388"/>
    </collision>

    <inertial>
      <mass value="0.1" />
      <origin xyz="0 0 0" rpy="0 0 0" />
       <inertia ixx="0.001" ixy="0" ixz="0" iyy="0.001" iyz="0" izz="0.001" />
    </inertial>

  </link>
  <!-- link3 -->
  <link name="link3">
    <visual>
      <geometry>
        <box size="0.115 0.112 0.387"/>
      </geometry>
      <origin xyz="-0.037500000000000006 0 0.10650000000000001"/>
    </visual>
    <collision>
      <geometry>
        <box size="0.115 0.112 0.387"/>
      </geometry>
      <origin xyz="-0.037500000000000006 0 0.10650000000000001"/>
    </collision>

    <inertial>
      <mass value="0.1" />
      <origin xyz="0 0 0" rpy="0 0 0" />
       <inertia ixx="0.001" ixy="0" ixz="0" iyy="0.001" iyz="0" izz="0.001" />
    </inertial>

  </link>
  <!-- link4 -->
  <link name="link4">
    <visual>
      <geometry>
        <box size="0.08 0.175 0.1208"/>
      </geometry>
      <origin xyz="0 0 0.0604"/>
    </visual>
    <collision>
      <geometry>
        <box size="0.08 0.175 0.1208"/>
      </geometry>
      <origin xyz="0 0 0.0604"/>
    </collision>

    <inertial>
      <mass value="0.1" />
      <origin xyz="0 0 0" rpy="0 0 0" />
       <inertia ixx="0.001" ixy="0" ixz="0" iyy="0.001" iyz="0" izz="0.001" />
    </inertial>


  </link>
  <!-- link5 -->
  <link name="link5">
    <visual>
      <geometry>
        <box size="0.045 0.045 0.09455"/>
      </geometry>
      <origin xyz="0 0 0.015474999999999996"/>
    </visual>
    <collision>
      <geometry>
        <box size="0.045 0.045 0.09455"/>
      </geometry>
      <origin xyz="0 0 0.015474999999999996"/>
    </collision>


    <inertial>
      <mass value="0.1" />
      <origin xyz="0 0 0" rpy="0 0 0" />
       <inertia ixx="0.001" ixy="0" ixz="0" iyy="0.001" iyz="0" izz="0.001" />
    </inertial>


  </link>
  <!-- gripper_base -->
  <link name="gripper_base">
    <visual>
      <geometry>
        <box size="0.1565 0.125 0.103"/>
      </geometry>
      <origin xyz="0.002250000000000002 -0.004600000000000007 -0.0965"/>
    </visual>
    <collision>
      <geometry>
        <box size="0.1565 0.125 0.103"/>
      </geometry>
      <origin xyz="0.002250000000000002 -0.004600000000000007 -0.0965"/>
    </collision>

    <inertial>
      <mass value="0.1" />
      <origin xyz="0 0 0" rpy="0 0 0" />
       <inertia ixx="0.001" ixy="0" ixz="0" iyy="0.001" iyz="0" izz="0.001" />
    </inertial>


  </link>
  <!-- gripper_left_finger -->
  <link name="gripper_left_finger">
    <visual>
      <geometry>
        <box size="0.0215 0.016 0.045"/>
      </geometry>
      <origin xyz="0 0.008 0.0225"/>
    </visual>
    <collision>
      <geometry>
        <box size="0.0215 0.016 0.045"/>
      </geometry>
      <origin xyz="0 0.008 0.0225"/>
    </collision>

    <inertial>
      <mass value="0.1" />
      <origin xyz="0 0 0" rpy="0 0 0" />
       <inertia ixx="0.001" ixy="0" ixz="0" iyy="0.001" iyz="0" izz="0.001" />
    </inertial>


  </link>
  <!-- gripper_right_finger -->
  <link name="gripper_right_finger">
    <visual>
      <geometry>
        <box size="0.0215 0.016 0.045"/>
      </geometry>
      <origin xyz="0 -0.008 0.0225"/>
    </visual>
    <collision>
      <geometry>
        <box size="0.0215 0.016 0.045"/>
      </geometry>
      <origin xyz="0 -0.008 0.0225"/>
    </collision>

    <inertial>
      <mass value="0.1" />
      <origin xyz="0 0 0" rpy="0 0 0" />
       <inertia ixx="0.001" ixy="0" ixz="0" iyy="0.001" iyz="0" izz="0.001" />
    </inertial>


  </link>
  <!-- ======================================================================================================================== -->
  <!-- ==========JOINTS========== -->
  <!-- joint1 -->
  <joint name="joint1" type="revolute">
    <parent link="base_link"/>
    <child link="link1"/>
    <origin xyz="0.22500000000000003 0 0.080625"/>
    <axis xyz="0 0 1"/>
    <limit effort="1" lower="-6.283185307179586" upper="6.283185307179586" velocity="0.5"/>
  </joint>
  <!-- joint2 -->
  <joint name="joint2" type="revolute">
    <parent link="link1"/>
    <child link="link2"/>
    <origin xyz="0 0.004749999999999997 0.098"/>
    <axis xyz="0 1 0"/>
    <limit effort="1" lower="-1.34" upper="2.07" velocity="0.5"/>
  </joint>
  <!-- motor_j3_joint -->
  <joint name="motor_j3_joint" type="fixed">
    <parent link="link2"/>
    <child link="motor_j3"/>
    <origin xyz="-0.008774999999999998 0 0.4"/>
    <axis xyz="1 0 0"/>
    <limit effort="1" lower="-3.141592653589793" upper="3.141592653589793" velocity="0.5"/>
  </joint>
  <!-- joint3 -->
  <joint name="joint3" type="revolute">
    <parent link="link2"/>
    <child link="link3"/>
    <origin rpy="0 1.5707963267948966 0" xyz="-0.008774999999999998 0 0.4"/>
    <axis xyz="0 1 0"/>
    <limit effort="1" lower="-1.1" upper="1" velocity="0.5"/>
  </joint>
  <!-- joint4 -->
  <joint name="joint4" type="revolute">
    <parent link="link3"/>
    <child link="link4"/>
    <origin xyz="-0.053500000000000006 0 0.30000000000000004"/>
    <axis xyz="0 0 1"/>
    <limit effort="1" lower="-6.283185307179586" upper="6.283185307179586" velocity="0.5"/>
  </joint>
  <!-- joint5 -->
  <joint name="joint5" type="revolute">
    <parent link="link4"/>
    <child link="link5"/>
    <origin xyz="0 0 0.0898"/>
    <axis xyz="0 1 0"/>
    <limit effort="1" lower="-1.9" upper="1.9" velocity="0.5"/>
  </joint>
  <!-- joint6 -->
  <joint name="joint6" type="revolute">
    <parent link="link5"/>
    <child link="gripper_base"/>
    <origin xyz="0 0 0.21075"/>
    <axis xyz="0 0 1"/>
    <limit effort="1" lower="-3.141592653589793" upper="3.141592653589793" velocity="0.5"/>
  </joint>
  <!-- gripper_left_finger_joint -->
  <joint name="gripper_left_finger_joint" type="prismatic">
    <parent link="gripper_base"/>
    <child link="gripper_left_finger"/>
    <origin xyz="0.0 0.0 -0.045000000000000005"/>
    <axis xyz="0 1 0"/>
    <limit effort="1" lower="0" upper="0.04" velocity="0.5"/>
  </joint>
  <!-- gripper_right_finger_joint -->
  <joint name="gripper_right_finger_joint" type="prismatic">
    <parent link="gripper_base"/>
    <child link="gripper_right_finger"/>
    <origin xyz="0.0 0.0 -0.045000000000000005"/>
    <axis xyz="0 1 0"/>
    <limit effort="1" lower="0" upper="0.1" velocity="0.5"/>
    <mimic joint="gripper_left_finger_joint" multiplier="-1" offset="0"/>
  </joint>
</robot>

