<?xml version="1.0"?>
<robot xmlns:xacro="http://ros.org/wiki/xacro">


<xacro:property name="body_color" value="Gazebo/Orange" />
<!-- <xacro:include filename="$(find rover_description)/description/kerby.trans" /> -->




<xacro:property name="rpm_to_Radps" value="${2*pi/60.0}" />     <!-- rotations per minute to Rad per second conversion -->
<xacro:property name="velocity_scaling" value="1.0" />     <!-- allows to scale all max velocities down at once -->

<xacro:macro name="aaa_joint_limits" params="lower:=0.0 upper:=0.0 velocity:=${rpm_to_Radps} effort:=100.0">
  <limit lower="${lower}" upper="${upper}" velocity="${velocity}" effort="${effort}"/>
</xacro:macro>

<xacro:property name="joint1_limits">
  <xacro:aaa_joint_limits lower="${-1.5*pi}" upper="${1.5*pi}" velocity="${3 * rpm_to_Radps * velocity_scaling}" />
</xacro:property>

<xacro:property name="joint2_limits">
  <xacro:aaa_joint_limits lower="${-pi}" upper="${pi/2}" velocity="${1 * rpm_to_Radps * velocity_scaling}" />
</xacro:property>

<xacro:property name="joint3_limits">
  <xacro:aaa_joint_limits lower="${-pi/4}" upper="${pi/4}" velocity="${1.5 * rpm_to_Radps * velocity_scaling}" />
</xacro:property>

<xacro:property name="joint4_limits">
  <xacro:aaa_joint_limits lower="${-2*pi}" upper="${2*pi}" velocity="${6 * rpm_to_Radps * velocity_scaling}" />
</xacro:property>

<xacro:property name="joint5_limits">
  <xacro:aaa_joint_limits lower="${-pi/2}" upper="${pi/2}" velocity="${2 * rpm_to_Radps * velocity_scaling}" />
</xacro:property>

<xacro:property name="joint6_limits">
  <xacro:aaa_joint_limits lower="${-pi}" upper="${pi}" velocity="${6 * rpm_to_Radps * velocity_scaling}" />
</xacro:property>




<!-- \\\\\\\\\\\\\\\\\\\\\\Links\\\\\\\\\\\\\\\\\\\\\\\\\\\\\\\\\\\\\\\\\\\\\\\\\\\\\\\\\\\\\\\\\\\\\\\\\\\\-->

<joint name="hd_joint1" type="continuous">
  <origin xyz="-0.228643 0.019974 0.035484" rpy="0 0 0"/>
  <parent link="chassis_link"/>
  <child link="hd_link1"/>
  <axis xyz="0.0 0.0 -1.0"/>
  <xacro:insert_block name="joint1_limits" />
</joint>
<link name="hd_link1">
  <inertial>
    <origin xyz="0.0001907779404468346 0.014210297972432132 0.0484216801173539" rpy="0 0 0"/>
    <mass value="0.3391136619658369"/>
    <inertia ixx="0.001801" iyy="0.001217" izz="0.00078" ixy="1e-05" iyz="-0.000142" ixz="-8e-06"/>
  </inertial>
  <visual>
    <origin xyz="0.228643 -0.019974 -0.035484" rpy="0 0 0"/>
    <geometry>
      <mesh filename="$(find rover_description)/meshes/hd_link1_1.dae" scale="0.001 0.001 0.001"/>
    </geometry>
  </visual>
  <collision>
    <origin xyz="0.228643 -0.019974 -0.035484" rpy="0 0 0"/>
    <geometry>
      <mesh filename="$(find rover_description)/meshes/hd_link1_1.dae" scale="0.001 0.001 0.001"/>
    </geometry>
  </collision>
</link>
<gazebo reference="hd_link1">
  <material>${body_color}</material>
  <mu1>0.2</mu1>
  <mu2>0.2</mu2>
  <selfCollide>true</selfCollide>
</gazebo>

<joint name="hd_joint2" type="continuous">
  <origin xyz="0.0 -0.0577 0.117" rpy="0 0 0"/>
  <parent link="hd_link1"/>
  <child link="hd_link2"/>
  <axis xyz="0.0 1.0 0.0"/>
  <xacro:insert_block name="joint2_limits" />
</joint>
<link name="hd_link2">
  <inertial>
    <origin xyz="0.007428383283974271 0.060838810370171845 0.14389716626077925" rpy="0 0 0"/>
    <mass value="2.4452075265656514"/>
    <inertia ixx="0.038674" iyy="0.03827" izz="0.003075" ixy="7.8e-05" iyz="0.001607" ixz="-0.00107"/>
  </inertial>
  <visual>
    <origin xyz="0.228643 0.037726 -0.152484" rpy="0 0 0"/>
    <geometry>
      <mesh filename="$(find rover_description)/meshes/hd_link2_1.dae" scale="0.001 0.001 0.001"/>
    </geometry>
    <material name="black"/>
  </visual>
  <collision>
    <origin xyz="0.228643 0.037726 -0.152484" rpy="0 0 0"/>
    <geometry>
      <mesh filename="$(find rover_description)/meshes/hd_link2_1.dae" scale="0.001 0.001 0.001"/>
    </geometry>
  </collision>
</link>
<gazebo reference="hd_link2">
  <material>${body_color}</material>
  <mu1>0.2</mu1>
  <mu2>0.2</mu2>
  <selfCollide>true</selfCollide>
</gazebo>


<joint name="hd_joint3" type="fixed">
  <origin xyz="0.012143 0.088 0.399912" rpy="0 0 0"/>
  <parent link="hd_link2"/>
  <child link="hd_link3"/>
  <axis xyz="-0.0 1.0 0.0"/>
  <xacro:insert_block name="joint3_limits" />
</joint>
<link name="hd_link3">
  <inertial>
    <origin xyz="-0.18506431602380205 -0.028188690485378982 0.03515465538516083" rpy="0 0 0"/>
    <mass value="0.3993227194340243"/>
    <inertia ixx="0.000842" iyy="0.00625" izz="0.00637" ixy="4.5e-05" iyz="-5e-06" ixz="0.000238"/>
  </inertial>
  <visual>
    <origin xyz="0.2165 -0.050274 -0.552396" rpy="0 0 0"/>
    <geometry>
      <mesh filename="$(find rover_description)/meshes/hd_link3_1.dae" scale="0.001 0.001 0.001"/>
    </geometry>
    <material name="black"/>
  </visual>
  <collision>
    <origin xyz="0.2165 -0.050274 -0.552396" rpy="0 0 0"/>
    <geometry>
      <mesh filename="$(find rover_description)/meshes/hd_link3_1.dae" scale="0.001 0.001 0.001"/>
    </geometry>
  </collision>
</link>
<gazebo reference="hd_link3">
  <material>${body_color}</material>
  <mu1>0.2</mu1>
  <mu2>0.2</mu2>
  <selfCollide>true</selfCollide>
</gazebo>

<joint name="hd_joint4" type="fixed">
  <origin xyz="-0.315008 -0.029644 0.03814" rpy="0 0 0"/>
  <parent link="hd_link3"/>
  <child link="hd_link4"/>
  <axis xyz="0.999926 0.0 -0.012203"/>
  <xacro:insert_block name="joint4_limits" />
</joint>
<link name="hd_link4">
  <inertial>
    <origin xyz="-0.02651321084424607 0.002896584112952065 -0.0003217450612928996" rpy="0 0 0"/>
    <mass value="0.16590781468918114"/>
    <inertia ixx="0.000197" iyy="0.000349" izz="0.000476" ixy="3.9e-05" iyz="5e-06" ixz="4e-06"/>
  </inertial>
  <visual>
    <origin xyz="0.531508 -0.02063 -0.590536" rpy="0 0 0"/>
    <geometry>
      <mesh filename="$(find rover_description)/meshes/hd_link4_1.dae" scale="0.001 0.001 0.001"/>
    </geometry>
  </visual>
  <collision>
    <origin xyz="0.531508 -0.02063 -0.590536" rpy="0 0 0"/>
    <geometry>
      <mesh filename="$(find rover_description)/meshes/hd_link4_1.dae" scale="0.001 0.001 0.001"/>
    </geometry>
  </collision>
</link>
<gazebo reference="hd_link4">
  <material>${body_color}</material>
  <mu1>0.2</mu1>
  <mu2>0.2</mu2>
  <selfCollide>true</selfCollide>
</gazebo>

<joint name="hd_joint5" type="fixed">
  <origin xyz="-0.093693 -0.042 0.001143" rpy="0 0 0"/>
  <parent link="hd_link4"/>
  <child link="hd_link5"/>
  <axis xyz="0.0 -1.0 0.0"/>
  <xacro:insert_block name="joint5_limits" />
</joint>
<link name="hd_link5">
  <inertial>
    <origin xyz="-0.0032697164246294763 0.03846028201984416 -9.33050693235904e-05" rpy="0 0 0"/>
    <mass value="0.06877842327462745"/>
    <inertia ixx="4.9e-05" iyy="2.9e-05" izz="4.3e-05" ixy="1e-06" iyz="0.0" ixz="-0.0"/>
  </inertial>
  <visual>
    <origin xyz="0.625201 0.02137 -0.591679" rpy="0 0 0"/>
    <geometry>
      <mesh filename="$(find rover_description)/meshes/hd_link5_1.dae" scale="0.001 0.001 0.001"/>
    </geometry>
  </visual>
  <collision>
    <origin xyz="0.625201 0.02137 -0.591679" rpy="0 0 0"/>
    <geometry>
      <mesh filename="$(find rover_description)/meshes/hd_link5_1.dae" scale="0.001 0.001 0.001"/>
    </geometry>
  </collision>
</link>
<gazebo reference="hd_link5">
  <material>${body_color}</material>
  <mu1>0.2</mu1>
  <mu2>0.2</mu2>
  <selfCollide>true</selfCollide>
</gazebo>


<joint name="hd_joint6" type="fixed">
  <origin xyz="-0.027 0.04196 0.000118" rpy="0 0 0"/>
  <parent link="hd_link5"/>
  <child link="hd_link6"/>
  <axis xyz="-0.99999 -0.0 0.00438"/>
  <xacro:insert_block name="joint6_limits" />
</joint>
<link name="hd_link6">
  <inertial>
    <origin xyz="-0.03519419436746607 -0.0007187354689699374 0.0009221743273718497" rpy="0 0 0"/>
    <mass value="0.11153016933793788"/>
    <inertia ixx="0.000117" iyy="0.000166" izz="0.000263" ixy="-2e-06" iyz="-1e-06" ixz="1e-06"/>
  </inertial>
  <visual>
    <origin xyz="0.652201 -0.02059 -0.591797" rpy="0 0 0"/>
    <geometry>
      <mesh filename="$(find rover_description)/meshes/hd_link6_1.dae" scale="0.001 0.001 0.001"/>
    </geometry>
  </visual>
  <collision>
    <origin xyz="0.652201 -0.02059 -0.591797" rpy="0 0 0"/>
    <geometry>
      <mesh filename="$(find rover_description)/meshes/hd_link6_1.dae" scale="0.001 0.001 0.001"/>
    </geometry>
  </collision>
</link>
<gazebo reference="hd_link6">
  <material>${body_color}</material>
  <mu1>0.2</mu1>
  <mu2>0.2</mu2>
  <selfCollide>true</selfCollide>
</gazebo> 





<!-- \\\\\\\\\\\\\\\\\\\\\\Fingers\\\\\\\\\\\\\\\\\\\\\\\\\\\\\\\\\\\\\\\\\\\\\\\\\\\\\\\\\\\\\\\\\\\\\\\\\\\\-->

<!-- <joint name="hd_joint_finger1" type="prismatic">
  <origin xyz="-0.5559 0.743598 0.063804" rpy="0 0 0"/>
  <parent link="hd_link6"/>
  <child link="hd_finger1"/>
  <axis xyz="0.007905 0.999801 0.018314"/>
  <limit upper="0.0" lower="0.0" effort="100" velocity="100"/>
  <mimic joint="finger1" multiplier="-1" offset="0"/>
</joint>

<link name="hd_finger1">
  <inertial>
    <origin xyz="0.4527983426832546 -0.7504874421753438 -0.06638458975098571" rpy="0 0 0"/>
    <mass value="0.025342855198124774"/>
    <inertia ixx="4e-06" iyy="1.8e-05" izz="1.6e-05" ixy="2e-06" iyz="-0.0" ixz="2e-06"/>
  </inertial>
  <visual>
    <origin xyz="1.208101 -0.764188 -0.655601" rpy="0 0 0"/>
    <geometry>
      <mesh filename="$(find rover_description)/meshes/hd_finger1_1.stl" scale="0.001 0.001 0.001"/>
    </geometry>
  </visual>
  <collision>
    <origin xyz="1.208101 -0.764188 -0.655601" rpy="0 0 0"/>
    <geometry>
      <mesh filename="$(find rover_description)/meshes/hd_finger1_1.stl" scale="0.001 0.001 0.001"/>
    </geometry>
  </collision>
</link>
<gazebo reference="hd_finger1">
  <material>${body_color}</material>
  <mu1>0.2</mu1>
  <mu2>0.2</mu2>
  <selfCollide>true</selfCollide>
</gazebo> -->

<!-- <joint name="hd_joint_finger2" type="prismatic">
  <origin xyz="-0.579286 0.743677 0.019718" rpy="0 0 0"/>
  <parent link="hd_link6"/>
  <child link="hd_finger2"/>
  <axis xyz="0.007905 0.999801 0.018314"/>
  <limit upper="0.0" lower="0.0" effort="100" velocity="100"/>
</joint> -->
<!-- 
<link name="hd_finger2">
  <inertial>
    <origin xyz="0.47666706754454413 -0.7361417133269437 -0.01622358994727202" rpy="0 0 0"/>
    <mass value="0.025342855198124774"/>
    <inertia ixx="4e-06" iyy="1.8e-05" izz="1.6e-05" ixy="-2e-06" iyz="-0.0" ixz="-2e-06"/>
  </inertial>
  <visual>
    <origin xyz="1.231487 -0.764267 -0.611515" rpy="0 0 0"/>
    <geometry>
      <mesh filename="$(find rover_description)/meshes/hd_finger2_1.stl" scale="0.001 0.001 0.001"/>
    </geometry>
  </visual>
  <collision>
    <origin xyz="1.231487 -0.764267 -0.611515" rpy="0 0 0"/>
    <geometry>
      <mesh filename="$(find rover_description)/meshes/hd_finger2_1.stl" scale="0.001 0.001 0.001"/>
    </geometry>
  </collision>
</link>
<gazebo reference="hd_finger2">
  <material>${body_color}</material>
  <mu1>0.2</mu1>
  <mu2>0.2</mu2>
  <selfCollide>true</selfCollide>
</gazebo> -->



<!-- \\\\\\\\\\\\\\\\\\\\\\Motor\\\\\\\\\\\\\\\\\\\\\\\\\\\\\\\\\\\\\\\\\\\\\\\\\\\\\\\\\\\\\\\\\\\\\\\\\\\\-->

<!-- 
<joint name="moteurJ3" type="fixed">
  <origin xyz="0.402151 -0.084889 -0.003226" rpy="0 0 0"/>
  <parent link="hd_link2"/>
  <child link="hd_motor_j3"/>
</joint>

<link name="hd_motor_j3">
  <inertial>
    <origin xyz="-0.3146867524268133 0.14188869096939155 0.25591208107402835" rpy="0 0 0"/>
    <mass value="0.11925838600046076"/>
    <inertia ixx="0.00051" iyy="0.000525" izz="2.9e-05" ixy="-0.0" iyz="-0.0" ixz="-8.7e-05"/>
  </inertial>
  <visual>
    <origin xyz="-0.173508 0.122615 -0.149258" rpy="0 0 0"/>
    <geometry>
      <mesh filename="$(find rover_description)/meshes/hd_motor_j3_1.stl" scale="0.001 0.001 0.001"/>
    </geometry>
  </visual>
  <collision>
    <origin xyz="-0.173508 0.122615 -0.149258" rpy="0 0 0"/>
    <geometry>
      <mesh filename="$(find rover_description)/meshes/hd_motor_j3_1.stl" scale="0.001 0.001 0.001"/>
    </geometry>
  </collision>
</link>
<gazebo reference="hd_motor_j3">
  <material>${body_color}</material>
  <mu1>0.2</mu1>
  <mu2>0.2</mu2>
  <selfCollide>true</selfCollide>
</gazebo> -->


</robot>












<!-- 
<xacro:property name="body_color" value="Gazebo/Orange" />


</robot>

<xacro:property name="rpm_to_Radps" value="${2*pi/60.0}" />    
<xacro:property name="velocity_scaling" value="1.0" />    

<xacro:macro name="aaa_joint_limits" params="lower:=0.0 upper:=0.0 velocity:=${rpm_to_Radps} effort:=100.0">
  <limit lower="${lower}" upper="${upper}" velocity="${velocity}" effort="${effort}"/>
</xacro:macro>

<xacro:property name="joint1_limits">
  <xacro:aaa_joint_limits lower="${-1.5*pi}" upper="${1.5*pi}" velocity="${3 * rpm_to_Radps * velocity_scaling}" />
</xacro:property>

<xacro:property name="joint2_limits">
  <xacro:aaa_joint_limits lower="${-pi}" upper="${pi/2}" velocity="${1 * rpm_to_Radps * velocity_scaling}" />
</xacro:property>

<xacro:property name="joint3_limits">
  <xacro:aaa_joint_limits lower="${-pi/4}" upper="${pi/4}" velocity="${1.5 * rpm_to_Radps * velocity_scaling}" />
</xacro:property>

<xacro:property name="joint4_limits">
  <xacro:aaa_joint_limits lower="${-2*pi}" upper="${2*pi}" velocity="${6 * rpm_to_Radps * velocity_scaling}" />
</xacro:property>

<xacro:property name="joint5_limits">
  <xacro:aaa_joint_limits lower="${-pi/2}" upper="${pi/2}" velocity="${2 * rpm_to_Radps * velocity_scaling}" />
</xacro:property>

<xacro:property name="joint6_limits">
  <xacro:aaa_joint_limits lower="${-pi}" upper="${pi}" velocity="${6 * rpm_to_Radps * velocity_scaling}" />
</xacro:property>

-->


<!-- \\\\\\\\\\\\\\\\\\\\\\Links\\\\\\\\\\\\\\\\\\\\\\\\\\\\\\\\\\\\\\\\\\\\\\\\\\\\\\\\\\\\\\\\\\\\\\\\\\\\-->
<!-- 
<joint name="hd_joint1" type="continuous">
  <origin xyz="-0.228643 0.019974 0.035484" rpy="0 0 0"/>
  <parent link="chassis_link"/>
  <child link="hd_link1"/>
  <axis xyz="0.0 0.0 -1.0"/>
  <!-- <xacro:insert_block name="joint1_limits" /> -->
</joint>
<link name="hd_link1">
  <inertial>
    <origin xyz="0.0001907779404468346 0.014210297972432132 0.0484216801173539" rpy="0 0 0"/>
    <mass value="0.1"/>

    <inertia ixx="0.001801" iyy="0.001217" izz="0.00078" ixy="1e-05" iyz="-0.000142" ixz="-8e-06"/>
  </inertial>
  <visual>
    <origin xyz="0.228643 -0.019974 -0.035484" rpy="0 0 0"/>
    <geometry>
      <mesh filename="$(find rover_description)/meshes/hd_link1_1.stl" scale="0.001 0.001 0.001"/>
    </geometry>
  </visual>
  <collision>
    <origin xyz="0.228643 -0.019974 -0.035484" rpy="0 0 0"/>
    <geometry>
      <mesh filename="$(find rover_description)/meshes/hd_link1_1.stl" scale="0.001 0.001 0.001"/>
    </geometry>
  </collision>
</link>
<gazebo reference="hd_link1">
  <material>${body_color}</material>
  <mu1>0.2</mu1>
  <mu2>0.2</mu2>
</gazebo>



<joint name="hd_joint2" type="continuous">
  <origin xyz="0.0 -0.0577 0.117" rpy="0 0 0"/>
  <parent link="hd_link1"/>
  <child link="hd_link2"/>
  <axis xyz="0.0 1.0 0.0"/>
</joint>
<link name="hd_link2">
  <inertial>
    <origin xyz="0.007428383283974271 0.060838810370171845 0.14389716626077925" rpy="0 0 0"/>
    <mass value="0.2"/>
    <inertia ixx="0.038674" iyy="0.03827" izz="0.003075" ixy="7.8e-05" iyz="0.001607" ixz="-0.00107"/>
  </inertial>
  <visual>
    <origin xyz="0.228643 0.037726 -0.152484" rpy="0 0 0"/>
    <geometry>
      <mesh filename="$(find rover_description)/meshes/hd_link2_1.stl" scale="0.001 0.001 0.001"/>
    </geometry>
    <material name="black"/>
  </visual>
  <!-- <collision>
    <origin xyz="0.228643 0.037726 -0.152484" rpy="0 0 0"/>
    <geometry>
      <mesh filename="$(find rover_description)/meshes/new_hd_link_2.stl" scale="0.001 0.001 0.001"/>
    </geometry>
  </collision> -->
</link>
<gazebo reference="hd_link2">
  <material>${body_color}</material>
  <mu1>0.2</mu1>
  <mu2>0.2</mu2>
</gazebo>

<joint name="hd_joint3" type="continuous">
  <!-- <origin xyz="0.012143 0.088 0.399912" rpy="0 0 0"/> -->
  <origin xyz="-0.01 0.088 0.399912" rpy="0 0 0"/>
  <parent link="hd_link2"/>
  <child link="hd_link3"/>
  <axis xyz="-0.0 1.0 0.0"/>
</joint>
<link name="hd_link3">
  <inertial>
    <origin xyz="-0.18506431602380205 -0.028188690485378982 0.03515465538516083" rpy="0 0 0"/>
    <mass value="0.1"/>

    <inertia ixx="0.000842" iyy="0.00625" izz="0.00637" ixy="4.5e-05" iyz="-5e-06" ixz="0.000238"/>
  </inertial>
  <visual>
    <origin xyz="0.2165 -0.050274 -0.552396" rpy="0 0 0"/>
    <geometry>
      <mesh filename="$(find rover_description)/meshes/hd_link3_1.stl" scale="0.001 0.001 0.001"/>
      
   </geometry>
    <material name="black"/>
  </visual>
  <!-- <collision>
    <origin xyz="0.2165 -0.050274 -0.552396" rpy="0 0 0"/>
    <geometry>
      <mesh filename="$(find rover_description)/meshes/hd_link3_1.stl" scale="0.001 0.001 0.001"/>
    </geometry>
  </collision> -->
</link>
<gazebo reference="hd_link3">
  <material>${body_color}</material>
  <mu1>0.2</mu1>
  <mu2>0.2</mu2>
</gazebo>
 -->

<!-- 

<joint name="hd_joint4" type="continuous">
  <origin xyz="-0.315008 -0.029644 0.03814" rpy="0 0 0"/>
  <parent link="hd_link3"/>
  <child link="hd_link4"/>
  <axis xyz="0.999926 0.0 -0.012203"/>
</joint>
<link name="hd_link4">
  <inertial>
    <origin xyz="-0.02651321084424607 0.002896584112952065 -0.0003217450612928996" rpy="0 0 0"/>
    <mass value="0.01"/>
    <inertia ixx="0.000197" iyy="0.000349" izz="0.000476" ixy="3.9e-05" iyz="5e-06" ixz="4e-06"/>
  </inertial>
  <visual>
    <origin xyz="0.531508 -0.02063 -0.590536" rpy="0 0 0"/>
    <geometry>
      <mesh filename="$(find rover_description)/meshes/hd_link4_1.stl" scale="0.001 0.001 0.001"/>
    </geometry>
  </visual>
  <collision>
    <origin xyz="0.531508 -0.02063 -0.590536" rpy="0 0 0"/>
    <geometry>
      <mesh filename="$(find rover_description)/meshes/hd_link4_1.dae" scale="0.001 0.001 0.001"/>
    </geometry>
  </collision> 
</link>
<gazebo reference="hd_link4">
  <material>${body_color}</material>
  <mu1>0.2</mu1>
  <mu2>0.2</mu2>
</gazebo> -->


<!-- <joint name="hd_joint5" type="continuous">
  <origin xyz="-0.093693 -0.042 0.001143" rpy="0 0 0"/>
  <parent link="hd_link4"/>
  <child link="hd_link5"/>
  <axis xyz="0.0 -1.0 0.0"/>
</joint>
<link name="hd_link5">
  <inertial>
    <origin xyz="-0.0032697164246294763 0.03846028201984416 -9.33050693235904e-05" rpy="0 0 0"/>
    <mass value="0.03"/>
    <inertia ixx="4.9e-05" iyy="2.9e-05" izz="4.3e-05" ixy="1e-06" iyz="0.0" ixz="-0.0"/>
  </inertial>
  <visual>
    <origin xyz="0.625201 0.02137 -0.591679" rpy="0 0 0"/>
    <geometry>
      <mesh filename="$(find rover_description)/meshes/hd_link5_1.stl" scale="0.001 0.001 0.001"/>
    </geometry>
  </visual>
 <collision>
    <origin xyz="0.625201 0.02137 -0.591679" rpy="0 0 0"/>
    <geometry>
      <mesh filename="$(find rover_description)/meshes/hd_link5_1.dae" scale="0.001 0.001 0.001"/>
    </geometry>
  </collision> 
</link>
<gazebo reference="hd_link5">
  <material>${body_color}</material>
  <mu1>0.2</mu1>
  <mu2>0.2</mu2>
</gazebo> -->

<!-- 
<joint name="hd_joint6" type="continuous">
  <origin xyz="-0.027 0.04196 0.000118" rpy="0 0 0"/>
  <parent link="hd_link5"/>
  <child link="hd_link6"/>
  <axis xyz="-0.99999 -0.0 0.00438"/>
</joint>
<link name="hd_link6">
  <inertial>
    <origin xyz="-0.03519419436746607 -0.0007187354689699374 0.0009221743273718497" rpy="0 0 0"/>
    <mass value="0.01"/>
    <inertia ixx="0.000117" iyy="0.000166" izz="0.000263" ixy="-2e-06" iyz="-1e-06" ixz="1e-06"/>
  </inertial>
  <visual>
    <origin xyz="0.652201 -0.02059 -0.591797" rpy="0 0 0"/>
    <geometry>
      <mesh filename="$(find rover_description)/meshes/hd_link6_1.stl" scale="0.001 0.001 0.001"/>
    </geometry>
  </visual>
<collision>
    <origin xyz="0.652201 -0.02059 -0.591797" rpy="0 0 0"/>
    <geometry>
      <mesh filename="$(find rover_description)/meshes/hd_link6_1.dae" scale="0.001 0.001 0.001"/>
    </geometry>
  </collision> 
</link>
<gazebo reference="hd_link6">
  <material>${body_color}</material>
  <mu1>0.2</mu1>
  <mu2>0.2</mu2>
</gazebo> 
 -->

</robot>
