<?xml version="1.0" ?>
<!-- =================================================================================== -->
<!-- |    This document was autogenerated by xacro from assemblage.urdf.xacro          | -->
<!-- |    EDITING THIS FILE BY HAND IS NOT RECOMMENDED                                 | -->
<!-- =================================================================================== -->
<robot name="kerby">
  <material name="silver">
    <color rgba="0.700 0.700 0.700 1.000"/>
  </material>
  <material name="black">
    <color rgba="0.1 0.1 0.1 1.000"/>
  </material>
  <material name="white">
    <color rgba="1 1 1 1.000"/>
  </material>
  <material name="pink">
    <!-- <color rgba="1 0.4117 0.70588 1.000"/> -->
    <color rgba="1 1 1 1.000"/>
  </material>
  <material name="blue">
    <color rgba="0 0 0.5 1.000"/>
  </material>
  <transmission name="steering1_tran">
    <type>transmission_interface/SimpleTransmission</type>
    <joint name="steering1">
      <hardwareInterface>hardware_interface/EffortJointInterface</hardwareInterface>
    </joint>
    <actuator name="steering1_actr">
      <hardwareInterface>hardware_interface/EffortJointInterface</hardwareInterface>
      <mechanicalReduction>1</mechanicalReduction>
    </actuator>
  </transmission>
  <transmission name="steering2_tran">
    <type>transmission_interface/SimpleTransmission</type>
    <joint name="steering2">
      <hardwareInterface>hardware_interface/EffortJointInterface</hardwareInterface>
    </joint>
    <actuator name="steering2_actr">
      <hardwareInterface>hardware_interface/EffortJointInterface</hardwareInterface>
      <mechanicalReduction>1</mechanicalReduction>
    </actuator>
  </transmission>
  <transmission name="steering3_tran">
    <type>transmission_interface/SimpleTransmission</type>
    <joint name="steering3">
      <hardwareInterface>hardware_interface/EffortJointInterface</hardwareInterface>
    </joint>
    <actuator name="steering3_actr">
      <hardwareInterface>hardware_interface/EffortJointInterface</hardwareInterface>
      <mechanicalReduction>1</mechanicalReduction>
    </actuator>
  </transmission>
  <transmission name="steering4_tran">
    <type>transmission_interface/SimpleTransmission</type>
    <joint name="steering4">
      <hardwareInterface>hardware_interface/EffortJointInterface</hardwareInterface>
    </joint>
    <actuator name="steering4_actr">
      <hardwareInterface>hardware_interface/EffortJointInterface</hardwareInterface>
      <mechanicalReduction>1</mechanicalReduction>
    </actuator>
  </transmission>
  <transmission name="driving4_tran">
    <type>transmission_interface/SimpleTransmission</type>
    <joint name="driving4">
      <hardwareInterface>hardware_interface/EffortJointInterface</hardwareInterface>
    </joint>
    <actuator name="driving4_actr">
      <hardwareInterface>hardware_interface/EffortJointInterface</hardwareInterface>
      <mechanicalReduction>1</mechanicalReduction>
    </actuator>
  </transmission>
  <transmission name="driving1_tran">
    <type>transmission_interface/SimpleTransmission</type>
    <joint name="driving1">
      <hardwareInterface>hardware_interface/EffortJointInterface</hardwareInterface>
    </joint>
    <actuator name="driving1_actr">
      <hardwareInterface>hardware_interface/EffortJointInterface</hardwareInterface>
      <mechanicalReduction>1</mechanicalReduction>
    </actuator>
  </transmission>
  <transmission name="driving3_tran">
    <type>transmission_interface/SimpleTransmission</type>
    <joint name="driving3">
      <hardwareInterface>hardware_interface/EffortJointInterface</hardwareInterface>
    </joint>
    <actuator name="driving3_actr">
      <hardwareInterface>hardware_interface/EffortJointInterface</hardwareInterface>
      <mechanicalReduction>1</mechanicalReduction>
    </actuator>
  </transmission>
  <transmission name="driving2_tran">
    <type>transmission_interface/SimpleTransmission</type>
    <joint name="driving2">
      <hardwareInterface>hardware_interface/EffortJointInterface</hardwareInterface>
    </joint>
    <actuator name="driving2_actr">
      <hardwareInterface>hardware_interface/EffortJointInterface</hardwareInterface>
      <mechanicalReduction>1</mechanicalReduction>
    </actuator>
  </transmission>
  

// 
  <transmission name="joint2_tran">
    
//   
    <type>transmission_interface/SimpleTransmission</type>
    
//   
    <joint name="joint2">
      
//     
      <hardwareInterface>hardware_interface/EffortJointInterface</hardwareInterface>
      
//   
    </joint>
    
//   
    <actuator name="joint2_actr">
      
//     
      <hardwareInterface>hardware_interface/EffortJointInterface</hardwareInterface>
      
//     
      <mechanicalReduction>1</mechanicalReduction>
      
//   
    </actuator>
    
// 
  </transmission>
  

// 
  <transmission name="joint3_tran">
    
//   
    <type>transmission_interface/SimpleTransmission</type>
    
//   
    <joint name="joint3">
      
//     
      <hardwareInterface>hardware_interface/EffortJointInterface</hardwareInterface>
      
//   
    </joint>
    
//   
    <actuator name="joint3_actr">
      
//     
      <hardwareInterface>hardware_interface/EffortJointInterface</hardwareInterface>
      
//     
      <mechanicalReduction>1</mechanicalReduction>
      
//   
    </actuator>
    
// 
  </transmission>
  

// 
  <transmission name="joint4_tran">
    
//   
    <type>transmission_interface/SimpleTransmission</type>
    
//   
    <joint name="joint4">
      
//     
      <hardwareInterface>hardware_interface/EffortJointInterface</hardwareInterface>
      
//   
    </joint>
    
//   
    <actuator name="joint4_actr">
      
//     
      <hardwareInterface>hardware_interface/EffortJointInterface</hardwareInterface>
      
//     
      <mechanicalReduction>1</mechanicalReduction>
      
//   
    </actuator>
    
// 
  </transmission>
  

// 
  <transmission name="joint5_tran">
    
//   
    <type>transmission_interface/SimpleTransmission</type>
    
//   
    <joint name="joint5">
      
//     
      <hardwareInterface>hardware_interface/EffortJointInterface</hardwareInterface>
      
//   
    </joint>
    
//   
    <actuator name="joint5_actr">
      
//     
      <hardwareInterface>hardware_interface/EffortJointInterface</hardwareInterface>
      
//     
      <mechanicalReduction>1</mechanicalReduction>
      
//   
    </actuator>
    
// 
  </transmission>
  

// 
  <transmission name="joint6_tran">
    
//   
    <type>transmission_interface/SimpleTransmission</type>
    
//   
    <joint name="joint6">
      
//     
      <hardwareInterface>hardware_interface/EffortJointInterface</hardwareInterface>
      
//   
    </joint>
    
//   
    <actuator name="joint6_actr">
      
//     
      <hardwareInterface>hardware_interface/EffortJointInterface</hardwareInterface>
      
//     
      <mechanicalReduction>1</mechanicalReduction>
      
//   
    </actuator>
    
// 
  </transmission>
  

// 
  <transmission name="finger1_tran">
    
//   
    <type>transmission_interface/SimpleTransmission</type>
    
//   
    <joint name="finger1">
      
//     
      <hardwareInterface>hardware_interface/EffortJointInterface</hardwareInterface>
      
//   
    </joint>
    
//   
    <actuator name="finger1_actr">
      
//     
      <hardwareInterface>hardware_interface/EffortJointInterface</hardwareInterface>
      
//     
      <mechanicalReduction>1</mechanicalReduction>
      
//   
    </actuator>
    
// 
  </transmission>
  

// 
  <transmission name="finger2_tran">
    
//   
    <type>transmission_interface/SimpleTransmission</type>
    
//   
    <joint name="finger2">
      
//     
      <hardwareInterface>hardware_interface/EffortJointInterface</hardwareInterface>
      
//   
    </joint>
    
//   
    <actuator name="finger2_actr">
      
//     
      <hardwareInterface>hardware_interface/EffortJointInterface</hardwareInterface>
      
//     
      <mechanicalReduction>1</mechanicalReduction>
      
//   
    </actuator>
    
// 
  </transmission>
  

// 
  <transmission name="R�volution 30_tran">
    
//   
    <type>transmission_interface/SimpleTransmission</type>
    
//   
    <joint name="R�volution 30">
      
//     
      <hardwareInterface>hardware_interface/EffortJointInterface</hardwareInterface>
      
//   
    </joint>
    
//   
    <actuator name="R�volution 30_actr">
      
//     
      <hardwareInterface>hardware_interface/EffortJointInterface</hardwareInterface>
      
//     
      <mechanicalReduction>1</mechanicalReduction>
      
//   
    </actuator>
    
// 
  </transmission>
  

// 
  <transmission name="R�volution 31_tran">
    
//   
    <type>transmission_interface/SimpleTransmission</type>
    
//   
    <joint name="R�volution 31">
      
//     
      <hardwareInterface>hardware_interface/EffortJointInterface</hardwareInterface>
      
//   
    </joint>
    
//   
    <actuator name="R�volution 31_actr">
      
//     
      <hardwareInterface>hardware_interface/EffortJointInterface</hardwareInterface>
      
//     
      <mechanicalReduction>1</mechanicalReduction>
      
//   
    </actuator>
    
// 
  </transmission>
  

// 
  <transmission name="R�volution 32_tran">
    
//   
    <type>transmission_interface/SimpleTransmission</type>
    
//   
    <joint name="R�volution 32">
      
//     
      <hardwareInterface>hardware_interface/EffortJointInterface</hardwareInterface>
      
//   
    </joint>
    
//   
    <actuator name="R�volution 32_actr">
      
//     
      <hardwareInterface>hardware_interface/EffortJointInterface</hardwareInterface>
      
//     
      <mechanicalReduction>1</mechanicalReduction>
      
//   
    </actuator>
    
// 
  </transmission>
  <gazebo reference="chassis_link">
    <material>Gazebo/Grey</material>
    <mu1>0.2</mu1>
    <mu2>0.2</mu2>
    <gravity>true</gravity>
  </gazebo>
  <gazebo reference="steering1_link">
    <material>Gazebo/Grey</material>
    <mu1>0.2</mu1>
    <mu2>0.2</mu2>
  </gazebo>
  <gazebo reference="steering2_link">
    <material>Gazebo/Grey</material>
    <mu1>0.2</mu1>
    <mu2>0.2</mu2>
  </gazebo>
  <gazebo reference="steering3_link">
    <material>Gazebo/Grey</material>
    <mu1>0.2</mu1>
    <mu2>0.2</mu2>
  </gazebo>
  <gazebo reference="steering4_link">
    <material>Gazebo/Grey</material>
    <mu1>2</mu1>
    <mu2>2</mu2>
  </gazebo>
  <gazebo reference="wheel3_link">
    <material>Gazebo/Grey</material>
    <mu1>2</mu1>
    <mu2>2</mu2>
  </gazebo>
  <gazebo reference="wheel4_link">
    <material>Gazebo/Grey</material>
    <mu1>0.2</mu1>
    <mu2>0.2</mu2>
  </gazebo>
  <gazebo reference="wheel2_link">
    <material>Gazebo/Grey</material>
    <mu1>2</mu1>
    <mu2>2</mu2>
  </gazebo>
  <gazebo reference="wheel1_link">
    <material>Gazebo/Grey</material>
    <mu1>2</mu1>
    <mu2>2</mu2>
  </gazebo>
  <gazebo reference="caster_wheel">
    <material>Gazebo/Grey</material>
    <mu1>2</mu1>
    <mu2>2</mu2>
  </gazebo>
  <gazebo reference="caster_axis">
    <material>Gazebo/Grey</material>
    <mu1>0.2</mu1>
    <mu2>0.2</mu2>
  </gazebo>
  <gazebo reference="lidar_axis">
    <material>Gazebo/LightGrey</material>
  </gazebo>
   


// 
  <gazebo reference="hd_link2_1">
    
//   
    <material>Gazebo/Grey</material>
    
//   
    <mu1>0.2</mu1>
    
//   
    <mu2>0.2</mu2>
    
//   
    <selfCollide>true</selfCollide>
    
// 
  </gazebo>
  

// 
  <gazebo reference="hd_link3_1">
    
//   
    <material>Gazebo/Grey</material>
    
//   
    <mu1>0.2</mu1>
    
//   
    <mu2>0.2</mu2>
    
//   
    <selfCollide>true</selfCollide>
    
// 
  </gazebo>
  

// 
  <gazebo reference="hd_link4_1">
    
//   
    <material>Gazebo/Grey</material>
    
//   
    <mu1>0.2</mu1>
    
//   
    <mu2>0.2</mu2>
    
//   
    <selfCollide>true</selfCollide>
    
// 
  </gazebo>
  

// 
  <gazebo reference="hd_link5_1">
    
//   
    <material>Gazebo/Grey</material>
    
//   
    <mu1>0.2</mu1>
    
//   
    <mu2>0.2</mu2>
    
//   
    <selfCollide>true</selfCollide>
    
// 
  </gazebo>
  

// 
  <gazebo reference="hd_link6_1">
    
//   
    <material>Gazebo/Grey</material>
    
//   
    <mu1>0.2</mu1>
    
//   
    <mu2>0.2</mu2>
    
//   
    <selfCollide>true</selfCollide>
    
// 
  </gazebo>
  

// 
  <gazebo reference="hd_finger2_1">
    
//   
    <material>Gazebo/Grey</material>
    
//   
    <mu1>0.2</mu1>
    
//   
    <mu2>0.2</mu2>
    
//   
    <selfCollide>true</selfCollide>
    
// 
  </gazebo>
  

// 
  <gazebo reference="hd_finger1_1">
    
//   
    <material>Gazebo/Grey</material>
    
//   
    <mu1>0.2</mu1>
    
//   
    <mu2>0.2</mu2>
    
//   
    <selfCollide>true</selfCollide>
    
// 
  </gazebo>
  

// 
  <gazebo reference="hd_motor_j3_1">
    
//   
    <material>Gazebo/Grey</material>
    
//   
    <mu1>0.2</mu1>
    
//   
    <mu2>0.2</mu2>
    
//   
    <selfCollide>true</selfCollide>
    
// 
  </gazebo>
  <gazebo reference="right_leg">
    <material>Gazebo/Grey</material>
    <mu1>0.2</mu1>
    <mu2>0.2</mu2>
    <selfCollide>true</selfCollide>
  </gazebo>
  <gazebo reference="left_leg">
    <material>Gazebo/Grey</material>
    <mu1>0.2</mu1>
    <mu2>0.2</mu2>
    <selfCollide>true</selfCollide>
  </gazebo>
  

// 
  <gazebo reference="hd_link1_1">
    
//   
    <material>Gazebo/Grey</material>
    
//   
    <mu1>0.2</mu1>
    
//   
    <mu2>0.2</mu2>
    
//   
    <selfCollide>true</selfCollide>
    
// 
  </gazebo>
  <!-- Specify some standard inertial calculations https://en.wikipedia.org/wiki/List_of_moments_of_inertia -->
  <!-- These make use of xacro's mathematical functionality -->
  <gazebo>
    <plugin filename="libgazebo_ros_control.so" name="control"/>
  </gazebo>
  <gazebo reference="base">
    <material>Gazebo/Red</material>
    <mu1>0.2</mu1>
    <mu2>0.2</mu2>
    
  // 
    <selfCollide>true</selfCollide>
    
  // 
    <gravity>true</gravity>
  </gazebo>
  <gazebo reference="hd_link1">
    <material>Gazebo/Blue</material>
    <mu1>0.2</mu1>
    <mu2>0.2</mu2>
    
  // 
    <selfCollide>true</selfCollide>
  </gazebo>
  <gazebo reference="hd_link2">
    <material>Gazebo/Red</material>
    <mu1>0.2</mu1>
    <mu2>0.2</mu2>
    
  // 
    <selfCollide>true</selfCollide>
  </gazebo>
  <gazebo reference="hd_link3">
    <material>Gazebo/Blue</material>
    <mu1>0.2</mu1>
    <mu2>0.2</mu2>
    
  // 
    <selfCollide>true</selfCollide>
  </gazebo>
  <gazebo reference="hd_link4">
    <material>Gazebo/Red</material>
    <mu1>0.2</mu1>
    <mu2>0.2</mu2>
    
  // 
    <selfCollide>true</selfCollide>
  </gazebo>
  <gazebo reference="hd_link5">
    <material>Gazebo/Blue</material>
    <mu1>0.2</mu1>
    <mu2>0.2</mu2>
    
  // 
    <selfCollide>true</selfCollide>
  </gazebo>
  <gazebo reference="hd_link6">
    <material>Gazebo/Red</material>
    <mu1>0.2</mu1>
    <mu2>0.2</mu2>
    
  // 
    <selfCollide>true</selfCollide>
  </gazebo>
  <gazebo reference="Gripper_Arcs_v1_1">
    <material>Gazebo/Blue</material>
    <mu1>0.2</mu1>
    <mu2>0.2</mu2>
    <selfCollide>true</selfCollide>
  </gazebo>
  <gazebo reference="Gripper_Finger_v1_1">
    <material>Gazebo/Red</material>
    <mu1>0.2</mu1>
    <mu2>0.2</mu2>
    
  // 
    <selfCollide>true</selfCollide>
  </gazebo>
  <gazebo reference="Gripper_Arcs_v1__2__1">
    <material>Gazebo/Blue</material>
    <mu1>0.2</mu1>
    <mu2>0.2</mu2>
    
  // 
    <selfCollide>true</selfCollide>
  </gazebo>
  <gazebo reference="Gripper_Finger_v1__1__1">
    <material>Gazebo/Red</material>
    <mu1>0.2</mu1>
    <mu2>0.2</mu2>
    
  // 
    <selfCollide>true</selfCollide>
  </gazebo>
  <!-- <xacro:include filename="$(find rover_description)/description/ros2_control_arm.xacro" /> -->
  <!-- <link name="base_link"/> -->
  <joint name="hd_joint0" type="fixed">
    <!-- <origin xyz="-0.228643 0.019974 -0.035484" rpy="0 0 ${pi}"/> -->
    <origin rpy="0 0 3.141592653589793" xyz="-0.22 0 0.035484"/>
    <parent link="chassis_link"/>
    <child link="base"/>
  </joint>
  <!-- <joint name="base_joint" type="fixed">
    <parent link="base_link"/>
    <child link="base"/>
    <origin xyz="0 0 0 " rpy="0 0 0"/>
</joint>  -->
  <link name="base">
    <inertial>
      <origin rpy="1.5707963267948966 0 0" xyz="0 0.47 -0.12"/>
      <!-- <origin xyz="0 0 0" rpy="${pi/2} 0 0"/> -->
      <mass value="1.001112718637754"/>
      <inertia ixx="0.00171" ixy="-0.0" ixz="-0.0" iyy="0.003332" iyz="0.0" izz="0.00171"/>
    </inertial>
    <visual>
      <origin rpy="1.5707963267948966 0 0" xyz="0 0.47 -0.12"/>
      <geometry>
        <mesh filename="package://rover_description/meshes/new_hd/base_link.stl" scale="0.001 0.001 0.001"/>
      </geometry>
      <material name="silver"/>
    </visual>
    <collision>
      <origin rpy="1.5707963267948966 0 0" xyz="0 0.47 -0.12"/>
      <geometry>
        <mesh filename="package://rover_description/meshes/new_hd/base_link.stl" scale="0.001 0.001 0.001"/>
      </geometry>
    </collision>
  </link>
  <link name="hd_link1">
    <inertial>
      <origin rpy="0 0 0" xyz="0.023340582081130535 0.09194845459261852 0.0126568969650096"/>
      <mass value="13.941603234564111"/>
      <inertia ixx="0.039361" ixy="-0.009386" ixz="-0.007119" iyy="0.035501" iyz="-0.00509" izz="0.048628"/>
    </inertial>
    <visual>
      <origin rpy="0 0 0" xyz="-0.007012 -0.143312 -0.484988"/>
      <geometry>
        <mesh filename="package://rover_description/meshes/new_hd/link_1_1.stl" scale="0.001 0.001 0.001"/>
      </geometry>
      <material name="silver"/>
    </visual>
    <collision>
      <origin rpy="0 0 0" xyz="-0.007012 -0.143312 -0.484988"/>
      <geometry>
        <mesh filename="package://rover_description/meshes/new_hd/link_1_1.stl" scale="0.001 0.001 0.001"/>
      </geometry>
    </collision>
  </link>
  <link name="hd_link2">
    <inertial>
      <origin rpy="0 0 0" xyz="-0.08423197746352788 0.10484954848092454 0.1284542941455662"/>
      <mass value="3.1130721114751427"/>
      <inertia ixx="0.055243" ixy="0.012697" ixz="0.016949" iyy="0.044626" iyz="-0.023414" izz="0.033179"/>
    </inertial>
    <visual>
      <origin rpy="0 0 0" xyz="-0.111181 -0.261812 -0.541477"/>
      <geometry>
        <mesh filename="package://rover_description/meshes/new_hd/link_2_1.stl" scale="0.001 0.001 0.001"/>
      </geometry>
      <material name="silver"/>
    </visual>
    <collision>
      <origin rpy="0 0 0" xyz="-0.111181 -0.261812 -0.541477"/>
      <geometry>
        <mesh filename="package://rover_description/meshes/new_hd/link_2_1.stl" scale="0.001 0.001 0.001"/>
      </geometry>
    </collision>
  </link>
  <link name="hd_link3">
    <inertial>
      <origin rpy="0 0 0" xyz="-0.06826283209546892 0.0031862398429799987 -0.06700337059280337"/>
      <mass value="13.941603234564111"/>
      <inertia ixx="0.04444" ixy="0.000162" ixz="-0.005885" iyy="0.052244" iyz="0.00239" izz="0.026806"/>
    </inertial>
    <visual>
      <origin rpy="0 0 0" xyz="0.034759 -0.471511 -0.8106"/>
      <geometry>
        <mesh filename="package://rover_description/meshes/new_hd/link_3_1.stl" scale="0.001 0.001 0.001"/>
      </geometry>
      <material name="silver"/>
    </visual>
    <collision>
      <origin rpy="0 0 0" xyz="0.034759 -0.471511 -0.8106"/>
      <geometry>
        <mesh filename="package://rover_description/meshes/new_hd/link_3_1.stl" scale="0.001 0.001 0.001"/>
      </geometry>
    </collision>
  </link>
  <link name="hd_link4">
    <inertial>
      <origin rpy="0 0 0" xyz="0.06826896232783315 0.01808291361303932 -0.13171586513395195"/>
      <mass value="2.3441890740360654"/>
      <inertia ixx="0.022767" ixy="-0.001236" ixz="0.009066" iyy="0.026136" iyz="0.002399" izz="0.00899"/>
    </inertial>
    <visual>
      <origin rpy="0 0 0" xyz="0.082848 -0.485732 -0.650695"/>
      <geometry>
        <mesh filename="package://rover_description/meshes/new_hd/link_4_1.stl" scale="0.001 0.001 0.001"/>
      </geometry>
      <material name="silver"/>
    </visual>
    <collision>
      <origin rpy="0 0 0" xyz="0.082848 -0.485732 -0.650695"/>
      <geometry>
        <mesh filename="package://rover_description/meshes/new_hd/link_4_1.stl" scale="0.001 0.001 0.001"/>
      </geometry>
    </collision>
  </link>
  <link name="hd_link5">
    <inertial>
      <origin rpy="0 0 0" xyz="0.08406378219626617 0.021222804231640358 0.04052714111106276"/>
      <mass value="13.941603234564111"/>
      <inertia ixx="0.036907" ixy="-0.010349" ixz="-0.006458" iyy="0.037003" iyz="-0.002873" izz="0.04958"/>
    </inertial>
    <visual>
      <origin rpy="0 0 0" xyz="-0.030684 -0.519236 -0.405724"/>
      <geometry>
        <mesh filename="package://rover_description/meshes/new_hd/link_5_1.stl" scale="0.001 0.001 0.001"/>
      </geometry>
      <material name="silver"/>
    </visual>
    <collision>
      <origin rpy="0 0 0" xyz="-0.030684 -0.519236 -0.405724"/>
      <geometry>
        <mesh filename="package://rover_description/meshes/new_hd/link_5_1.stl" scale="0.001 0.001 0.001"/>
      </geometry>
    </collision>
  </link>
  <link name="hd_link6">
    <inertial>
      <origin rpy="0 0 0" xyz="0.0068379243827132175 0.05694988563890202 -0.006998024700884231"/>
      <mass value="1.7329993951645233"/>
      <inertia ixx="0.003586" ixy="-0.000155" ixz="0.000189" iyy="0.002091" iyz="-9e-06" izz="0.002336"/>
    </inertial>
    <visual>
      <origin rpy="0 0 0" xyz="-0.148761 -0.629862 -0.449364"/>
      <geometry>
        <mesh filename="package://rover_description/meshes/new_hd/link_6_1.stl" scale="0.001 0.001 0.001"/>
      </geometry>
      <material name="silver"/>
    </visual>
    <collision>
      <origin rpy="0 0 0" xyz="-0.148761 -0.629862 -0.449364"/>
      <geometry>
        <mesh filename="package://rover_description/meshes/new_hd/link_6_1.stl" scale="0.001 0.001 0.001"/>
      </geometry>
    </collision>
  </link>
  <link name="Gripper_Arcs_v1_1">
    <inertial>
      <origin rpy="0 0 0" xyz="0.0032046409818504706 0.02179918196608699 -0.0327963271004742"/>
      <mass value="0.11098435196969862"/>
      <inertia ixx="0.000116" ixy="-1.4e-05" ixz="6e-06" iyy="2.6e-05" iyz="3e-05" izz="9.6e-05"/>
    </inertial>
    <visual>
      <origin rpy="0 0 0" xyz="-0.139762 -0.725909 -0.421506"/>
      <geometry>
        <mesh filename="package://rover_description/meshes/new_hd/Gripper_Arcs_v1_1.stl" scale="0.001 0.001 0.001"/>
      </geometry>
      <material name="silver"/>
    </visual>
    <collision>
      <origin rpy="0 0 0" xyz="-0.139762 -0.725909 -0.421506"/>
      <geometry>
        <mesh filename="package://rover_description/meshes/new_hd/Gripper_Arcs_v1_1.stl" scale="0.001 0.001 0.001"/>
      </geometry>
    </collision>
  </link>
  <link name="Gripper_Finger_v1_1">
    <inertial>
      <origin rpy="0 0 0" xyz="0.023381449181451852 -0.0033549268355534956 -0.005946789572352451"/>
      <mass value="0.21136162569656056"/>
      <inertia ixx="3.7e-05" ixy="2e-06" ixz="0.0" iyy="5.6e-05" iyz="-2e-06" izz="3.4e-05"/>
    </inertial>
    <visual>
      <origin rpy="0 0 0" xyz="-0.153478 -0.800615 -0.379727"/>
      <geometry>
        <mesh filename="package://rover_description/meshes/new_hd/Gripper_Finger_v1_1.stl" scale="0.001 0.001 0.001"/>
      </geometry>
      <material name="silver"/>
    </visual>
    <collision>
      <origin rpy="0 0 0" xyz="-0.153478 -0.800615 -0.379727"/>
      <geometry>
        <mesh filename="package://rover_description/meshes/new_hd/Gripper_Finger_v1_1.stl" scale="0.001 0.001 0.001"/>
      </geometry>
    </collision>
  </link>
  <link name="Gripper_Arcs_v1__2__1">
    <inertial>
      <origin rpy="0 0 0" xyz="-0.0037295922171562967 0.03252274690034984 0.022124051579247295"/>
      <mass value="0.11098435196969862"/>
      <inertia ixx="0.000117" ixy="-1.1e-05" ixz="2e-06" iyy="1.3e-05" iyz="-0.0" izz="0.000107"/>
    </inertial>
    <visual>
      <origin rpy="0 0 0" xyz="-0.135804 -0.729418 -0.451036"/>
      <geometry>
        <mesh filename="package://rover_description/meshes/new_hd/Gripper_Arcs_v1__2__1.stl" scale="0.001 0.001 0.001"/>
      </geometry>
      <material name="silver"/>
    </visual>
    <collision>
      <origin rpy="0 0 0" xyz="-0.135804 -0.729418 -0.451036"/>
      <geometry>
        <mesh filename="package://rover_description/meshes/new_hd/Gripper_Arcs_v1__2__1.stl" scale="0.001 0.001 0.001"/>
      </geometry>
    </collision>
  </link>
  <link name="Gripper_Finger_v1__1__1">
    <inertial>
      <origin rpy="0 0 0" xyz="0.020918878059417806 -0.0011722824247640817 0.012422973814116889"/>
      <mass value="0.21136162569656056"/>
      <inertia ixx="3.7e-05" ixy="2e-06" ixz="0.0" iyy="5.6e-05" iyz="-2e-06" izz="3.4e-05"/>
    </inertial>
    <visual>
      <origin rpy="0 0 0" xyz="-0.142591 -0.81484 -0.464138"/>
      <geometry>
        <mesh filename="package://rover_description/meshes/new_hd/Gripper_Finger_v1__1__1.stl" scale="0.001 0.001 0.001"/>
      </geometry>
      <material name="silver"/>
    </visual>
    <collision>
      <origin rpy="0 0 0" xyz="-0.142591 -0.81484 -0.464138"/>
      <geometry>
        <mesh filename="package://rover_description/meshes/new_hd/Gripper_Finger_v1__1__1.stl" scale="0.001 0.001 0.001"/>
      </geometry>
    </collision>
  </link>
  <joint name="hd_joint1" type="continuous">
    <!-- <origin xyz="0.007012 0.143312 0.484988" rpy="0 0 0"/> -->
    <origin rpy="1.5707963267948966 0 0" xyz="0 0 0"/>
    <parent link="base"/>
    <child link="hd_link1"/>
    <axis xyz="0 1 0"/>
  </joint>
  <joint name="hd_joint2" type="continuous">
    <origin rpy="0 0 0" xyz="0.104169 0.1185 0.056489"/>
    <parent link="hd_link1"/>
    <child link="hd_link2"/>
    <axis xyz="0.879067 0.0 0.476699"/>
  </joint>
  <joint name="hd_joint3" type="continuous">
    <origin rpy="0 0 0" xyz="-0.14594 0.209699 0.269123"/>
    <parent link="hd_link2"/>
    <child link="hd_link3"/>
    <axis xyz="-0.879067 -0.0 -0.476699"/>
  </joint>
  <joint name="hd_joint4" type="continuous">
    <origin rpy="0 0 0" xyz="-0.048089 0.014221 -0.159905"/>
    <parent link="hd_link3"/>
    <child link="hd_link4"/>
    <axis xyz="0.473254 0.120008 -0.872713"/>
  </joint>
  <joint name="hd_joint5" type="continuous">
    <origin rpy="0 0 0" xyz="0.113532 0.033504 -0.244971"/>
    <parent link="hd_link4"/>
    <child link="hd_link5"/>
    <axis xyz="0.880882 -0.054511 0.470187"/>
  </joint>
  <joint name="hd_joint6" type="continuous">
    <origin rpy="0 0 0" xyz="0.118077 0.110626 0.04364"/>
    <parent link="hd_link5"/>
    <child link="hd_link6"/>
    <axis xyz="0.115545 0.98806 -0.101919"/>
  </joint>
  <joint name="hd_joint7" type="fixed">
    <origin rpy="0 0 0" xyz="-0.008999 0.096047 -0.027858"/>
    <parent link="hd_link6"/>
    <child link="Gripper_Arcs_v1_1"/>
    <axis xyz="-0.9845 0.100287 -0.14388"/>
  </joint>
  <joint name="hd_joint8" type="fixed">
    <origin rpy="0 0 0" xyz="0.013716 0.074706 -0.041779"/>
    <parent link="Gripper_Arcs_v1_1"/>
    <child link="Gripper_Finger_v1_1"/>
    <axis xyz="0.9845 -0.100287 0.14388"/>
  </joint>
  <joint name="hd_joint9" type="fixed">
    <origin rpy="0 0 0" xyz="-0.012957 0.099556 0.001672"/>
    <parent link="hd_link6"/>
    <child link="Gripper_Arcs_v1__2__1"/>
    <axis xyz="-0.9845 0.100287 -0.14388"/>
  </joint>
  <joint name="hd_joint10" type="fixed">
    <origin rpy="0 0 0" xyz="0.006787 0.085422 0.013102"/>
    <parent link="Gripper_Arcs_v1__2__1"/>
    <child link="Gripper_Finger_v1__1__1"/>
    <axis xyz="0.9845 -0.100287 0.14388"/>
  </joint>
   --&gt;


  <!-- <xacro:include filename="package://rover_description/description/ros2_control_arm.xacro" /> -->
  <link name="base_link"/>
  <joint name="chassis_joint" type="fixed">
    <parent link="base_link"/>
    <child link="chassis_link"/>
    <origin rpy="0 0 0" xyz="0 0 0 "/>
    <axis xyz="0.0 1.0 0.0"/>
  </joint>
  <link name="chassis_link">
    <inertial>
      <origin rpy="0 0 0" xyz="0.05362398614035063 0.01974617698532859 0.037120813316089823"/>
      <!-- <mass value="6.257043020156179"/> -->
      <mass value="50"/>
      <inertia ixx="0.340644" ixy="0.000337" ixz="-0.092411" iyy="0.466541" iyz="0.00055" izz="0.402706"/>
    </inertial>
    <visual>
      <origin rpy="0 0 0" xyz="0 0 0"/>
      <geometry>
        <mesh filename="package://rover_description/meshes/base_link.stl" scale="0.001 0.001 0.001"/>
      </geometry>
      <material name="blue"/>
    </visual>
    <!-- <collision>
    <origin xyz="0 0 0" rpy="0 0 0"/>
    <geometry>
      <mesh filename="package://rover_description/meshes/base_link.stl" scale="0.001 0.001 0.001"/>
    </geometry>
  </collision> -->
  </link>
  <link name="steering3_link">
    <inertial>
      <origin rpy="0 0 0" xyz="-0.01189644601781037 -0.036027929982466456 -0.2129618322901442"/>
      <mass value="0.3543584805415501"/>
      <inertia ixx="0.003558" ixy="2e-06" ixz="-0.000178" iyy="0.003121" iyz="-0.000206" izz="0.000562"/>
    </inertial>
    <visual>
      <origin rpy="0 0 0" xyz="-0.421384 -0.393882 0.063562"/>
      <geometry>
        <mesh filename="package://rover_description/meshes/steering_1.stl" scale="0.001 0.001 0.001"/>
      </geometry>
      <material name="silver"/>
    </visual>
    <collision>
      <origin rpy="0 0 0" xyz="-0.421384 -0.393882 0.063562"/>
      <geometry>
        <mesh filename="package://rover_description/meshes/steering_1.stl" scale="0.001 0.001 0.001"/>
      </geometry>
    </collision>
  </link>
  <link name="steering4_link">
    <inertial>
      <origin rpy="0 0 0" xyz="0.011896575272170529 0.03602765244982159 -0.21296112839152875"/>
      <mass value="0.3543584805415501"/>
      <inertia ixx="0.003558" ixy="2e-06" ixz="0.000178" iyy="0.003121" iyz="0.000206" izz="0.000562"/>
    </inertial>
    <visual>
      <origin rpy="0 0 0" xyz="-0.42341 0.353934 0.012408"/>
      <geometry>
        <mesh filename="package://rover_description/meshes/steering_2.stl" scale="0.001 0.001 0.001"/>
      </geometry>
      <material name="silver"/>
    </visual>
    <collision>
      <origin rpy="0 0 0" xyz="-0.42341 0.353934 0.012408"/>
      <geometry>
        <mesh filename="package://rover_description/meshes/steering_2.stl" scale="0.001 0.001 0.001"/>
      </geometry>
    </collision>
  </link>
  <link name="steering1_link">
    <inertial>
      <origin rpy="0 0 0" xyz="0.011896795779964109 0.03602765244982109 -0.21296183229014454"/>
      <mass value="0.3543584805415501"/>
      <inertia ixx="0.003558" ixy="2e-06" ixz="0.000178" iyy="0.003121" iyz="0.000206" izz="0.000562"/>
    </inertial>
    <visual>
      <origin rpy="0 0 0" xyz="0.408171 0.353934 0.063562"/>
      <geometry>
        <mesh filename="package://rover_description/meshes/steering_3.stl" scale="0.001 0.001 0.001"/>
      </geometry>
      <material name="silver"/>
    </visual>
    <collision>
      <origin rpy="0 0 0" xyz="0.408171 0.353934 0.063562"/>
      <geometry>
        <mesh filename="package://rover_description/meshes/steering_3.stl" scale="0.001 0.001 0.001"/>
      </geometry>
    </collision>
  </link>
  <link name="steering2_link">
    <inertial>
      <origin rpy="0 0 0" xyz="-0.011896225510015512 -0.036027929982466234 -0.21296112839152861"/>
      <mass value="0.3543584805415501"/>
      <inertia ixx="0.003558" ixy="2e-06" ixz="-0.000178" iyy="0.003121" iyz="-0.000206" izz="0.000562"/>
    </inertial>
    <visual>
      <origin rpy="0 0 0" xyz="0.410197 -0.393882 0.012408"/>
      <geometry>
        <mesh filename="package://rover_description/meshes/steering_4.stl" scale="0.001 0.001 0.001"/>
      </geometry>
      <material name="silver"/>
    </visual>
    <collision>
      <origin rpy="0 0 0" xyz="0.410197 -0.393882 0.012408"/>
      <geometry>
        <mesh filename="package://rover_description/meshes/steering_4.stl" scale="0.001 0.001 0.001"/>
      </geometry>
    </collision>
  </link>
  <link name="wheel2_1ink">
    <inertial>
      <origin rpy="0 0 0" xyz="0.0003394916280188287 -0.010196510227617639 -2.006330920018007e-05"/>
      <mass value="1.592763813314383"/>
      <inertia ixx="0.010896" ixy="-0.000257" ixz="-0.0" iyy="0.018605" iyz="1.6e-05" izz="0.010887"/>
    </inertial>
    <visual>
      <origin rpy="0 0 0" xyz="0.42733 -0.410572 0.281864"/>
      <geometry>
        <mesh filename="package://rover_description/meshes/wheel3_1.stl" scale="0.001 0.001 0.001"/>
      </geometry>
      <material name="pink"/>
    </visual>
    <collision>
      <origin rpy="0 0 0" xyz="0.42733 -0.410572 0.281864"/>
      <geometry>
        <mesh filename="package://rover_description/meshes/wheel3_1.stl" scale="0.001 0.001 0.001"/>
      </geometry>
    </collision>
  </link>
  <link name="wheel3_1ink">
    <inertial>
      <origin rpy="0 0 0" xyz="0.0003392711202230836 -0.010196510227618527 -1.9767207815879484e-05"/>
      <mass value="1.592763813314383"/>
      <inertia ixx="0.010896" ixy="-0.000257" ixz="-0.0" iyy="0.018605" iyz="1.6e-05" izz="0.010887"/>
    </inertial>
    <visual>
      <origin rpy="0 0 0" xyz="-0.404251 -0.410572 0.333019"/>
      <geometry>
        <mesh filename="package://rover_description/meshes/wheel4_1.stl" scale="0.001 0.001 0.001"/>
      </geometry>
      <material name="pink"/>
    </visual>
    <collision>
      <origin rpy="0 0 0" xyz="-0.404251 -0.410572 0.333019"/>
      <geometry>
        <mesh filename="package://rover_description/meshes/wheel4_1.stl" scale="0.001 0.001 0.001"/>
      </geometry>
    </collision>
  </link>
  <link name="wheel1_1ink">
    <inertial>
      <origin rpy="0 0 0" xyz="-0.0003399213580693172 0.010197232694972913 -1.9767207816323573e-05"/>
      <mass value="1.592763813314383"/>
      <inertia ixx="0.010896" ixy="-0.000257" ixz="0.0" iyy="0.018605" iyz="-1.6e-05" izz="0.010887"/>
    </inertial>
    <visual>
      <origin rpy="0 0 0" xyz="0.391037 0.370625 0.333019"/>
      <geometry>
        <mesh filename="package://rover_description/meshes/wheel2_1.stl" scale="0.001 0.001 0.001"/>
      </geometry>
      <material name="pink"/>
    </visual>
    <collision>
      <origin rpy="0 0 0" xyz="0.391037 0.370625 0.333019"/>
      <geometry>
        <mesh filename="package://rover_description/meshes/wheel2_1.stl" scale="0.001 0.001 0.001"/>
      </geometry>
    </collision>
  </link>
  <link name="wheel4_1ink">
    <inertial>
      <origin rpy="0 0 0" xyz="-0.0003391418658636458 0.010197232694973468 -2.0063309200568646e-05"/>
      <mass value="1.592763813314383"/>
      <inertia ixx="0.010896" ixy="-0.000257" ixz="0.0" iyy="0.018605" iyz="-1.6e-05" izz="0.010887"/>
    </inertial>
    <visual>
      <origin rpy="0 0 0" xyz="-0.440543 0.370625 0.281864"/>
      <geometry>
        <mesh filename="package://rover_description/meshes/wheel1_1.stl" scale="0.001 0.001 0.001"/>
      </geometry>
      <material name="pink"/>
    </visual>
    <collision>
      <origin rpy="0 0 0" xyz="-0.440543 0.370625 0.281864"/>
      <geometry>
        <mesh filename="package://rover_description/meshes/wheel1_1.stl" scale="0.001 0.001 0.001"/>
      </geometry>
    </collision>
  </link>
  <link name="right_leg">
    <inertial>
      <origin rpy="0 0 0" xyz="0.0009668399350314201 0.11623489359260658 0.013375805290350871"/>
      <mass value="1.6615144825592312"/>
      <inertia ixx="0.007103" ixy="-5.6e-05" ixz="0.013196" iyy="0.220618" iyz="-0.000815" izz="0.220639"/>
    </inertial>
    <visual>
      <origin rpy="0 0 0" xyz="-0.006607 -0.250474 0.021516"/>
      <geometry>
        <mesh filename="package://rover_description/meshes/pivot_droit_1.stl" scale="0.001 0.001 0.001"/>
      </geometry>
      <material name="black"/>
    </visual>
    <collision>
      <origin rpy="0 0 0" xyz="-0.006607 -0.250474 0.021516"/>
      <geometry>
        <mesh filename="package://rover_description/meshes/pivot_droit_1.stl" scale="0.001 0.001 0.001"/>
      </geometry>
    </collision>
  </link>
  <link name="left_leg">
    <inertial>
      <origin rpy="0 0 0" xyz="-0.0009674901728771402 -0.11623517112525206 0.013375805290350576"/>
      <mass value="1.6615144825592312"/>
      <inertia ixx="0.007103" ixy="-5.6e-05" ixz="-0.013196" iyy="0.220618" iyz="0.000815" izz="0.220639"/>
    </inertial>
    <visual>
      <origin rpy="0 0 0" xyz="-0.006607 0.210526 0.021516"/>
      <geometry>
        <mesh filename="package://rover_description/meshes/pivot_gauche_1.stl" scale="0.001 0.001 0.001"/>
      </geometry>
      <material name="black"/>
    </visual>
    <collision>
      <origin rpy="0 0 0" xyz="-0.006607 0.210526 0.021516"/>
      <geometry>
        <mesh filename="package://rover_description/meshes/pivot_gauche_1.stl" scale="0.001 0.001 0.001"/>
      </geometry>
    </collision>
  </link>
  <!-- Caster wheel (not needed if fixed base-->
  <joint name="chassis_to_caster_axis" type="continuous">
    <origin rpy="0 -0.6 0" xyz="0.3 0.0 -0.225"/>
    <axis xyz="0 0 1"/>
    <parent link="chassis_link"/>
    <child link="caster_axis"/>
  </joint>
  <link name="caster_axis">
    <visual>
      <geometry>
        <cylinder length="0.41" radius="0.005"/>
      </geometry>
    </visual>
    <collision>
      <geometry>
        <cylinder length="0.41" radius="0.005"/>
      </geometry>
    </collision>
    <inertial>
      <origin xyz="0 0 0"/>
      <mass value="0.25"/>
      <inertia ixx="0.0035036458333333326" ixy="0.0" ixz="0.0" iyy="0.0035036458333333326" iyz="0.0" izz="3.125e-06"/>
    </inertial>
  </link>
  <joint name="caster_axis_to_caster_wheel" type="continuous">
    <origin rpy="1.5707963267948966 0 0" xyz="0 0 -0.25"/>
    <parent link="caster_axis"/>
    <axis xyz="0 0 1"/>
    <child link="caster_wheel"/>
  </joint>
  <link name="caster_wheel">
    <visual>
      <geometry>
        <cylinder length="0.05" radius="0.05"/>
      </geometry>
    </visual>
    <collision>
      <origin rpy="0 0 0" xyz="0 0 0"/>
      <geometry>
        <cylinder length="0.05" radius="0.05"/>
      </geometry>
    </collision>
    <inertial>
      <origin xyz="0 0 0"/>
      <mass value="15"/>
      <inertia ixx="0.012500000000000002" ixy="0.0" ixz="0.0" iyy="0.012500000000000002" iyz="0.0" izz="0.018750000000000003"/>
    </inertial>
  </link>
  <joint name="chassis_to_lidar_axis" type="fixed">
    <origin rpy="0 0 0" xyz="0.2 0.20 0.12"/>
    <parent link="chassis_link"/>
    <child link="lidar_axis"/>
  </joint>
  <link name="lidar_axis">
    <visual>
      <geometry>
        <cylinder length="0.24" radius="0.005"/>
      </geometry>
      <material name="white"/>
    </visual>
    <collision>
      <geometry>
        <cylinder length="0.24" radius="0.005"/>
      </geometry>
    </collision>
    <inertial>
      <origin xyz="0 0 0"/>
      <mass value="0.25"/>
      <inertia ixx="0.0012015625" ixy="0.0" ixz="0.0" iyy="0.0012015625" iyz="0.0" izz="3.125e-06"/>
    </inertial>
  </link>
  <joint name="steering3" type="fixed">
    <origin rpy="0 0 0" xyz="0.414777 0.143408 -0.042046"/>
    <parent link="right_leg"/>
    <child link="steering3_link"/>
    <axis xyz="-0.061399 0.0 -0.998113"/>
  </joint>
  <joint name="steering4" type="fixed">
    <origin rpy="0 0 0" xyz="0.416803 -0.143408 0.009108"/>
    <parent link="left_leg"/>
    <child link="steering4_link"/>
    <axis xyz="-0.061399 0.0 0.998113"/>
  </joint>
  <joint name="steering1" type="fixed">
    <origin rpy="0 0 0" xyz="-0.414778 -0.143408 -0.042046"/>
    <parent link="left_leg"/>
    <child link="steering1_link"/>
    <axis xyz="0.061399 -0.0 -0.998113"/>
  </joint>
  <joint name="steering2" type="fixed">
    <origin rpy="0 0 0" xyz="-0.416804 0.143408 0.009108"/>
    <parent link="right_leg"/>
    <child link="steering2_link"/>
    <axis xyz="0.061399 -0.0 0.998113"/>
  </joint>
  <joint name="driving2" type="fixed">
    <origin rpy="0 0 0" xyz="-0.017133 0.01669 -0.269456"/>
    <parent link="steering2_link"/>
    <child link="wheel2_1ink"/>
    <axis xyz="-0.033267 0.999444 0.002046"/>
  </joint>
  <joint name="driving3" type="fixed">
    <origin rpy="0 0 0" xyz="-0.017133 0.01669 -0.269457"/>
    <parent link="steering3_link"/>
    <child link="wheel3_1ink"/>
    <axis xyz="-0.033267 0.999444 0.002046"/>
  </joint>
  <joint name="driving1" type="fixed">
    <origin rpy="0 0 0" xyz="0.017134 -0.016691 -0.269457"/>
    <parent link="steering1_link"/>
    <child link="wheel1_1ink"/>
    <axis xyz="0.033267 -0.999444 0.002046"/>
  </joint>
  <joint name="driving4" type="fixed">
    <origin rpy="0 0 0" xyz="0.017133 -0.016691 -0.269456"/>
    <parent link="steering4_link"/>
    <child link="wheel4_1ink"/>
    <axis xyz="0.033267 -0.999444 0.002046"/>
  </joint>
  <!--  Controllable rover base -->
  <!-- <joint name="right_pivot" type="fixed">
  <origin xyz="-0.1 0.250474 -0.021516" rpy="0 0 0"/>
  <parent link="chassis_link"/>
  <child link="right_leg"/>
  <axis xyz="0.0 1.0 0.0"/>
</joint>

<joint name="left_pivot" type="fixed">
  <origin xyz="-0.1 -0.210526 -0.021516" rpy="0 0 0"/>
  <parent link="chassis_link"/>
  <child link="left_leg"/>
   <mimic joint="right_pivot" multiplier="-1.0" />
  <axis xyz="0.0 1.0 0.0"/>
</joint> -->
  <joint name="right_pivot" type="fixed">
    <origin rpy="0 0 0" xyz="0 0.250474 -0.021516"/>
    <parent link="chassis_link"/>
    <child link="right_leg"/>
    <axis xyz="0.0 1.0 0.0"/>
    <!-- <limit>
    <lower>-0.1</lower>
    <upper>0.1</upper>
    <effort>300</effort>
    <velocity>5</velocity>
  </limit>  -->
  </joint>
  <joint name="left_pivot" type="fixed">
    <origin rpy="0 0 0" xyz="0 -0.210526 -0.021516"/>
    <parent link="chassis_link"/>
    <child link="left_leg"/>
    <mimic joint="right_pivot" multiplier="-1.0"/>
    <axis xyz="0.0 1.0 0.0"/>
    <!-- <limit>
    <lower>-0.1</lower>
    <upper>0.1</upper>
    <effort>300</effort>
    <velocity>5</velocity>
  </limit> -->
  </joint>
</robot>
