<?xml version="1.0" ?>
<!-- =================================================================================== -->
<!-- |    This document was autogenerated by xacro from URDF3.urdf.xacro               | -->
<!-- |    EDITING THIS FILE BY HAND IS NOT RECOMMENDED                                 | -->
<!-- =================================================================================== -->
<robot name="new_hd">
  <gazebo>
    <plugin filename="libgazebo_ros_control.so" name="control"/>
  </gazebo>
  <gazebo reference="base">
    <material>Gazebo/Red</material>
    <mu1>0.2</mu1>
    <mu2>0.2</mu2>
    
  // 
    <selfCollide>true</selfCollide>
    
  // 
    <gravity>true</gravity>
  </gazebo>
  <gazebo reference="hd_link1">
    <material>Gazebo/Blue</material>
    <mu1>0.2</mu1>
    <mu2>0.2</mu2>
    
  // 
    <selfCollide>true</selfCollide>
  </gazebo>
  <gazebo reference="hd_link2">
    <material>Gazebo/Red</material>
    <mu1>0.2</mu1>
    <mu2>0.2</mu2>
    
  // 
    <selfCollide>true</selfCollide>
  </gazebo>
  <gazebo reference="hd_link3">
    <material>Gazebo/Blue</material>
    <mu1>0.2</mu1>
    <mu2>0.2</mu2>
    
  // 
    <selfCollide>true</selfCollide>
  </gazebo>
  <gazebo reference="hd_link4">
    <material>Gazebo/Red</material>
    <mu1>0.2</mu1>
    <mu2>0.2</mu2>
    
  // 
    <selfCollide>true</selfCollide>
  </gazebo>
  <gazebo reference="hd_link5">
    <material>Gazebo/Blue</material>
    <mu1>0.2</mu1>
    <mu2>0.2</mu2>
    
  // 
    <selfCollide>true</selfCollide>
  </gazebo>
  <gazebo reference="hd_link6">
    <material>Gazebo/Red</material>
    <mu1>0.2</mu1>
    <mu2>0.2</mu2>
    
  // 
    <selfCollide>true</selfCollide>
  </gazebo>
  <gazebo reference="Gripper_Arcs_v1_1">
    <material>Gazebo/Blue</material>
    <mu1>0.2</mu1>
    <mu2>0.2</mu2>
    <selfCollide>true</selfCollide>
  </gazebo>
  <gazebo reference="Gripper_Finger_v1_1">
    <material>Gazebo/Red</material>
    <mu1>0.2</mu1>
    <mu2>0.2</mu2>
    
  // 
    <selfCollide>true</selfCollide>
  </gazebo>
  <gazebo reference="Gripper_Arcs_v1__2__1">
    <material>Gazebo/Blue</material>
    <mu1>0.2</mu1>
    <mu2>0.2</mu2>
    
  // 
    <selfCollide>true</selfCollide>
  </gazebo>
  <gazebo reference="Gripper_Finger_v1__1__1">
    <material>Gazebo/Red</material>
    <mu1>0.2</mu1>
    <mu2>0.2</mu2>
    
  // 
    <selfCollide>true</selfCollide>
  </gazebo>
  <!-- <xacro:include filename="$(find rover_description)/description/ros2_control_arm.xacro" /> -->
  <!-- <link name="base_link"/> -->
  <joint name="hd_joint0" type="fixed">
    <!-- <origin xyz="-0.228643 0.019974 -0.035484" rpy="0 0 ${pi}"/> -->
    <origin rpy="0 0 3.141592653589793" xyz="-0.22 0 0.035484"/>
    <parent link="chassis_link"/>
    <child link="base"/>
  </joint>
  <!-- <joint name="base_joint" type="fixed">
    <parent link="base_link"/>
    <child link="base"/>
    <origin xyz="0 0 0 " rpy="0 0 0"/>
</joint>  -->
  <link name="base">
    <inertial>
      <origin rpy="1.5707963267948966 0 0" xyz="0 0.47 -0.12"/>
      <!-- <origin xyz="0 0 0" rpy="${pi/2} 0 0"/> -->
      <mass value="1.001112718637754"/>
      <inertia ixx="0.00171" ixy="-0.0" ixz="-0.0" iyy="0.003332" iyz="0.0" izz="0.00171"/>
    </inertial>
    <visual>
      <origin rpy="1.5707963267948966 0 0" xyz="0 0.47 -0.12"/>
      <geometry>
        <mesh filename="package://rover_description/meshes/new_hd/base_link.stl" scale="0.001 0.001 0.001"/>
      </geometry>
      <material name="silver"/>
    </visual>
    <collision>
      <origin rpy="1.5707963267948966 0 0" xyz="0 0.47 -0.12"/>
      <geometry>
        <mesh filename="package://rover_description/meshes/new_hd/base_link.stl" scale="0.001 0.001 0.001"/>
      </geometry>
    </collision>
  </link>
  <link name="hd_link1">
    <inertial>
      <origin rpy="0 0 0" xyz="0.023340582081130535 0.09194845459261852 0.0126568969650096"/>
      <mass value="13.941603234564111"/>
      <inertia ixx="0.039361" ixy="-0.009386" ixz="-0.007119" iyy="0.035501" iyz="-0.00509" izz="0.048628"/>
    </inertial>
    <visual>
      <origin rpy="0 0 0" xyz="-0.007012 -0.143312 -0.484988"/>
      <geometry>
        <mesh filename="package://rover_description/meshes/new_hd/link_1_1.stl" scale="0.001 0.001 0.001"/>
      </geometry>
      <material name="silver"/>
    </visual>
    <collision>
      <origin rpy="0 0 0" xyz="-0.007012 -0.143312 -0.484988"/>
      <geometry>
        <mesh filename="package://rover_description/meshes/new_hd/link_1_1.stl" scale="0.001 0.001 0.001"/>
      </geometry>
    </collision>
  </link>
  <link name="hd_link2">
    <inertial>
      <origin rpy="0 0 0" xyz="-0.08423197746352788 0.10484954848092454 0.1284542941455662"/>
      <mass value="3.1130721114751427"/>
      <inertia ixx="0.055243" ixy="0.012697" ixz="0.016949" iyy="0.044626" iyz="-0.023414" izz="0.033179"/>
    </inertial>
    <visual>
      <origin rpy="0 0 0" xyz="-0.111181 -0.261812 -0.541477"/>
      <geometry>
        <mesh filename="package://rover_description/meshes/new_hd/link_2_1.stl" scale="0.001 0.001 0.001"/>
      </geometry>
      <material name="silver"/>
    </visual>
    <collision>
      <origin rpy="0 0 0" xyz="-0.111181 -0.261812 -0.541477"/>
      <geometry>
        <mesh filename="package://rover_description/meshes/new_hd/link_2_1.stl" scale="0.001 0.001 0.001"/>
      </geometry>
    </collision>
  </link>
  <link name="hd_link3">
    <inertial>
      <origin rpy="0 0 0" xyz="-0.06826283209546892 0.0031862398429799987 -0.06700337059280337"/>
      <mass value="13.941603234564111"/>
      <inertia ixx="0.04444" ixy="0.000162" ixz="-0.005885" iyy="0.052244" iyz="0.00239" izz="0.026806"/>
    </inertial>
    <visual>
      <origin rpy="0 0 0" xyz="0.034759 -0.471511 -0.8106"/>
      <geometry>
        <mesh filename="package://rover_description/meshes/new_hd/link_3_1.stl" scale="0.001 0.001 0.001"/>
      </geometry>
      <material name="silver"/>
    </visual>
    <collision>
      <origin rpy="0 0 0" xyz="0.034759 -0.471511 -0.8106"/>
      <geometry>
        <mesh filename="package://rover_description/meshes/new_hd/link_3_1.stl" scale="0.001 0.001 0.001"/>
      </geometry>
    </collision>
  </link>
  <link name="hd_link4">
    <inertial>
      <origin rpy="0 0 0" xyz="0.06826896232783315 0.01808291361303932 -0.13171586513395195"/>
      <mass value="2.3441890740360654"/>
      <inertia ixx="0.022767" ixy="-0.001236" ixz="0.009066" iyy="0.026136" iyz="0.002399" izz="0.00899"/>
    </inertial>
    <visual>
      <origin rpy="0 0 0" xyz="0.082848 -0.485732 -0.650695"/>
      <geometry>
        <mesh filename="package://rover_description/meshes/new_hd/link_4_1.stl" scale="0.001 0.001 0.001"/>
      </geometry>
      <material name="silver"/>
    </visual>
    <collision>
      <origin rpy="0 0 0" xyz="0.082848 -0.485732 -0.650695"/>
      <geometry>
        <mesh filename="package://rover_description/meshes/new_hd/link_4_1.stl" scale="0.001 0.001 0.001"/>
      </geometry>
    </collision>
  </link>
  <link name="hd_link5">
    <inertial>
      <origin rpy="0 0 0" xyz="0.08406378219626617 0.021222804231640358 0.04052714111106276"/>
      <mass value="13.941603234564111"/>
      <inertia ixx="0.036907" ixy="-0.010349" ixz="-0.006458" iyy="0.037003" iyz="-0.002873" izz="0.04958"/>
    </inertial>
    <visual>
      <origin rpy="0 0 0" xyz="-0.030684 -0.519236 -0.405724"/>
      <geometry>
        <mesh filename="package://rover_description/meshes/new_hd/link_5_1.stl" scale="0.001 0.001 0.001"/>
      </geometry>
      <material name="silver"/>
    </visual>
    <collision>
      <origin rpy="0 0 0" xyz="-0.030684 -0.519236 -0.405724"/>
      <geometry>
        <mesh filename="package://rover_description/meshes/new_hd/link_5_1.stl" scale="0.001 0.001 0.001"/>
      </geometry>
    </collision>
  </link>
  <link name="hd_link6">
    <inertial>
      <origin rpy="0 0 0" xyz="0.0068379243827132175 0.05694988563890202 -0.006998024700884231"/>
      <mass value="1.7329993951645233"/>
      <inertia ixx="0.003586" ixy="-0.000155" ixz="0.000189" iyy="0.002091" iyz="-9e-06" izz="0.002336"/>
    </inertial>
    <visual>
      <origin rpy="0 0 0" xyz="-0.148761 -0.629862 -0.449364"/>
      <geometry>
        <mesh filename="package://rover_description/meshes/new_hd/link_6_1.stl" scale="0.001 0.001 0.001"/>
      </geometry>
      <material name="silver"/>
    </visual>
    <collision>
      <origin rpy="0 0 0" xyz="-0.148761 -0.629862 -0.449364"/>
      <geometry>
        <mesh filename="package://rover_description/meshes/new_hd/link_6_1.stl" scale="0.001 0.001 0.001"/>
      </geometry>
    </collision>
  </link>
  <link name="Gripper_Arcs_v1_1">
    <inertial>
      <origin rpy="0 0 0" xyz="0.0032046409818504706 0.02179918196608699 -0.0327963271004742"/>
      <mass value="0.11098435196969862"/>
      <inertia ixx="0.000116" ixy="-1.4e-05" ixz="6e-06" iyy="2.6e-05" iyz="3e-05" izz="9.6e-05"/>
    </inertial>
    <visual>
      <origin rpy="0 0 0" xyz="-0.139762 -0.725909 -0.421506"/>
      <geometry>
        <mesh filename="package://rover_description/meshes/new_hd/Gripper_Arcs_v1_1.stl" scale="0.001 0.001 0.001"/>
      </geometry>
      <material name="silver"/>
    </visual>
    <collision>
      <origin rpy="0 0 0" xyz="-0.139762 -0.725909 -0.421506"/>
      <geometry>
        <mesh filename="package://rover_description/meshes/new_hd/Gripper_Arcs_v1_1.stl" scale="0.001 0.001 0.001"/>
      </geometry>
    </collision>
  </link>
  <link name="Gripper_Finger_v1_1">
    <inertial>
      <origin rpy="0 0 0" xyz="0.023381449181451852 -0.0033549268355534956 -0.005946789572352451"/>
      <mass value="0.21136162569656056"/>
      <inertia ixx="3.7e-05" ixy="2e-06" ixz="0.0" iyy="5.6e-05" iyz="-2e-06" izz="3.4e-05"/>
    </inertial>
    <visual>
      <origin rpy="0 0 0" xyz="-0.153478 -0.800615 -0.379727"/>
      <geometry>
        <mesh filename="package://rover_description/meshes/new_hd/Gripper_Finger_v1_1.stl" scale="0.001 0.001 0.001"/>
      </geometry>
      <material name="silver"/>
    </visual>
    <collision>
      <origin rpy="0 0 0" xyz="-0.153478 -0.800615 -0.379727"/>
      <geometry>
        <mesh filename="package://rover_description/meshes/new_hd/Gripper_Finger_v1_1.stl" scale="0.001 0.001 0.001"/>
      </geometry>
    </collision>
  </link>
  <link name="Gripper_Arcs_v1__2__1">
    <inertial>
      <origin rpy="0 0 0" xyz="-0.0037295922171562967 0.03252274690034984 0.022124051579247295"/>
      <mass value="0.11098435196969862"/>
      <inertia ixx="0.000117" ixy="-1.1e-05" ixz="2e-06" iyy="1.3e-05" iyz="-0.0" izz="0.000107"/>
    </inertial>
    <visual>
      <origin rpy="0 0 0" xyz="-0.135804 -0.729418 -0.451036"/>
      <geometry>
        <mesh filename="package://rover_description/meshes/new_hd/Gripper_Arcs_v1__2__1.stl" scale="0.001 0.001 0.001"/>
      </geometry>
      <material name="silver"/>
    </visual>
    <collision>
      <origin rpy="0 0 0" xyz="-0.135804 -0.729418 -0.451036"/>
      <geometry>
        <mesh filename="package://rover_description/meshes/new_hd/Gripper_Arcs_v1__2__1.stl" scale="0.001 0.001 0.001"/>
      </geometry>
    </collision>
  </link>
  <link name="Gripper_Finger_v1__1__1">
    <inertial>
      <origin rpy="0 0 0" xyz="0.020918878059417806 -0.0011722824247640817 0.012422973814116889"/>
      <mass value="0.21136162569656056"/>
      <inertia ixx="3.7e-05" ixy="2e-06" ixz="0.0" iyy="5.6e-05" iyz="-2e-06" izz="3.4e-05"/>
    </inertial>
    <visual>
      <origin rpy="0 0 0" xyz="-0.142591 -0.81484 -0.464138"/>
      <geometry>
        <mesh filename="package://rover_description/meshes/new_hd/Gripper_Finger_v1__1__1.stl" scale="0.001 0.001 0.001"/>
      </geometry>
      <material name="silver"/>
    </visual>
    <collision>
      <origin rpy="0 0 0" xyz="-0.142591 -0.81484 -0.464138"/>
      <geometry>
        <mesh filename="package://rover_description/meshes/new_hd/Gripper_Finger_v1__1__1.stl" scale="0.001 0.001 0.001"/>
      </geometry>
    </collision>
  </link>
  <joint name="hd_joint1" type="continuous">
    <!-- <origin xyz="0.007012 0.143312 0.484988" rpy="0 0 0"/> -->
    <origin rpy="1.5707963267948966 0 0" xyz="0 0 0"/>
    <parent link="base"/>
    <child link="hd_link1"/>
    <axis xyz="0 1 0"/>
  </joint>
  <joint name="hd_joint2" type="continuous">
    <origin rpy="0 0 0" xyz="0.104169 0.1185 0.056489"/>
    <parent link="hd_link1"/>
    <child link="hd_link2"/>
    <axis xyz="0.879067 0.0 0.476699"/>
  </joint>
  <joint name="hd_joint3" type="continuous">
    <origin rpy="0 0 0" xyz="-0.14594 0.209699 0.269123"/>
    <parent link="hd_link2"/>
    <child link="hd_link3"/>
    <axis xyz="-0.879067 -0.0 -0.476699"/>
  </joint>
  <joint name="hd_joint4" type="continuous">
    <origin rpy="0 0 0" xyz="-0.048089 0.014221 -0.159905"/>
    <parent link="hd_link3"/>
    <child link="hd_link4"/>
    <axis xyz="0.473254 0.120008 -0.872713"/>
  </joint>
  <joint name="hd_joint5" type="continuous">
    <origin rpy="0 0 0" xyz="0.113532 0.033504 -0.244971"/>
    <parent link="hd_link4"/>
    <child link="hd_link5"/>
    <axis xyz="0.880882 -0.054511 0.470187"/>
  </joint>
  <joint name="hd_joint6" type="continuous">
    <origin rpy="0 0 0" xyz="0.118077 0.110626 0.04364"/>
    <parent link="hd_link5"/>
    <child link="hd_link6"/>
    <axis xyz="0.115545 0.98806 -0.101919"/>
  </joint>
  <joint name="hd_joint7" type="fixed">
    <origin rpy="0 0 0" xyz="-0.008999 0.096047 -0.027858"/>
    <parent link="hd_link6"/>
    <child link="Gripper_Arcs_v1_1"/>
    <axis xyz="-0.9845 0.100287 -0.14388"/>
  </joint>
  <joint name="hd_joint8" type="fixed">
    <origin rpy="0 0 0" xyz="0.013716 0.074706 -0.041779"/>
    <parent link="Gripper_Arcs_v1_1"/>
    <child link="Gripper_Finger_v1_1"/>
    <axis xyz="0.9845 -0.100287 0.14388"/>
  </joint>
  <joint name="hd_joint9" type="fixed">
    <origin rpy="0 0 0" xyz="-0.012957 0.099556 0.001672"/>
    <parent link="hd_link6"/>
    <child link="Gripper_Arcs_v1__2__1"/>
    <axis xyz="-0.9845 0.100287 -0.14388"/>
  </joint>
  <joint name="hd_joint10" type="fixed">
    <origin rpy="0 0 0" xyz="0.006787 0.085422 0.013102"/>
    <parent link="Gripper_Arcs_v1__2__1"/>
    <child link="Gripper_Finger_v1__1__1"/>
    <axis xyz="0.9845 -0.100287 0.14388"/>
  </joint>
   --&gt;


</robot>
