<?xml version="1.0" ?>
<robot name="URDF3" xmlns:xacro="http://www.ros.org/wiki/xacro">

<xacro:include filename="$(find URDF3_description)/urdf/materials.xacro" />
<xacro:include filename="$(find URDF3_description)/urdf/URDF3.trans" />
<xacro:include filename="$(find URDF3_description)/urdf/URDF3.gazebo" />
<link name="base_link">
  <inertial>
    <origin xyz="-0.029879818542253234 0.15340462037121128 0.5605796895339228" rpy="0 0 0"/>
    <mass value="1.001112718637754"/>
    <inertia ixx="0.00171" iyy="0.003332" izz="0.00171" ixy="-0.0" iyz="-0.0" ixz="0.0"/>
  </inertial>
  <visual>
    <origin xyz="0 0 0" rpy="0 0 0"/>
    <geometry>
      <mesh filename="file://$(find URDF3_description)/meshes/base_link.stl" scale="0.001 0.001 0.001"/>
    </geometry>
    <material name="silver"/>
  </visual>
  <collision>
    <origin xyz="0 0 0" rpy="0 0 0"/>
    <geometry>
      <mesh filename="file://$(find URDF3_description)/meshes/base_link.stl" scale="0.001 0.001 0.001"/>
    </geometry>
  </collision>
</link>

<link name="link_1_1">
  <inertial>
    <origin xyz="0.023341018537840326 0.09194838159618982 0.012656931022134277" rpy="0 0 0"/>
    <mass value="13.941603234564111"/>
    <inertia ixx="0.039361" iyy="0.035501" izz="0.048628" ixy="-0.009386" iyz="-0.00509" ixz="-0.007119"/>
  </inertial>
  <visual>
    <origin xyz="0.02988 -0.159629 -0.56058" rpy="0 0 0"/>
    <geometry>
      <mesh filename="file://$(find URDF3_description)/meshes/link_1_1.stl" scale="0.001 0.001 0.001"/>
    </geometry>
    <material name="silver"/>
  </visual>
  <collision>
    <origin xyz="0.02988 -0.159629 -0.56058" rpy="0 0 0"/>
    <geometry>
      <mesh filename="file://$(find URDF3_description)/meshes/link_1_1.stl" scale="0.001 0.001 0.001"/>
    </geometry>
  </collision>
</link>

<link name="link_2_1">
  <inertial>
    <origin xyz="-0.08423254100681848 0.10484947548449375 0.12845432820269032" rpy="0 0 0"/>
    <mass value="3.1130721114751427"/>
    <inertia ixx="0.055243" iyy="0.044626" izz="0.033179" ixy="0.012697" iyz="-0.023414" ixz="0.016949"/>
  </inertial>
  <visual>
    <origin xyz="-0.07429 -0.278129 -0.617069" rpy="0 0 0"/>
    <geometry>
      <mesh filename="file://$(find URDF3_description)/meshes/link_2_1.stl" scale="0.001 0.001 0.001"/>
    </geometry>
    <material name="silver"/>
  </visual>
  <collision>
    <origin xyz="-0.07429 -0.278129 -0.617069" rpy="0 0 0"/>
    <geometry>
      <mesh filename="file://$(find URDF3_description)/meshes/link_2_1.stl" scale="0.001 0.001 0.001"/>
    </geometry>
  </collision>
</link>

<link name="link_3_1">
  <inertial>
    <origin xyz="-0.06826239563875915 0.0031861668465493764 -0.0670033365356777" rpy="0 0 0"/>
    <mass value="13.941603234564111"/>
    <inertia ixx="0.04444" iyy="0.052244" izz="0.026806" ixy="0.000162" iyz="0.00239" ixz="-0.005885"/>
  </inertial>
  <visual>
    <origin xyz="0.071651 -0.487828 -0.886192" rpy="0 0 0"/>
    <geometry>
      <mesh filename="file://$(find URDF3_description)/meshes/aaaaaaaaaaaaaa.stl" scale="0.001 0.001 0.001"/>
    </geometry>
    <material name="silver"/>
  </visual>
  <collision>
    <origin xyz="0.071651 -0.487828 -0.886192" rpy="0 0 0"/>
    <geometry>
      <mesh filename="file://$(find URDF3_description)/meshes/link_2_1.stl" scale="0.001 0.001 0.001"/>
    </geometry>
  </collision>
</link>

<link name="link_4_1">
  <inertial>
    <origin xyz="0.06826839878454309 0.01808284061660692 -0.1317158310768265" rpy="0 0 0"/>
    <mass value="2.3441890740360654"/>
    <inertia ixx="0.022767" iyy="0.026136" izz="0.00899" ixy="-0.001236" iyz="0.002399" ixz="0.009066"/>
  </inertial>
  <visual>
    <origin xyz="0.119739 -0.502049 -0.726287" rpy="0 0 0"/>
    <geometry>
      <mesh filename="file://$(find URDF3_description)/meshes/link_4_1.stl" scale="0.001 0.001 0.001"/>
    </geometry>
    <material name="silver"/>
  </visual>
  <collision>
    <origin xyz="0.119739 -0.502049 -0.726287" rpy="0 0 0"/>
    <geometry>
      <mesh filename="file://$(find URDF3_description)/meshes/link_4_1.stl" scale="0.001 0.001 0.001"/>
    </geometry>
  </collision>
</link>

<link name="link_5_1">
  <inertial>
    <origin xyz="0.0840632186529757 0.021222731235207237 0.040527175168186214" rpy="0 0 0"/>
    <mass value="13.941603234564111"/>
    <inertia ixx="0.036907" iyy="0.037003" izz="0.04958" ixy="-0.010349" iyz="-0.002873" ixz="-0.006458"/>
  </inertial>
  <visual>
    <origin xyz="0.006207 -0.535553 -0.481316" rpy="0 0 0"/>
    <geometry>
      <mesh filename="file://$(find URDF3_description)/meshes/link_5_1.stl" scale="0.001 0.001 0.001"/>
    </geometry>
    <material name="silver"/>
  </visual>
  <collision>
    <origin xyz="0.006207 -0.535553 -0.481316" rpy="0 0 0"/>
    <geometry>
      <mesh filename="file://$(find URDF3_description)/meshes/link_5_1.stl" scale="0.001 0.001 0.001"/>
    </geometry>
  </collision>
</link>

<link name="link_6_1">
  <inertial>
    <origin xyz="0.006838360839422852 0.05694981264246779 -0.006997990643761054" rpy="0 0 0"/>
    <mass value="1.7329993951645233"/>
    <inertia ixx="0.003586" iyy="0.002091" izz="0.002336" ixy="-0.000155" iyz="-9e-06" ixz="0.000189"/>
  </inertial>
  <visual>
    <origin xyz="-0.111869 -0.646179 -0.524956" rpy="0 0 0"/>
    <geometry>
      <mesh filename="file://$(find URDF3_description)/meshes/link_6_1.stl" scale="0.001 0.001 0.001"/>
    </geometry>
    <material name="silver"/>
  </visual>
  <collision>
    <origin xyz="-0.111869 -0.646179 -0.524956" rpy="0 0 0"/>
    <geometry>
      <mesh filename="file://$(find URDF3_description)/meshes/link_6_1.stl" scale="0.001 0.001 0.001"/>
    </geometry>
  </collision>
</link>

<link name="link_8_1">
  <inertial>
    <origin xyz="0.0026700547725347495 0.033274287017572624 -0.021136994267583142" rpy="0 0 0"/>
    <mass value="0.11098435196969862"/>
    <inertia ixx="0.000117" iyy="1.4e-05" izz="0.000107" ixy="-1e-05" iyz="-6e-06" ixz="1e-06"/>
  </inertial>
  <visual>
    <origin xyz="-0.10287 -0.742226 -0.497098" rpy="0 0 0"/>
    <geometry>
      <mesh filename="file://$(find URDF3_description)/meshes/link_8_1.stl" scale="0.001 0.001 0.001"/>
    </geometry>
    <material name="silver"/>
  </visual>
  <collision>
    <origin xyz="-0.10287 -0.742226 -0.497098" rpy="0 0 0"/>
    <geometry>
      <mesh filename="file://$(find URDF3_description)/meshes/link_8_1.stl" scale="0.001 0.001 0.001"/>
    </geometry>
  </collision>
</link>

<link name="link_9_1">
  <inertial>
    <origin xyz="0.023381631817404824 -0.003354345913246015 -0.005946895456361234" rpy="0 0 0"/>
    <mass value="0.21136162569656056"/>
    <inertia ixx="3.7e-05" iyy="5.6e-05" izz="3.4e-05" ixy="2e-06" iyz="-2e-06" ixz="0.0"/>
  </inertial>
  <visual>
    <origin xyz="-0.112729 -0.828008 -0.489433" rpy="0 0 0"/>
    <geometry>
      <mesh filename="file://$(find URDF3_description)/meshes/link_9_1.stl" scale="0.001 0.001 0.001"/>
    </geometry>
    <material name="silver"/>
  </visual>
  <collision>
    <origin xyz="-0.112729 -0.828008 -0.489433" rpy="0 0 0"/>
    <geometry>
      <mesh filename="file://$(find URDF3_description)/meshes/link_9_1.stl" scale="0.001 0.001 0.001"/>
    </geometry>
  </collision>
</link>

<link name="link_7_1">
  <inertial>
    <origin xyz="-0.0016397440612819364 0.03776929491140868 0.011484294390729732" rpy="0 0 0"/>
    <mass value="0.11098435196969862"/>
    <inertia ixx="0.000116" iyy="2.3e-05" izz="9.9e-05" ixy="-1.4e-05" iyz="2.6e-05" ixz="6e-06"/>
  </inertial>
  <visual>
    <origin xyz="-0.098912 -0.745735 -0.526628" rpy="0 0 0"/>
    <geometry>
      <mesh filename="file://$(find URDF3_description)/meshes/link_7_1.stl" scale="0.001 0.001 0.001"/>
    </geometry>
    <material name="silver"/>
  </visual>
  <collision>
    <origin xyz="-0.098912 -0.745735 -0.526628" rpy="0 0 0"/>
    <geometry>
      <mesh filename="file://$(find URDF3_description)/meshes/link_7_1.stl" scale="0.001 0.001 0.001"/>
    </geometry>
  </collision>
</link>

<link name="link_10_1">
  <inertial>
    <origin xyz="0.020920920577857563 -0.001158344156213964 0.012421744255080802" rpy="0 0 0"/>
    <mass value="0.21136162569656056"/>
    <inertia ixx="3.7e-05" iyy="5.6e-05" izz="3.4e-05" ixy="2e-06" iyz="-2e-06" ixz="0.0"/>
  </inertial>
  <visual>
    <origin xyz="-0.109498 -0.830759 -0.513458" rpy="0 0 0"/>
    <geometry>
      <mesh filename="file://$(find URDF3_description)/meshes/link_10_1.stl" scale="0.001 0.001 0.001"/>
    </geometry>
    <material name="silver"/>
  </visual>
  <collision>
    <origin xyz="-0.109498 -0.830759 -0.513458" rpy="0 0 0"/>
    <geometry>
      <mesh filename="file://$(find URDF3_description)/meshes/link_10_1.stl" scale="0.001 0.001 0.001"/>
    </geometry>
  </collision>
</link>

<joint name="Revolute 23" type="continuous">
  <origin xyz="-0.02988 0.159629 0.56058" rpy="0 0 0"/>
  <parent link="base_link"/>
  <child link="link_1_1"/>
  <axis xyz="-0.0 1.0 -0.0"/>
</joint>

<joint name="Revolute 24" type="continuous">
  <origin xyz="0.10417 0.1185 0.056489" rpy="0 0 0"/>
  <parent link="link_1_1"/>
  <child link="link_2_1"/>
  <axis xyz="0.879067 0.0 0.476699"/>
</joint>

<joint name="Revolute 25" type="continuous">
  <origin xyz="-0.145941 0.209699 0.269123" rpy="0 0 0"/>
  <parent link="link_2_1"/>
  <child link="link_3_1"/>
  <axis xyz="-0.879067 -0.0 -0.476699"/>
</joint>

<joint name="Revolute 26" type="continuous">
  <origin xyz="-0.048088 0.014221 -0.159905" rpy="0 0 0"/>
  <parent link="link_3_1"/>
  <child link="link_4_1"/>
  <axis xyz="0.473254 0.120008 -0.872713"/>
</joint>

<joint name="Revolute 27" type="continuous">
  <origin xyz="0.113532 0.033504 -0.244971" rpy="0 0 0"/>
  <parent link="link_4_1"/>
  <child link="link_5_1"/>
  <axis xyz="0.880882 -0.054511 0.470187"/>
</joint>

<joint name="Revolute 28" type="continuous">
  <origin xyz="0.118076 0.110626 0.04364" rpy="0 0 0"/>
  <parent link="link_5_1"/>
  <child link="link_6_1"/>
  <axis xyz="0.115545 0.98806 -0.101919"/>
</joint>

<joint name="Revolute 29" type="continuous">
  <origin xyz="-0.008999 0.096047 -0.027858" rpy="0 0 0"/>
  <parent link="link_6_1"/>
  <child link="link_8_1"/>
  <axis xyz="-0.9845 0.100287 -0.14388"/>
</joint>

<joint name="Revolute 30" type="continuous">
  <origin xyz="0.009859 0.085782 -0.007665" rpy="0 0 0"/>
  <parent link="link_8_1"/>
  <child link="link_9_1"/>
  <axis xyz="-0.9845 0.100287 -0.14388"/>
</joint>

<joint name="Revolute 31" type="continuous">
  <origin xyz="-0.012957 0.099556 0.001672" rpy="0 0 0"/>
  <parent link="link_6_1"/>
  <child link="link_7_1"/>
  <axis xyz="-0.9845 0.100287 -0.14388"/>
</joint>

<joint name="Revolute 32" type="continuous">
  <origin xyz="0.010586 0.085024 -0.01317" rpy="0 0 0"/>
  <parent link="link_7_1"/>
  <child link="link_10_1"/>
  <axis xyz="0.9845 -0.100287 0.14388"/>
</joint>

</robot>
