<?xml version="1.0" ?>
<robot name="kerby" xmlns:xacro="http://www.ros.org/wiki/xacro">

<xacro:include filename="$(find kerby_description)/urdf/materials.xacro" />
<xacro:include filename="$(find kerby_description)/urdf/kerby.trans" />
<xacro:include filename="$(find kerby_description)/urdf/kerby.gazebo" />


<xacro:property name="rpm_to_Radps" value="${2*pi/60.0}" />     <!-- rotations per minute to Rad per second conversion -->
<xacro:property name="velocity_scaling" value="1.0" />     <!-- allows to scale all max velocities down at once -->

<xacro:macro name="aaa_joint_limits" params="lower:=0.0 upper:=0.0 velocity:=${rpm_to_Radps} effort:=100.0">
  <limit lower="${lower}" upper="${upper}" velocity="${velocity}" effort="${effort}"/>
</xacro:macro>

<xacro:property name="joint1_limits">
  <xacro:aaa_joint_limits lower="${-1.5*pi}" upper="${1.5*pi}" velocity="${3 * rpm_to_Radps * velocity_scaling}" />
</xacro:property>

<xacro:property name="joint2_limits">
  <xacro:aaa_joint_limits lower="${-pi}" upper="${pi/2}" velocity="${1 * rpm_to_Radps * velocity_scaling}" />
</xacro:property>

<xacro:property name="joint3_limits">
  <xacro:aaa_joint_limits lower="${-pi/4}" upper="${pi/4}" velocity="${1.5 * rpm_to_Radps * velocity_scaling}" />
</xacro:property>

<xacro:property name="joint4_limits">
  <xacro:aaa_joint_limits lower="${-2*pi}" upper="${2*pi}" velocity="${6 * rpm_to_Radps * velocity_scaling}" />
</xacro:property>

<xacro:property name="joint5_limits">
  <xacro:aaa_joint_limits lower="${-pi/2}" upper="${pi/2}" velocity="${2 * rpm_to_Radps * velocity_scaling}" />
</xacro:property>

<xacro:property name="joint6_limits">
  <xacro:aaa_joint_limits lower="${-pi}" upper="${pi}" velocity="${6 * rpm_to_Radps * velocity_scaling}" />
</xacro:property>



<link name="base_link">
  <inertial>
    <origin xyz="0.05362398614035063 0.01974617698532859 0.037120813316089823" rpy="0 0 0"/>
    <mass value="6.257043020156179"/>
    <inertia ixx="0.340644" iyy="0.466541" izz="0.402706" ixy="0.000337" iyz="0.00055" ixz="-0.092411"/>
  </inertial>
  <visual>
    <origin xyz="0 0 0" rpy="0 0 0"/>
    <geometry>
      <mesh filename="package://kerby_description/meshes/base_link.stl" scale="0.001 0.001 0.001"/>
    </geometry>
    <material name="blue"/>
  </visual>
  <collision>
    <origin xyz="0 0 0" rpy="0 0 0"/>
    <geometry>
      <mesh filename="package://kerby_description/meshes/base_link.stl" scale="0.001 0.001 0.001"/>
    </geometry>
  </collision>
</link>

<link name="steering_1">
  <inertial>
    <origin xyz="-0.01189644601781037 -0.036027929982466456 -0.2129618322901442" rpy="0 0 0"/>
    <mass value="0.3543584805415501"/>
    <inertia ixx="0.003558" iyy="0.003121" izz="0.000562" ixy="2e-06" iyz="-0.000206" ixz="-0.000178"/>
  </inertial>
  <visual>
    <origin xyz="-0.421384 -0.393882 0.063562" rpy="0 0 0"/>
    <geometry>
      <mesh filename="package://kerby_description/meshes/steering_1.stl" scale="0.001 0.001 0.001"/>
    </geometry>
    <material name="silver"/>
  </visual>
  <collision>
    <origin xyz="-0.421384 -0.393882 0.063562" rpy="0 0 0"/>
    <geometry>
      <mesh filename="package://kerby_description/meshes/steering_1.stl" scale="0.001 0.001 0.001"/>
    </geometry>
  </collision>
</link>

<link name="steering_2">
  <inertial>
    <origin xyz="0.011896575272170529 0.03602765244982159 -0.21296112839152875" rpy="0 0 0"/>
    <mass value="0.3543584805415501"/>
    <inertia ixx="0.003558" iyy="0.003121" izz="0.000562" ixy="2e-06" iyz="0.000206" ixz="0.000178"/>
  </inertial>
  <visual>
    <origin xyz="-0.42341 0.353934 0.012408" rpy="0 0 0"/>
    <geometry>
      <mesh filename="package://kerby_description/meshes/steering_2.stl" scale="0.001 0.001 0.001"/>
    </geometry>
    <material name="silver"/>
  </visual>
  <collision>
    <origin xyz="-0.42341 0.353934 0.012408" rpy="0 0 0"/>
    <geometry>
      <mesh filename="package://kerby_description/meshes/steering_2.stl" scale="0.001 0.001 0.001"/>
    </geometry>
  </collision>
</link>

<link name="steering_3">
  <inertial>
    <origin xyz="0.011896795779964109 0.03602765244982109 -0.21296183229014454" rpy="0 0 0"/>
    <mass value="0.3543584805415501"/>
    <inertia ixx="0.003558" iyy="0.003121" izz="0.000562" ixy="2e-06" iyz="0.000206" ixz="0.000178"/>
  </inertial>
  <visual>
    <origin xyz="0.408171 0.353934 0.063562" rpy="0 0 0"/>
    <geometry>
      <mesh filename="package://kerby_description/meshes/steering_3.stl" scale="0.001 0.001 0.001"/>
    </geometry>
    <material name="silver"/>
  </visual>
  <collision>
    <origin xyz="0.408171 0.353934 0.063562" rpy="0 0 0"/>
    <geometry>
      <mesh filename="package://kerby_description/meshes/steering_3.stl" scale="0.001 0.001 0.001"/>
    </geometry>
  </collision>
</link>

<link name="steering_4">
  <inertial>
    <origin xyz="-0.011896225510015512 -0.036027929982466234 -0.21296112839152861" rpy="0 0 0"/>
    <mass value="0.3543584805415501"/>
    <inertia ixx="0.003558" iyy="0.003121" izz="0.000562" ixy="2e-06" iyz="-0.000206" ixz="-0.000178"/>
  </inertial>
  <visual>
    <origin xyz="0.410197 -0.393882 0.012408" rpy="0 0 0"/>
    <geometry>
      <mesh filename="package://kerby_description/meshes/steering_4.stl" scale="0.001 0.001 0.001"/>
    </geometry>
    <material name="silver"/>
  </visual>
  <collision>
    <origin xyz="0.410197 -0.393882 0.012408" rpy="0 0 0"/>
    <geometry>
      <mesh filename="package://kerby_description/meshes/steering_4.stl" scale="0.001 0.001 0.001"/>
    </geometry>
  </collision>
</link>

<link name="wheel3_1">
  <inertial>
    <origin xyz="0.0003394916280188287 -0.010196510227617639 -2.006330920018007e-05" rpy="0 0 0"/>
    <mass value="1.592763813314383"/>
    <inertia ixx="0.010896" iyy="0.018605" izz="0.010887" ixy="-0.000257" iyz="1.6e-05" ixz="-0.0"/>
  </inertial>
  <visual>
    <origin xyz="0.42733 -0.410572 0.281864" rpy="0 0 0"/>
    <geometry>
      <mesh filename="package://kerby_description/meshes/wheel3_1.stl" scale="0.001 0.001 0.001"/>
    </geometry>
    <material name="pink"/>
  </visual>
  <collision>
    <origin xyz="0.42733 -0.410572 0.281864" rpy="0 0 0"/>
    <geometry>
      <mesh filename="package://kerby_description/meshes/wheel3_1.stl" scale="0.001 0.001 0.001"/>
    </geometry>
  </collision>
</link>

<link name="wheel4_1">
  <inertial>
    <origin xyz="0.0003392711202230836 -0.010196510227618527 -1.9767207815879484e-05" rpy="0 0 0"/>
    <mass value="1.592763813314383"/>
    <inertia ixx="0.010896" iyy="0.018605" izz="0.010887" ixy="-0.000257" iyz="1.6e-05" ixz="-0.0"/>
  </inertial>
  <visual>
    <origin xyz="-0.404251 -0.410572 0.333019" rpy="0 0 0"/>
    <geometry>
      <mesh filename="package://kerby_description/meshes/wheel4_1.stl" scale="0.001 0.001 0.001"/>
    </geometry>
    <material name="pink"/>
  </visual>
  <collision>
    <origin xyz="-0.404251 -0.410572 0.333019" rpy="0 0 0"/>
    <geometry>
      <mesh filename="package://kerby_description/meshes/wheel4_1.stl" scale="0.001 0.001 0.001"/>
    </geometry>
  </collision>
</link>

<link name="wheel2_1">
  <inertial>
    <origin xyz="-0.0003399213580693172 0.010197232694972913 -1.9767207816323573e-05" rpy="0 0 0"/>
    <mass value="1.592763813314383"/>
    <inertia ixx="0.010896" iyy="0.018605" izz="0.010887" ixy="-0.000257" iyz="-1.6e-05" ixz="0.0"/>
  </inertial>
  <visual>
    <origin xyz="0.391037 0.370625 0.333019" rpy="0 0 0"/>
    <geometry>
      <mesh filename="package://kerby_description/meshes/wheel2_1.stl" scale="0.001 0.001 0.001"/>
    </geometry>
    <material name="pink"/>
  </visual>
  <collision>
    <origin xyz="0.391037 0.370625 0.333019" rpy="0 0 0"/>
    <geometry>
      <mesh filename="package://kerby_description/meshes/wheel2_1.stl" scale="0.001 0.001 0.001"/>
    </geometry>
  </collision>
</link>

<link name="wheel1_1">
  <inertial>
    <origin xyz="-0.0003391418658636458 0.010197232694973468 -2.0063309200568646e-05" rpy="0 0 0"/>
    <mass value="1.592763813314383"/>
    <inertia ixx="0.010896" iyy="0.018605" izz="0.010887" ixy="-0.000257" iyz="-1.6e-05" ixz="0.0"/>
  </inertial>
  <visual>
    <origin xyz="-0.440543 0.370625 0.281864" rpy="0 0 0"/>
    <geometry>
      <mesh filename="package://kerby_description/meshes/wheel1_1.stl" scale="0.001 0.001 0.001"/>
    </geometry>
    <material name="pink"/>
  </visual>
  <collision>
    <origin xyz="-0.440543 0.370625 0.281864" rpy="0 0 0"/>
    <geometry>
      <mesh filename="package://kerby_description/meshes/wheel1_1.stl" scale="0.001 0.001 0.001"/>
    </geometry>
  </collision>
</link>

<link name="hd_link2_1">
  <inertial>
    <origin xyz="0.007428383283974271 0.060838810370171845 0.14389716626077925" rpy="0 0 0"/>
    <mass value="2.4452075265656514"/>
    <inertia ixx="0.038674" iyy="0.03827" izz="0.003075" ixy="7.8e-05" iyz="0.001607" ixz="-0.00107"/>
  </inertial>
  <visual>
    <origin xyz="0.228643 0.037726 -0.152484" rpy="0 0 0"/>
    <geometry>
      <mesh filename="package://kerby_description/meshes/hd_link2_1.stl" scale="0.001 0.001 0.001"/>
    </geometry>
    <material name="black"/>
  </visual>
  <collision>
    <origin xyz="0.228643 0.037726 -0.152484" rpy="0 0 0"/>
    <geometry>
      <mesh filename="package://kerby_description/meshes/hd_link2_1.stl" scale="0.001 0.001 0.001"/>
    </geometry>
  </collision>
</link>

<link name="hd_link3_1">
  <inertial>
    <origin xyz="-0.18506431602380205 -0.028188690485378982 0.03515465538516083" rpy="0 0 0"/>
    <mass value="0.3993227194340243"/>
    <inertia ixx="0.000842" iyy="0.00625" izz="0.00637" ixy="4.5e-05" iyz="-5e-06" ixz="0.000238"/>
  </inertial>
  <visual>
    <origin xyz="0.2165 -0.050274 -0.552396" rpy="0 0 0"/>
    <geometry>
      <mesh filename="package://kerby_description/meshes/hd_link3_1.stl" scale="0.001 0.001 0.001"/>
    </geometry>
    <material name="black"/>
  </visual>
  <collision>
    <origin xyz="0.2165 -0.050274 -0.552396" rpy="0 0 0"/>
    <geometry>
      <mesh filename="package://kerby_description/meshes/hd_link3_1.stl" scale="0.001 0.001 0.001"/>
    </geometry>
  </collision>
</link>

<link name="hd_link4_1">
  <inertial>
    <origin xyz="-0.02651321084424607 0.002896584112952065 -0.0003217450612928996" rpy="0 0 0"/>
    <mass value="0.16590781468918114"/>
    <inertia ixx="0.000197" iyy="0.000349" izz="0.000476" ixy="3.9e-05" iyz="5e-06" ixz="4e-06"/>
  </inertial>
  <visual>
    <origin xyz="0.531508 -0.02063 -0.590536" rpy="0 0 0"/>
    <geometry>
      <mesh filename="package://kerby_description/meshes/hd_link4_1.stl" scale="0.001 0.001 0.001"/>
    </geometry>
    <material name="silver"/>
  </visual>
  <collision>
    <origin xyz="0.531508 -0.02063 -0.590536" rpy="0 0 0"/>
    <geometry>
      <mesh filename="package://kerby_description/meshes/hd_link4_1.stl" scale="0.001 0.001 0.001"/>
    </geometry>
  </collision>
</link>

<link name="hd_link5_1">
  <inertial>
    <origin xyz="-0.0032697164246294763 0.03846028201984416 -9.33050693235904e-05" rpy="0 0 0"/>
    <mass value="0.06877842327462745"/>
    <inertia ixx="4.9e-05" iyy="2.9e-05" izz="4.3e-05" ixy="1e-06" iyz="0.0" ixz="-0.0"/>
  </inertial>
  <visual>
    <origin xyz="0.625201 0.02137 -0.591679" rpy="0 0 0"/>
    <geometry>
      <mesh filename="package://kerby_description/meshes/hd_link5_1.stl" scale="0.001 0.001 0.001"/>
    </geometry>
    <material name="silver"/>
  </visual>
  <collision>
    <origin xyz="0.625201 0.02137 -0.591679" rpy="0 0 0"/>
    <geometry>
      <mesh filename="package://kerby_description/meshes/hd_link5_1.stl" scale="0.001 0.001 0.001"/>
    </geometry>
  </collision>
</link>

<link name="hd_link6_1">
  <inertial>
    <origin xyz="-0.03519419436746607 -0.0007187354689699374 0.0009221743273718497" rpy="0 0 0"/>
    <mass value="0.11153016933793788"/>
    <inertia ixx="0.000117" iyy="0.000166" izz="0.000263" ixy="-2e-06" iyz="-1e-06" ixz="1e-06"/>
  </inertial>
  <visual>
    <origin xyz="0.652201 -0.02059 -0.591797" rpy="0 0 0"/>
    <geometry>
      <mesh filename="package://kerby_description/meshes/hd_link6_1.stl" scale="0.001 0.001 0.001"/>
    </geometry>
    <material name="silver"/>
  </visual>
  <collision>
    <origin xyz="0.652201 -0.02059 -0.591797" rpy="0 0 0"/>
    <geometry>
      <mesh filename="package://kerby_description/meshes/hd_link6_1.stl" scale="0.001 0.001 0.001"/>
    </geometry>
  </collision>
</link>

<link name="hd_finger2_1">
  <inertial>
    <origin xyz="0.47666706754454413 -0.7361417133269437 -0.01622358994727202" rpy="0 0 0"/>
    <mass value="0.025342855198124774"/>
    <inertia ixx="4e-06" iyy="1.8e-05" izz="1.6e-05" ixy="-2e-06" iyz="-0.0" ixz="-2e-06"/>
  </inertial>
  <visual>
    <origin xyz="1.231487 -0.764267 -0.611515" rpy="0 0 0"/>
    <geometry>
      <mesh filename="package://kerby_description/meshes/hd_finger2_1.stl" scale="0.001 0.001 0.001"/>
    </geometry>
    <material name="silver"/>
  </visual>
  <collision>
    <origin xyz="1.231487 -0.764267 -0.611515" rpy="0 0 0"/>
    <geometry>
      <mesh filename="package://kerby_description/meshes/hd_finger2_1.stl" scale="0.001 0.001 0.001"/>
    </geometry>
  </collision>
</link>

<link name="hd_finger1_1">
  <inertial>
    <origin xyz="0.4527983426832546 -0.7504874421753438 -0.06638458975098571" rpy="0 0 0"/>
    <mass value="0.025342855198124774"/>
    <inertia ixx="4e-06" iyy="1.8e-05" izz="1.6e-05" ixy="2e-06" iyz="-0.0" ixz="2e-06"/>
  </inertial>
  <visual>
    <origin xyz="1.208101 -0.764188 -0.655601" rpy="0 0 0"/>
    <geometry>
      <mesh filename="package://kerby_description/meshes/hd_finger1_1.stl" scale="0.001 0.001 0.001"/>
    </geometry>
    <material name="silver"/>
  </visual>
  <collision>
    <origin xyz="1.208101 -0.764188 -0.655601" rpy="0 0 0"/>
    <geometry>
      <mesh filename="package://kerby_description/meshes/hd_finger1_1.stl" scale="0.001 0.001 0.001"/>
    </geometry>
  </collision>
</link>

<link name="hd_motor_j3_1">
  <inertial>
    <origin xyz="-0.3146867524268133 0.14188869096939155 0.25591208107402835" rpy="0 0 0"/>
    <mass value="0.11925838600046076"/>
    <inertia ixx="0.00051" iyy="0.000525" izz="2.9e-05" ixy="-0.0" iyz="-0.0" ixz="-8.7e-05"/>
  </inertial>
  <visual>
    <origin xyz="-0.173508 0.122615 -0.149258" rpy="0 0 0"/>
    <geometry>
      <mesh filename="package://kerby_description/meshes/hd_motor_j3_1.stl" scale="0.001 0.001 0.001"/>
    </geometry>
    <material name="silver"/>
  </visual>
  <collision>
    <origin xyz="-0.173508 0.122615 -0.149258" rpy="0 0 0"/>
    <geometry>
      <mesh filename="package://kerby_description/meshes/hd_motor_j3_1.stl" scale="0.001 0.001 0.001"/>
    </geometry>
  </collision>
</link>

<link name="pivot_droit_1">
  <inertial>
    <origin xyz="0.0009668399350314201 0.11623489359260658 0.013375805290350871" rpy="0 0 0"/>
    <mass value="1.6615144825592312"/>
    <inertia ixx="0.007103" iyy="0.220618" izz="0.220639" ixy="-5.6e-05" iyz="-0.000815" ixz="0.013196"/>
  </inertial>
  <visual>
    <origin xyz="-0.006607 -0.250474 0.021516" rpy="0 0 0"/>
    <geometry>
      <mesh filename="package://kerby_description/meshes/pivot_droit_1.stl" scale="0.001 0.001 0.001"/>
    </geometry>
    <material name="black"/>
  </visual>
  <collision>
    <origin xyz="-0.006607 -0.250474 0.021516" rpy="0 0 0"/>
    <geometry>
      <mesh filename="package://kerby_description/meshes/pivot_droit_1.stl" scale="0.001 0.001 0.001"/>
    </geometry>
  </collision>
</link>

<link name="pivot_gauche_1">
  <inertial>
    <origin xyz="-0.0009674901728771402 -0.11623517112525206 0.013375805290350576" rpy="0 0 0"/>
    <mass value="1.6615144825592312"/>
    <inertia ixx="0.007103" iyy="0.220618" izz="0.220639" ixy="-5.6e-05" iyz="0.000815" ixz="-0.013196"/>
  </inertial>
  <visual>
    <origin xyz="-0.006607 0.210526 0.021516" rpy="0 0 0"/>
    <geometry>
      <mesh filename="package://kerby_description/meshes/pivot_gauche_1.stl" scale="0.001 0.001 0.001"/>
    </geometry>
    <material name="black"/>
  </visual>
  <collision>
    <origin xyz="-0.006607 0.210526 0.021516" rpy="0 0 0"/>
    <geometry>
      <mesh filename="package://kerby_description/meshes/pivot_gauche_1.stl" scale="0.001 0.001 0.001"/>
    </geometry>
  </collision>
</link>

<link name="hd_link1_1">
  <inertial>
    <origin xyz="0.0001907779404468346 0.014210297972432132 0.0484216801173539" rpy="0 0 0"/>
    <mass value="0.3391136619658369"/>
    <inertia ixx="0.001801" iyy="0.001217" izz="0.00078" ixy="1e-05" iyz="-0.000142" ixz="-8e-06"/>
  </inertial>
  <visual>
    <origin xyz="0.228643 -0.019974 -0.035484" rpy="0 0 0"/>
    <geometry>
      <mesh filename="package://kerby_description/meshes/hd_link1_1.stl" scale="0.001 0.001 0.001"/>
    </geometry>
    <material name="silver"/>
  </visual>
  <collision>
    <origin xyz="0.228643 -0.019974 -0.035484" rpy="0 0 0"/>
    <geometry>
      <mesh filename="package://kerby_description/meshes/hd_link1_1.stl" scale="0.001 0.001 0.001"/>
    </geometry>
  </collision>
</link>

<joint name="steering1" type="continuous">
  <origin xyz="0.414777 0.143408 -0.042046" rpy="0 0 0"/>
  <parent link="pivot_droit_1"/>
  <child link="steering_1"/>
  <axis xyz="-0.061399 0.0 -0.998113"/>
</joint>

<joint name="steering2" type="continuous">
  <origin xyz="0.416803 -0.143408 0.009108" rpy="0 0 0"/>
  <parent link="pivot_gauche_1"/>
  <child link="steering_2"/>
  <axis xyz="-0.061399 0.0 0.998113"/>
</joint>

<joint name="steering3" type="continuous">
  <origin xyz="-0.414778 -0.143408 -0.042046" rpy="0 0 0"/>
  <parent link="pivot_gauche_1"/>
  <child link="steering_3"/>
  <axis xyz="0.061399 -0.0 -0.998113"/>
</joint>

<joint name="steering4" type="continuous">
  <origin xyz="-0.416804 0.143408 0.009108" rpy="0 0 0"/>
  <parent link="pivot_droit_1"/>
  <child link="steering_4"/>
  <axis xyz="0.061399 -0.0 0.998113"/>
</joint>

<joint name="driving4" type="continuous">
  <origin xyz="-0.017133 0.01669 -0.269456" rpy="0 0 0"/>
  <parent link="steering_4"/>
  <child link="wheel3_1"/>
  <axis xyz="-0.033267 0.999444 0.002046"/>
</joint>

<joint name="driving1" type="continuous">
  <origin xyz="-0.017133 0.01669 -0.269457" rpy="0 0 0"/>
  <parent link="steering_1"/>
  <child link="wheel4_1"/>
  <axis xyz="-0.033267 0.999444 0.002046"/>
</joint>

<joint name="driving3" type="continuous">
  <origin xyz="0.017134 -0.016691 -0.269457" rpy="0 0 0"/>
  <parent link="steering_3"/>
  <child link="wheel2_1"/>
  <axis xyz="0.033267 -0.999444 0.002046"/>
</joint>

<joint name="driving2" type="continuous">
  <origin xyz="0.017133 -0.016691 -0.269456" rpy="0 0 0"/>
  <parent link="steering_2"/>
  <child link="wheel1_1"/>
  <axis xyz="0.033267 -0.999444 0.002046"/>
</joint>

<joint name="joint2" type="revolute">
  <origin xyz="0.0 -0.0577 0.117" rpy="0 0 0"/>
  <parent link="hd_link1_1"/>
  <child link="hd_link2_1"/>
  <axis xyz="0.0 1.0 0.0"/>
  <xacro:insert_block name="joint2_limits" />
</joint>

<joint name="joint3" type="revolute">
  <origin xyz="0.012143 0.088 0.399912" rpy="0 0 0"/>
  <parent link="hd_link2_1"/>
  <child link="hd_link3_1"/>
  <axis xyz="-0.0 1.0 0.0"/>
  <xacro:insert_block name="joint3_limits" />
</joint>

<joint name="joint4" type="revolute">
  <origin xyz="-0.315008 -0.029644 0.03814" rpy="0 0 0"/>
  <parent link="hd_link3_1"/>
  <child link="hd_link4_1"/>
  <axis xyz="0.999926 0.0 -0.012203"/>
  <xacro:insert_block name="joint4_limits" />
</joint>

<joint name="joint5" type="revolute">
  <origin xyz="-0.093693 -0.042 0.001143" rpy="0 0 0"/>
  <parent link="hd_link4_1"/>
  <child link="hd_link5_1"/>
  <axis xyz="0.0 -1.0 0.0"/>
  <xacro:insert_block name="joint5_limits" />
</joint>

<joint name="joint6" type="revolute">
  <origin xyz="-0.027 0.04196 0.000118" rpy="0 0 0"/>
  <parent link="hd_link5_1"/>
  <child link="hd_link6_1"/>
  <axis xyz="-0.99999 -0.0 0.00438"/>
  <xacro:insert_block name="joint6_limits" />
</joint>

<joint name="finger1" type="prismatic">
  <origin xyz="-0.579286 0.743677 0.019718" rpy="0 0 0"/>
  <parent link="hd_link6_1"/>
  <child link="hd_finger2_1"/>
  <axis xyz="0.007905 0.999801 0.018314"/>
  <limit upper="0.0" lower="0.0" effort="100" velocity="100"/>
</joint>

<joint name="finger2" type="prismatic">
  <origin xyz="-0.5559 0.743598 0.063804" rpy="0 0 0"/>
  <parent link="hd_link6_1"/>
  <child link="hd_finger1_1"/>
  <axis xyz="0.007905 0.999801 0.018314"/>
  <limit upper="0.0" lower="0.0" effort="100" velocity="100"/>
  <mimic joint="finger1" multiplier="-1" offset="0"/>
</joint>

<joint name="moteurJ3" type="fixed">
  <origin xyz="0.402151 -0.084889 -0.003226" rpy="0 0 0"/>
  <parent link="hd_link2_1"/>
  <child link="hd_motor_j3_1"/>
</joint>

<joint name="pivot_gauche" type="continuous">
  <origin xyz="0.006607 0.250474 -0.021516" rpy="0 0 0"/>
  <parent link="base_link"/>
  <child link="pivot_droit_1"/>
  <axis xyz="-0.0 1.0 0.0"/>
</joint>

<joint name="pivot_droit" type="continuous">
  <origin xyz="0.006607 -0.210526 -0.021516" rpy="0 0 0"/>
  <parent link="base_link"/>
  <child link="pivot_gauche_1"/>
  <axis xyz="0.0 1.0 0.0"/>
</joint>

<joint name="joint1" type="revolute">
  <origin xyz="-0.228643 0.019974 0.035484" rpy="0 0 0"/>
  <parent link="base_link"/>
  <child link="hd_link1_1"/>
  <axis xyz="-0.0 0.0 -1.0"/>
  <xacro:insert_block name="joint1_limits" />
</joint>

</robot>
