<?xml version="1.0" ?>
<robot name="new_hd" xmlns:xacro="http://www.ros.org/wiki/xacro">

<!-- <xacro:include filename="$(find onyx_description)/description/materials3.xacro" /> -->
<!-- <xacro:include filename="$(find onyx_description)/description/URDF3.trans" /> -->
<xacro:include filename="$(find onyx_description)/description/URDF3.gazebo" />
<!-- <xacro:include filename="$(find onyx_description)/description/ros2_control_arm.xacro" /> -->



<!-- <link name="base_link"/> -->

<joint name="hd_joint0" type="fixed">
  <!-- <origin xyz="-0.228643 0.019974 -0.035484" rpy="0 0 ${pi}"/> -->
  <origin xyz="-0.22 0 0.035484" rpy="0 0 ${pi}"/>
  <parent link="chassis_link"/>
  <child link="base"/>
</joint> 


 <!-- <joint name="base_joint" type="fixed">
    <parent link="base_link"/>
    <child link="base"/>
    <origin xyz="0 0 0 " rpy="0 0 0"/>
</joint>  -->

<link name="base">
  <inertial>
    <origin xyz="0 0.47 -0.12" rpy="${pi/2} 0 0"/>
    <!-- <origin xyz="0 0 0" rpy="${pi/2} 0 0"/> -->
    <mass value="1.001112718637754"/>
    <inertia ixx="0.00171" iyy="0.003332" izz="0.00171" ixy="-0.0" iyz="0.0" ixz="-0.0"/>
  </inertial>
  <visual>
    <origin xyz="0 0.47 -0.12" rpy="${pi/2} 0 0"/>
    <geometry>
      <mesh filename="package://onyx_description/meshes/new_hd/base_link.stl" scale="0.001 0.001 0.001"/>
    </geometry>
    <material name="silver"/>
  </visual>
  <collision>
    <origin xyz="0 0.47 -0.12" rpy="${pi/2} 0 0"/>
    <geometry>
      <mesh filename="package://onyx_description/meshes/new_hd/base_link.stl" scale="0.001 0.001 0.001"/>
    </geometry>
  </collision>
</link>

<link name="hd_link1">
  <inertial>
    <origin xyz="0.023340582081130535 0.09194845459261852 0.0126568969650096" rpy="0 0 0"/>
    <mass value="13.941603234564111"/>
    <inertia ixx="0.039361" iyy="0.035501" izz="0.048628" ixy="-0.009386" iyz="-0.00509" ixz="-0.007119"/>
  </inertial>
  <visual>
    <origin xyz="-0.007012 -0.143312 -0.484988" rpy="0 0 0"/>
    <geometry>
      <mesh filename="package://onyx_description/meshes/new_hd/link_1_1.stl" scale="0.001 0.001 0.001"/>
    </geometry>
    <material name="silver"/>
  </visual>
  <collision>
    <origin xyz="-0.007012 -0.143312 -0.484988" rpy="0 0 0"/>
    <geometry>
      <mesh filename="package://onyx_description/meshes/new_hd/link_1_1.stl" scale="0.001 0.001 0.001"/>
    </geometry>
  </collision>
</link>

<link name="hd_link2">
  <inertial>
    <origin xyz="-0.08423197746352788 0.10484954848092454 0.1284542941455662" rpy="0 0 0"/>
    <mass value="3.1130721114751427"/>
    <inertia ixx="0.055243" iyy="0.044626" izz="0.033179" ixy="0.012697" iyz="-0.023414" ixz="0.016949"/>
  </inertial>
  <visual>
    <origin xyz="-0.111181 -0.261812 -0.541477" rpy="0 0 0"/>
    <geometry>
      <mesh filename="package://onyx_description/meshes/new_hd/link_2_1.stl" scale="0.001 0.001 0.001"/>
    </geometry>
    <material name="silver"/>
  </visual>
  <collision>
    <origin xyz="-0.111181 -0.261812 -0.541477" rpy="0 0 0"/>
    <geometry>
      <mesh filename="package://onyx_description/meshes/new_hd/link_2_1.stl" scale="0.001 0.001 0.001"/>
    </geometry>
  </collision>
</link>

<link name="hd_link3">
  <inertial>
    <origin xyz="-0.06826283209546892 0.0031862398429799987 -0.06700337059280337" rpy="0 0 0"/>
    <mass value="13.941603234564111"/>
    <inertia ixx="0.04444" iyy="0.052244" izz="0.026806" ixy="0.000162" iyz="0.00239" ixz="-0.005885"/>
  </inertial>
  <visual>
    <origin xyz="0.034759 -0.471511 -0.8106" rpy="0 0 0"/>
    <geometry>
      <mesh filename="package://onyx_description/meshes/new_hd/link_3_1.stl" scale="0.001 0.001 0.001"/>
    </geometry>
    <material name="silver"/>
  </visual>
  <collision>
    <origin xyz="0.034759 -0.471511 -0.8106" rpy="0 0 0"/>
    <geometry>
      <mesh filename="package://onyx_description/meshes/new_hd/link_3_1.stl" scale="0.001 0.001 0.001"/>
    </geometry>
  </collision>
</link>

<link name="hd_link4">
  <inertial>
    <origin xyz="0.06826896232783315 0.01808291361303932 -0.13171586513395195" rpy="0 0 0"/>
    <mass value="2.3441890740360654"/>
    <inertia ixx="0.022767" iyy="0.026136" izz="0.00899" ixy="-0.001236" iyz="0.002399" ixz="0.009066"/>
  </inertial>
  <visual>
    <origin xyz="0.082848 -0.485732 -0.650695" rpy="0 0 0"/>
    <geometry>
      <mesh filename="package://onyx_description/meshes/new_hd/link_4_1.stl" scale="0.001 0.001 0.001"/>
    </geometry>
    <material name="silver"/>
  </visual>
  <collision>
    <origin xyz="0.082848 -0.485732 -0.650695" rpy="0 0 0"/>
    <geometry>
      <mesh filename="package://onyx_description/meshes/new_hd/link_4_1.stl" scale="0.001 0.001 0.001"/>
    </geometry>
  </collision>
</link>

<link name="hd_link5">
  <inertial>
    <origin xyz="0.08406378219626617 0.021222804231640358 0.04052714111106276" rpy="0 0 0"/>
    <mass value="13.941603234564111"/>
    <inertia ixx="0.036907" iyy="0.037003" izz="0.04958" ixy="-0.010349" iyz="-0.002873" ixz="-0.006458"/>
  </inertial>
  <visual>
    <origin xyz="-0.030684 -0.519236 -0.405724" rpy="0 0 0"/>
    <geometry>
      <mesh filename="package://onyx_description/meshes/new_hd/link_5_1.stl" scale="0.001 0.001 0.001"/>
    </geometry>
    <material name="silver"/>
  </visual>
  <collision>
    <origin xyz="-0.030684 -0.519236 -0.405724" rpy="0 0 0"/>
    <geometry>
      <mesh filename="package://onyx_description/meshes/new_hd/link_5_1.stl" scale="0.001 0.001 0.001"/>
    </geometry>
  </collision>
</link>

<link name="hd_link6">
  <inertial>
    <origin xyz="0.0068379243827132175 0.05694988563890202 -0.006998024700884231" rpy="0 0 0"/>
    <mass value="1.7329993951645233"/>
    <inertia ixx="0.003586" iyy="0.002091" izz="0.002336" ixy="-0.000155" iyz="-9e-06" ixz="0.000189"/>
  </inertial>
  <visual>
    <origin xyz="-0.148761 -0.629862 -0.449364" rpy="0 0 0"/>
    <geometry>
      <mesh filename="package://onyx_description/meshes/new_hd/link_6_1.stl" scale="0.001 0.001 0.001"/>
    </geometry>
    <material name="silver"/>
  </visual>
  <collision>
    <origin xyz="-0.148761 -0.629862 -0.449364" rpy="0 0 0"/>
    <geometry>
      <mesh filename="package://onyx_description/meshes/new_hd/link_6_1.stl" scale="0.001 0.001 0.001"/>
    </geometry>
  </collision>
</link>

<link name="Gripper_Arcs_v1_1">
  <inertial>
    <origin xyz="0.0032046409818504706 0.02179918196608699 -0.0327963271004742" rpy="0 0 0"/>
    <mass value="0.11098435196969862"/>
    <inertia ixx="0.000116" iyy="2.6e-05" izz="9.6e-05" ixy="-1.4e-05" iyz="3e-05" ixz="6e-06"/>
  </inertial>
  <visual>
    <origin xyz="-0.139762 -0.725909 -0.421506" rpy="0 0 0"/>
    <geometry>
      <mesh filename="package://onyx_description/meshes/new_hd/Gripper_Arcs_v1_1.stl" scale="0.001 0.001 0.001"/>
    </geometry>
    <material name="silver"/>
  </visual>
  <collision>
    <origin xyz="-0.139762 -0.725909 -0.421506" rpy="0 0 0"/>
    <geometry>
      <mesh filename="package://onyx_description/meshes/new_hd/Gripper_Arcs_v1_1.stl" scale="0.001 0.001 0.001"/>
    </geometry>
  </collision>
</link>

<link name="Gripper_Finger_v1_1">
  <inertial>
    <origin xyz="0.023381449181451852 -0.0033549268355534956 -0.005946789572352451" rpy="0 0 0"/>
    <mass value="0.21136162569656056"/>
    <inertia ixx="3.7e-05" iyy="5.6e-05" izz="3.4e-05" ixy="2e-06" iyz="-2e-06" ixz="0.0"/>
  </inertial>
  <visual>
    <origin xyz="-0.153478 -0.800615 -0.379727" rpy="0 0 0"/>
    <geometry>
      <mesh filename="package://onyx_description/meshes/new_hd/Gripper_Finger_v1_1.stl" scale="0.001 0.001 0.001"/>
    </geometry>
    <material name="silver"/>
  </visual>
  <collision>
    <origin xyz="-0.153478 -0.800615 -0.379727" rpy="0 0 0"/>
    <geometry>
      <mesh filename="package://onyx_description/meshes/new_hd/Gripper_Finger_v1_1.stl" scale="0.001 0.001 0.001"/>
    </geometry>
  </collision>
</link>

<link name="Gripper_Arcs_v1__2__1">
  <inertial>
    <origin xyz="-0.0037295922171562967 0.03252274690034984 0.022124051579247295" rpy="0 0 0"/>
    <mass value="0.11098435196969862"/>
    <inertia ixx="0.000117" iyy="1.3e-05" izz="0.000107" ixy="-1.1e-05" iyz="-0.0" ixz="2e-06"/>
  </inertial>
  <visual>
    <origin xyz="-0.135804 -0.729418 -0.451036" rpy="0 0 0"/>
    <geometry>
      <mesh filename="package://onyx_description/meshes/new_hd/Gripper_Arcs_v1__2__1.stl" scale="0.001 0.001 0.001"/>
    </geometry>
    <material name="silver"/>
  </visual>
  <collision>
    <origin xyz="-0.135804 -0.729418 -0.451036" rpy="0 0 0"/>
    <geometry>
      <mesh filename="package://onyx_description/meshes/new_hd/Gripper_Arcs_v1__2__1.stl" scale="0.001 0.001 0.001"/>
    </geometry>
  </collision>
</link>

<link name="Gripper_Finger_v1__1__1">
  <inertial>
    <origin xyz="0.020918878059417806 -0.0011722824247640817 0.012422973814116889" rpy="0 0 0"/>
    <mass value="0.21136162569656056"/>
    <inertia ixx="3.7e-05" iyy="5.6e-05" izz="3.4e-05" ixy="2e-06" iyz="-2e-06" ixz="0.0"/>
  </inertial>
  <visual>
    <origin xyz="-0.142591 -0.81484 -0.464138" rpy="0 0 0"/>
    <geometry>
      <mesh filename="package://onyx_description/meshes/new_hd/Gripper_Finger_v1__1__1.stl" scale="0.001 0.001 0.001"/>
    </geometry>
    <material name="silver"/>
  </visual>
  <collision>
    <origin xyz="-0.142591 -0.81484 -0.464138" rpy="0 0 0"/>
    <geometry>
      <mesh filename="package://onyx_description/meshes/new_hd/Gripper_Finger_v1__1__1.stl" scale="0.001 0.001 0.001"/>
    </geometry>
  </collision>
</link>

<joint name="hd_joint1" type="continuous">
  <!-- <origin xyz="0.007012 0.143312 0.484988" rpy="0 0 0"/> -->
  <origin xyz="0 0 0" rpy="${pi/2} 0 -1.091427"/>
  <parent link="base"/>
  <child link="hd_link1"/>
  <axis xyz="0 1 0"/> 
</joint>

<joint name="hd_joint2" type="continuous">
  <origin xyz="0.104169 0.1185 0.056489" rpy="0 0 0"/>
  <parent link="hd_link1"/>
  <child link="hd_link2"/>
  <axis xyz="0.879067 0.0 0.476699"/>
</joint>
<!-- [ x: -0.8207109, y: 0.1795091, z: -0.4079707 ] -->

<joint name="hd_joint3" type="continuous">
  <origin xyz="-0.14594 0.209699 0.269123" rpy="0 0 0"/>
  <parent link="hd_link2"/>
  <child link="hd_link3"/>
  <axis xyz="-0.879067 -0.0 -0.476699"/>
</joint>

<joint name="hd_joint4" type="continuous">
  <origin xyz="-0.048089 0.014221 -0.159905" rpy="0 0 0"/>
  <parent link="hd_link3"/>
  <child link="hd_link4"/>
  <axis xyz="0.473254 0.120008 -0.872713"/>
</joint>

<joint name="hd_joint5" type="continuous">
  <origin xyz="0.113532 0.033504 -0.244971" rpy="0 0 0"/>
  <parent link="hd_link4"/>
  <child link="hd_link5"/>
  <axis xyz="0.880882 -0.054511 0.470187"/>
</joint>

<joint name="hd_joint6" type="continuous">
  <origin xyz="0.118077 0.110626 0.04364" rpy="0 0 0"/>
  <parent link="hd_link5"/>
  <child link="hd_link6"/>
  <axis xyz="0.115545 0.98806 -0.101919"/>
</joint>

<joint name="hd_joint7" type="fixed">
  <origin xyz="-0.008999 0.096047 -0.027858" rpy="0 0 0"/>
  <parent link="hd_link6"/>
  <child link="Gripper_Arcs_v1_1"/>
  <axis xyz="-0.9845 0.100287 -0.14388"/>
</joint>

<joint name="hd_joint8" type="fixed">
  <origin xyz="0.013716 0.074706 -0.041779" rpy="0 0 0"/>
  <parent link="Gripper_Arcs_v1_1"/>
  <child link="Gripper_Finger_v1_1"/>
  <axis xyz="0.9845 -0.100287 0.14388"/>
</joint>

<joint name="hd_joint9" type="fixed">
  <origin xyz="-0.012957 0.099556 0.001672" rpy="0 0 0"/>
  <parent link="hd_link6"/>
  <child link="Gripper_Arcs_v1__2__1"/>
  <axis xyz="-0.9845 0.100287 -0.14388"/>
</joint>

<joint name="hd_joint10" type="fixed">
  <origin xyz="0.006787 0.085422 0.013102" rpy="0 0 0"/>
  <parent link="Gripper_Arcs_v1__2__1"/>
  <child link="Gripper_Finger_v1__1__1"/>
  <axis xyz="0.9845 -0.100287 0.14388"/>
</joint>

</robot>
