<?xml version="1.0" ?>
<!-- =================================================================================== -->
<!-- |    This document was autogenerated by xacro from kerby.urdf.xacro               | -->
<!-- |    EDITING THIS FILE BY HAND IS NOT RECOMMENDED                                 | -->
<!-- =================================================================================== -->
<robot name="kerby">
  <material name="silver">
    <color rgba="0.700 0.700 0.700 1.000"/>
  </material>
  <material name="black">
    <color rgba="0.1 0.1 0.1 1.000"/>
  </material>
  <material name="white">
    <color rgba="1 1 1 1.000"/>
  </material>
  <material name="pink">
    <!-- <color rgba="1 0.4117 0.70588 1.000"/> -->
    <color rgba="1 1 1 1.000"/>
  </material>
  <material name="blue">
    <color rgba="0 0 0.5 1.000"/>
  </material>
  <transmission name="steering1_tran">
    <type>transmission_interface/SimpleTransmission</type>
    <joint name="steering1">
      <hardwareInterface>hardware_interface/EffortJointInterface</hardwareInterface>
    </joint>
    <actuator name="steering1_actr">
      <hardwareInterface>hardware_interface/EffortJointInterface</hardwareInterface>
      <mechanicalReduction>1</mechanicalReduction>
    </actuator>
  </transmission>
  <transmission name="steering2_tran">
    <type>transmission_interface/SimpleTransmission</type>
    <joint name="steering2">
      <hardwareInterface>hardware_interface/EffortJointInterface</hardwareInterface>
    </joint>
    <actuator name="steering2_actr">
      <hardwareInterface>hardware_interface/EffortJointInterface</hardwareInterface>
      <mechanicalReduction>1</mechanicalReduction>
    </actuator>
  </transmission>
  <transmission name="steering3_tran">
    <type>transmission_interface/SimpleTransmission</type>
    <joint name="steering3">
      <hardwareInterface>hardware_interface/EffortJointInterface</hardwareInterface>
    </joint>
    <actuator name="steering3_actr">
      <hardwareInterface>hardware_interface/EffortJointInterface</hardwareInterface>
      <mechanicalReduction>1</mechanicalReduction>
    </actuator>
  </transmission>
  <transmission name="steering4_tran">
    <type>transmission_interface/SimpleTransmission</type>
    <joint name="steering4">
      <hardwareInterface>hardware_interface/EffortJointInterface</hardwareInterface>
    </joint>
    <actuator name="steering4_actr">
      <hardwareInterface>hardware_interface/EffortJointInterface</hardwareInterface>
      <mechanicalReduction>1</mechanicalReduction>
    </actuator>
  </transmission>
  <transmission name="driving4_tran">
    <type>transmission_interface/SimpleTransmission</type>
    <joint name="driving4">
      <hardwareInterface>hardware_interface/EffortJointInterface</hardwareInterface>
    </joint>
    <actuator name="driving4_actr">
      <hardwareInterface>hardware_interface/EffortJointInterface</hardwareInterface>
      <mechanicalReduction>1</mechanicalReduction>
    </actuator>
  </transmission>
  <transmission name="driving1_tran">
    <type>transmission_interface/SimpleTransmission</type>
    <joint name="driving1">
      <hardwareInterface>hardware_interface/EffortJointInterface</hardwareInterface>
    </joint>
    <actuator name="driving1_actr">
      <hardwareInterface>hardware_interface/EffortJointInterface</hardwareInterface>
      <mechanicalReduction>1</mechanicalReduction>
    </actuator>
  </transmission>
  <transmission name="driving3_tran">
    <type>transmission_interface/SimpleTransmission</type>
    <joint name="driving3">
      <hardwareInterface>hardware_interface/EffortJointInterface</hardwareInterface>
    </joint>
    <actuator name="driving3_actr">
      <hardwareInterface>hardware_interface/EffortJointInterface</hardwareInterface>
      <mechanicalReduction>1</mechanicalReduction>
    </actuator>
  </transmission>
  <transmission name="driving2_tran">
    <type>transmission_interface/SimpleTransmission</type>
    <joint name="driving2">
      <hardwareInterface>hardware_interface/EffortJointInterface</hardwareInterface>
    </joint>
    <actuator name="driving2_actr">
      <hardwareInterface>hardware_interface/EffortJointInterface</hardwareInterface>
      <mechanicalReduction>1</mechanicalReduction>
    </actuator>
  </transmission>
  <transmission name="joint2_tran">
    <type>transmission_interface/SimpleTransmission</type>
    <joint name="joint2">
      <hardwareInterface>hardware_interface/EffortJointInterface</hardwareInterface>
    </joint>
    <actuator name="joint2_actr">
      <hardwareInterface>hardware_interface/EffortJointInterface</hardwareInterface>
      <mechanicalReduction>1</mechanicalReduction>
    </actuator>
  </transmission>
  <transmission name="joint3_tran">
    <type>transmission_interface/SimpleTransmission</type>
    <joint name="joint3">
      <hardwareInterface>hardware_interface/EffortJointInterface</hardwareInterface>
    </joint>
    <actuator name="joint3_actr">
      <hardwareInterface>hardware_interface/EffortJointInterface</hardwareInterface>
      <mechanicalReduction>1</mechanicalReduction>
    </actuator>
  </transmission>
  <transmission name="joint4_tran">
    <type>transmission_interface/SimpleTransmission</type>
    <joint name="joint4">
      <hardwareInterface>hardware_interface/EffortJointInterface</hardwareInterface>
    </joint>
    <actuator name="joint4_actr">
      <hardwareInterface>hardware_interface/EffortJointInterface</hardwareInterface>
      <mechanicalReduction>1</mechanicalReduction>
    </actuator>
  </transmission>
  <transmission name="joint5_tran">
    <type>transmission_interface/SimpleTransmission</type>
    <joint name="joint5">
      <hardwareInterface>hardware_interface/EffortJointInterface</hardwareInterface>
    </joint>
    <actuator name="joint5_actr">
      <hardwareInterface>hardware_interface/EffortJointInterface</hardwareInterface>
      <mechanicalReduction>1</mechanicalReduction>
    </actuator>
  </transmission>
  <transmission name="joint6_tran">
    <type>transmission_interface/SimpleTransmission</type>
    <joint name="joint6">
      <hardwareInterface>hardware_interface/EffortJointInterface</hardwareInterface>
    </joint>
    <actuator name="joint6_actr">
      <hardwareInterface>hardware_interface/EffortJointInterface</hardwareInterface>
      <mechanicalReduction>1</mechanicalReduction>
    </actuator>
  </transmission>
  <transmission name="finger1_tran">
    <type>transmission_interface/SimpleTransmission</type>
    <joint name="finger1">
      <hardwareInterface>hardware_interface/EffortJointInterface</hardwareInterface>
    </joint>
    <actuator name="finger1_actr">
      <hardwareInterface>hardware_interface/EffortJointInterface</hardwareInterface>
      <mechanicalReduction>1</mechanicalReduction>
    </actuator>
  </transmission>
  <transmission name="finger2_tran">
    <type>transmission_interface/SimpleTransmission</type>
    <joint name="finger2">
      <hardwareInterface>hardware_interface/EffortJointInterface</hardwareInterface>
    </joint>
    <actuator name="finger2_actr">
      <hardwareInterface>hardware_interface/EffortJointInterface</hardwareInterface>
      <mechanicalReduction>1</mechanicalReduction>
    </actuator>
  </transmission>
  <transmission name="R�volution 30_tran">
    <type>transmission_interface/SimpleTransmission</type>
    <joint name="R�volution 30">
      <hardwareInterface>hardware_interface/EffortJointInterface</hardwareInterface>
    </joint>
    <actuator name="R�volution 30_actr">
      <hardwareInterface>hardware_interface/EffortJointInterface</hardwareInterface>
      <mechanicalReduction>1</mechanicalReduction>
    </actuator>
  </transmission>
  <transmission name="R�volution 31_tran">
    <type>transmission_interface/SimpleTransmission</type>
    <joint name="R�volution 31">
      <hardwareInterface>hardware_interface/EffortJointInterface</hardwareInterface>
    </joint>
    <actuator name="R�volution 31_actr">
      <hardwareInterface>hardware_interface/EffortJointInterface</hardwareInterface>
      <mechanicalReduction>1</mechanicalReduction>
    </actuator>
  </transmission>
  <transmission name="R�volution 32_tran">
    <type>transmission_interface/SimpleTransmission</type>
    <joint name="R�volution 32">
      <hardwareInterface>hardware_interface/EffortJointInterface</hardwareInterface>
    </joint>
    <actuator name="R�volution 32_actr">
      <hardwareInterface>hardware_interface/EffortJointInterface</hardwareInterface>
      <mechanicalReduction>1</mechanicalReduction>
    </actuator>
  </transmission>
  <gazebo>
    <plugin filename="libgazebo_ros_control.so" name="control"/>
  </gazebo>
  <gazebo reference="base_link">
    <material>Gazebo/Silver</material>
    <mu1>0.2</mu1>
    <mu2>0.2</mu2>
    <selfCollide>true</selfCollide>
    <gravity>true</gravity>
  </gazebo>
  <gazebo reference="steering_1">
    <material>Gazebo/Silver</material>
    <mu1>0.2</mu1>
    <mu2>0.2</mu2>
    <selfCollide>true</selfCollide>
  </gazebo>
  <gazebo reference="steering_2">
    <material>Gazebo/Silver</material>
    <mu1>0.2</mu1>
    <mu2>0.2</mu2>
    <selfCollide>true</selfCollide>
  </gazebo>
  <gazebo reference="steering_3">
    <material>Gazebo/Silver</material>
    <mu1>0.2</mu1>
    <mu2>0.2</mu2>
    <selfCollide>true</selfCollide>
  </gazebo>
  <gazebo reference="steering_4">
    <material>Gazebo/Silver</material>
    <mu1>0.2</mu1>
    <mu2>0.2</mu2>
    <selfCollide>true</selfCollide>
  </gazebo>
  <gazebo reference="wheel3_1">
    <material>Gazebo/Silver</material>
    <mu1>0.2</mu1>
    <mu2>0.2</mu2>
    <selfCollide>true</selfCollide>
  </gazebo>
  <gazebo reference="wheel4_1">
    <material>Gazebo/Silver</material>
    <mu1>0.2</mu1>
    <mu2>0.2</mu2>
    <selfCollide>true</selfCollide>
  </gazebo>
  <gazebo reference="wheel2_1">
    <material>Gazebo/Silver</material>
    <mu1>0.2</mu1>
    <mu2>0.2</mu2>
    <selfCollide>true</selfCollide>
  </gazebo>
  <gazebo reference="wheel1_1">
    <material>Gazebo/Silver</material>
    <mu1>0.2</mu1>
    <mu2>0.2</mu2>
    <selfCollide>true</selfCollide>
  </gazebo>
  <gazebo reference="hd_link2_1">
    <material>Gazebo/Silver</material>
    <mu1>0.2</mu1>
    <mu2>0.2</mu2>
    <selfCollide>true</selfCollide>
  </gazebo>
  <gazebo reference="hd_link3_1">
    <material>Gazebo/Silver</material>
    <mu1>0.2</mu1>
    <mu2>0.2</mu2>
    <selfCollide>true</selfCollide>
  </gazebo>
  <gazebo reference="hd_link4_1">
    <material>Gazebo/Silver</material>
    <mu1>0.2</mu1>
    <mu2>0.2</mu2>
    <selfCollide>true</selfCollide>
  </gazebo>
  <gazebo reference="hd_link5_1">
    <material>Gazebo/Silver</material>
    <mu1>0.2</mu1>
    <mu2>0.2</mu2>
    <selfCollide>true</selfCollide>
  </gazebo>
  <gazebo reference="hd_link6_1">
    <material>Gazebo/Silver</material>
    <mu1>0.2</mu1>
    <mu2>0.2</mu2>
    <selfCollide>true</selfCollide>
  </gazebo>
  <gazebo reference="hd_finger2_1">
    <material>Gazebo/Silver</material>
    <mu1>0.2</mu1>
    <mu2>0.2</mu2>
    <selfCollide>true</selfCollide>
  </gazebo>
  <gazebo reference="hd_finger1_1">
    <material>Gazebo/Silver</material>
    <mu1>0.2</mu1>
    <mu2>0.2</mu2>
    <selfCollide>true</selfCollide>
  </gazebo>
  <gazebo reference="hd_motor_j3_1">
    <material>Gazebo/Silver</material>
    <mu1>0.2</mu1>
    <mu2>0.2</mu2>
    <selfCollide>true</selfCollide>
  </gazebo>
  <gazebo reference="pivot_droit_1">
    <material>Gazebo/Silver</material>
    <mu1>0.2</mu1>
    <mu2>0.2</mu2>
    <selfCollide>true</selfCollide>
  </gazebo>
  <gazebo reference="pivot_gauche_1">
    <material>Gazebo/Silver</material>
    <mu1>0.2</mu1>
    <mu2>0.2</mu2>
    <selfCollide>true</selfCollide>
  </gazebo>
  <gazebo reference="hd_link1_1">
    <material>Gazebo/Silver</material>
    <mu1>0.2</mu1>
    <mu2>0.2</mu2>
    <selfCollide>true</selfCollide>
  </gazebo>
  <!-- allows to scale all max velocities down at once -->
  <link name="base_link">
    <inertial>
      <origin rpy="0 0 0" xyz="0.05362398614035063 0.01974617698532859 0.037120813316089823"/>
      <mass value="6.257043020156179"/>
      <inertia ixx="0.340644" ixy="0.000337" ixz="-0.092411" iyy="0.466541" iyz="0.00055" izz="0.402706"/>
    </inertial>
    <visual>
      <origin rpy="0 0 0" xyz="0 0 0"/>
      <geometry>
        <mesh filename="package://kerby_description/meshes/base_link.stl" scale="0.001 0.001 0.001"/>
      </geometry>
      <material name="blue"/>
    </visual>
    <collision>
      <origin rpy="0 0 0" xyz="0 0 0"/>
      <geometry>
        <mesh filename="package://kerby_description/meshes/base_link.stl" scale="0.001 0.001 0.001"/>
      </geometry>
    </collision>
  </link>
  <link name="steering_1">
    <inertial>
      <origin rpy="0 0 0" xyz="-0.01189644601781037 -0.036027929982466456 -0.2129618322901442"/>
      <mass value="0.3543584805415501"/>
      <inertia ixx="0.003558" ixy="2e-06" ixz="-0.000178" iyy="0.003121" iyz="-0.000206" izz="0.000562"/>
    </inertial>
    <visual>
      <origin rpy="0 0 0" xyz="-0.421384 -0.393882 0.063562"/>
      <geometry>
        <mesh filename="package://kerby_description/meshes/steering_1.stl" scale="0.001 0.001 0.001"/>
      </geometry>
      <material name="silver"/>
    </visual>
    <collision>
      <origin rpy="0 0 0" xyz="-0.421384 -0.393882 0.063562"/>
      <geometry>
        <mesh filename="package://kerby_description/meshes/steering_1.stl" scale="0.001 0.001 0.001"/>
      </geometry>
    </collision>
  </link>
  <link name="steering_2">
    <inertial>
      <origin rpy="0 0 0" xyz="0.011896575272170529 0.03602765244982159 -0.21296112839152875"/>
      <mass value="0.3543584805415501"/>
      <inertia ixx="0.003558" ixy="2e-06" ixz="0.000178" iyy="0.003121" iyz="0.000206" izz="0.000562"/>
    </inertial>
    <visual>
      <origin rpy="0 0 0" xyz="-0.42341 0.353934 0.012408"/>
      <geometry>
        <mesh filename="package://kerby_description/meshes/steering_2.stl" scale="0.001 0.001 0.001"/>
      </geometry>
      <material name="silver"/>
    </visual>
    <collision>
      <origin rpy="0 0 0" xyz="-0.42341 0.353934 0.012408"/>
      <geometry>
        <mesh filename="package://kerby_description/meshes/steering_2.stl" scale="0.001 0.001 0.001"/>
      </geometry>
    </collision>
  </link>
  <link name="steering_3">
    <inertial>
      <origin rpy="0 0 0" xyz="0.011896795779964109 0.03602765244982109 -0.21296183229014454"/>
      <mass value="0.3543584805415501"/>
      <inertia ixx="0.003558" ixy="2e-06" ixz="0.000178" iyy="0.003121" iyz="0.000206" izz="0.000562"/>
    </inertial>
    <visual>
      <origin rpy="0 0 0" xyz="0.408171 0.353934 0.063562"/>
      <geometry>
        <mesh filename="package://kerby_description/meshes/steering_3.stl" scale="0.001 0.001 0.001"/>
      </geometry>
      <material name="silver"/>
    </visual>
    <collision>
      <origin rpy="0 0 0" xyz="0.408171 0.353934 0.063562"/>
      <geometry>
        <mesh filename="package://kerby_description/meshes/steering_3.stl" scale="0.001 0.001 0.001"/>
      </geometry>
    </collision>
  </link>
  <link name="steering_4">
    <inertial>
      <origin rpy="0 0 0" xyz="-0.011896225510015512 -0.036027929982466234 -0.21296112839152861"/>
      <mass value="0.3543584805415501"/>
      <inertia ixx="0.003558" ixy="2e-06" ixz="-0.000178" iyy="0.003121" iyz="-0.000206" izz="0.000562"/>
    </inertial>
    <visual>
      <origin rpy="0 0 0" xyz="0.410197 -0.393882 0.012408"/>
      <geometry>
        <mesh filename="package://kerby_description/meshes/steering_4.stl" scale="0.001 0.001 0.001"/>
      </geometry>
      <material name="silver"/>
    </visual>
    <collision>
      <origin rpy="0 0 0" xyz="0.410197 -0.393882 0.012408"/>
      <geometry>
        <mesh filename="package://kerby_description/meshes/steering_4.stl" scale="0.001 0.001 0.001"/>
      </geometry>
    </collision>
  </link>
  <link name="wheel3_1">
    <inertial>
      <origin rpy="0 0 0" xyz="0.0003394916280188287 -0.010196510227617639 -2.006330920018007e-05"/>
      <mass value="1.592763813314383"/>
      <inertia ixx="0.010896" ixy="-0.000257" ixz="-0.0" iyy="0.018605" iyz="1.6e-05" izz="0.010887"/>
    </inertial>
    <visual>
      <origin rpy="0 0 0" xyz="0.42733 -0.410572 0.281864"/>
      <geometry>
        <mesh filename="package://kerby_description/meshes/wheel3_1.stl" scale="0.001 0.001 0.001"/>
      </geometry>
      <material name="pink"/>
    </visual>
    <collision>
      <origin rpy="0 0 0" xyz="0.42733 -0.410572 0.281864"/>
      <geometry>
        <mesh filename="package://kerby_description/meshes/wheel3_1.stl" scale="0.001 0.001 0.001"/>
      </geometry>
    </collision>
  </link>
  <link name="wheel4_1">
    <inertial>
      <origin rpy="0 0 0" xyz="0.0003392711202230836 -0.010196510227618527 -1.9767207815879484e-05"/>
      <mass value="1.592763813314383"/>
      <inertia ixx="0.010896" ixy="-0.000257" ixz="-0.0" iyy="0.018605" iyz="1.6e-05" izz="0.010887"/>
    </inertial>
    <visual>
      <origin rpy="0 0 0" xyz="-0.404251 -0.410572 0.333019"/>
      <geometry>
        <mesh filename="package://kerby_description/meshes/wheel4_1.stl" scale="0.001 0.001 0.001"/>
      </geometry>
      <material name="pink"/>
    </visual>
    <collision>
      <origin rpy="0 0 0" xyz="-0.404251 -0.410572 0.333019"/>
      <geometry>
        <mesh filename="package://kerby_description/meshes/wheel4_1.stl" scale="0.001 0.001 0.001"/>
      </geometry>
    </collision>
  </link>
  <link name="wheel2_1">
    <inertial>
      <origin rpy="0 0 0" xyz="-0.0003399213580693172 0.010197232694972913 -1.9767207816323573e-05"/>
      <mass value="1.592763813314383"/>
      <inertia ixx="0.010896" ixy="-0.000257" ixz="0.0" iyy="0.018605" iyz="-1.6e-05" izz="0.010887"/>
    </inertial>
    <visual>
      <origin rpy="0 0 0" xyz="0.391037 0.370625 0.333019"/>
      <geometry>
        <mesh filename="package://kerby_description/meshes/wheel2_1.stl" scale="0.001 0.001 0.001"/>
      </geometry>
      <material name="pink"/>
    </visual>
    <collision>
      <origin rpy="0 0 0" xyz="0.391037 0.370625 0.333019"/>
      <geometry>
        <mesh filename="package://kerby_description/meshes/wheel2_1.stl" scale="0.001 0.001 0.001"/>
      </geometry>
    </collision>
  </link>
  <link name="wheel1_1">
    <inertial>
      <origin rpy="0 0 0" xyz="-0.0003391418658636458 0.010197232694973468 -2.0063309200568646e-05"/>
      <mass value="1.592763813314383"/>
      <inertia ixx="0.010896" ixy="-0.000257" ixz="0.0" iyy="0.018605" iyz="-1.6e-05" izz="0.010887"/>
    </inertial>
    <visual>
      <origin rpy="0 0 0" xyz="-0.440543 0.370625 0.281864"/>
      <geometry>
        <mesh filename="package://kerby_description/meshes/wheel1_1.stl" scale="0.001 0.001 0.001"/>
      </geometry>
      <material name="pink"/>
    </visual>
    <collision>
      <origin rpy="0 0 0" xyz="-0.440543 0.370625 0.281864"/>
      <geometry>
        <mesh filename="package://kerby_description/meshes/wheel1_1.stl" scale="0.001 0.001 0.001"/>
      </geometry>
    </collision>
  </link>
  <link name="hd_link2_1">
    <inertial>
      <origin rpy="0 0 0" xyz="0.007428383283974271 0.060838810370171845 0.14389716626077925"/>
      <mass value="2.4452075265656514"/>
      <inertia ixx="0.038674" ixy="7.8e-05" ixz="-0.00107" iyy="0.03827" iyz="0.001607" izz="0.003075"/>
    </inertial>
    <visual>
      <origin rpy="0 0 0" xyz="0.228643 0.037726 -0.152484"/>
      <geometry>
        <mesh filename="package://kerby_description/meshes/hd_link2_1.stl" scale="0.001 0.001 0.001"/>
      </geometry>
      <material name="black"/>
    </visual>
    <collision>
      <origin rpy="0 0 0" xyz="0.228643 0.037726 -0.152484"/>
      <geometry>
        <mesh filename="package://kerby_description/meshes/hd_link2_1.stl" scale="0.001 0.001 0.001"/>
      </geometry>
    </collision>
  </link>
  <link name="hd_link3_1">
    <inertial>
      <origin rpy="0 0 0" xyz="-0.18506431602380205 -0.028188690485378982 0.03515465538516083"/>
      <mass value="0.3993227194340243"/>
      <inertia ixx="0.000842" ixy="4.5e-05" ixz="0.000238" iyy="0.00625" iyz="-5e-06" izz="0.00637"/>
    </inertial>
    <visual>
      <origin rpy="0 0 0" xyz="0.2165 -0.050274 -0.552396"/>
      <geometry>
        <mesh filename="package://kerby_description/meshes/hd_link3_1.stl" scale="0.001 0.001 0.001"/>
      </geometry>
      <material name="black"/>
    </visual>
    <collision>
      <origin rpy="0 0 0" xyz="0.2165 -0.050274 -0.552396"/>
      <geometry>
        <mesh filename="package://kerby_description/meshes/hd_link3_1.stl" scale="0.001 0.001 0.001"/>
      </geometry>
    </collision>
  </link>
  <link name="hd_link4_1">
    <inertial>
      <origin rpy="0 0 0" xyz="-0.02651321084424607 0.002896584112952065 -0.0003217450612928996"/>
      <mass value="0.16590781468918114"/>
      <inertia ixx="0.000197" ixy="3.9e-05" ixz="4e-06" iyy="0.000349" iyz="5e-06" izz="0.000476"/>
    </inertial>
    <visual>
      <origin rpy="0 0 0" xyz="0.531508 -0.02063 -0.590536"/>
      <geometry>
        <mesh filename="package://kerby_description/meshes/hd_link4_1.stl" scale="0.001 0.001 0.001"/>
      </geometry>
      <material name="silver"/>
    </visual>
    <collision>
      <origin rpy="0 0 0" xyz="0.531508 -0.02063 -0.590536"/>
      <geometry>
        <mesh filename="package://kerby_description/meshes/hd_link4_1.stl" scale="0.001 0.001 0.001"/>
      </geometry>
    </collision>
  </link>
  <link name="hd_link5_1">
    <inertial>
      <origin rpy="0 0 0" xyz="-0.0032697164246294763 0.03846028201984416 -9.33050693235904e-05"/>
      <mass value="0.06877842327462745"/>
      <inertia ixx="4.9e-05" ixy="1e-06" ixz="-0.0" iyy="2.9e-05" iyz="0.0" izz="4.3e-05"/>
    </inertial>
    <visual>
      <origin rpy="0 0 0" xyz="0.625201 0.02137 -0.591679"/>
      <geometry>
        <mesh filename="package://kerby_description/meshes/hd_link5_1.stl" scale="0.001 0.001 0.001"/>
      </geometry>
      <material name="silver"/>
    </visual>
    <collision>
      <origin rpy="0 0 0" xyz="0.625201 0.02137 -0.591679"/>
      <geometry>
        <mesh filename="package://kerby_description/meshes/hd_link5_1.stl" scale="0.001 0.001 0.001"/>
      </geometry>
    </collision>
  </link>
  <link name="hd_link6_1">
    <inertial>
      <origin rpy="0 0 0" xyz="-0.03519419436746607 -0.0007187354689699374 0.0009221743273718497"/>
      <mass value="0.11153016933793788"/>
      <inertia ixx="0.000117" ixy="-2e-06" ixz="1e-06" iyy="0.000166" iyz="-1e-06" izz="0.000263"/>
    </inertial>
    <visual>
      <origin rpy="0 0 0" xyz="0.652201 -0.02059 -0.591797"/>
      <geometry>
        <mesh filename="package://kerby_description/meshes/hd_link6_1.stl" scale="0.001 0.001 0.001"/>
      </geometry>
      <material name="silver"/>
    </visual>
    <collision>
      <origin rpy="0 0 0" xyz="0.652201 -0.02059 -0.591797"/>
      <geometry>
        <mesh filename="package://kerby_description/meshes/hd_link6_1.stl" scale="0.001 0.001 0.001"/>
      </geometry>
    </collision>
  </link>
  <link name="hd_finger2_1">
    <inertial>
      <origin rpy="0 0 0" xyz="0.47666706754454413 -0.7361417133269437 -0.01622358994727202"/>
      <mass value="0.025342855198124774"/>
      <inertia ixx="4e-06" ixy="-2e-06" ixz="-2e-06" iyy="1.8e-05" iyz="-0.0" izz="1.6e-05"/>
    </inertial>
    <visual>
      <origin rpy="0 0 0" xyz="1.231487 -0.764267 -0.611515"/>
      <geometry>
        <mesh filename="package://kerby_description/meshes/hd_finger2_1.stl" scale="0.001 0.001 0.001"/>
      </geometry>
      <material name="silver"/>
    </visual>
    <collision>
      <origin rpy="0 0 0" xyz="1.231487 -0.764267 -0.611515"/>
      <geometry>
        <mesh filename="package://kerby_description/meshes/hd_finger2_1.stl" scale="0.001 0.001 0.001"/>
      </geometry>
    </collision>
  </link>
  <link name="hd_finger1_1">
    <inertial>
      <origin rpy="0 0 0" xyz="0.4527983426832546 -0.7504874421753438 -0.06638458975098571"/>
      <mass value="0.025342855198124774"/>
      <inertia ixx="4e-06" ixy="2e-06" ixz="2e-06" iyy="1.8e-05" iyz="-0.0" izz="1.6e-05"/>
    </inertial>
    <visual>
      <origin rpy="0 0 0" xyz="1.208101 -0.764188 -0.655601"/>
      <geometry>
        <mesh filename="package://kerby_description/meshes/hd_finger1_1.stl" scale="0.001 0.001 0.001"/>
      </geometry>
      <material name="silver"/>
    </visual>
    <collision>
      <origin rpy="0 0 0" xyz="1.208101 -0.764188 -0.655601"/>
      <geometry>
        <mesh filename="package://kerby_description/meshes/hd_finger1_1.stl" scale="0.001 0.001 0.001"/>
      </geometry>
    </collision>
  </link>
  <link name="hd_motor_j3_1">
    <inertial>
      <origin rpy="0 0 0" xyz="-0.3146867524268133 0.14188869096939155 0.25591208107402835"/>
      <mass value="0.11925838600046076"/>
      <inertia ixx="0.00051" ixy="-0.0" ixz="-8.7e-05" iyy="0.000525" iyz="-0.0" izz="2.9e-05"/>
    </inertial>
    <visual>
      <origin rpy="0 0 0" xyz="-0.173508 0.122615 -0.149258"/>
      <geometry>
        <mesh filename="package://kerby_description/meshes/hd_motor_j3_1.stl" scale="0.001 0.001 0.001"/>
      </geometry>
      <material name="silver"/>
    </visual>
    <collision>
      <origin rpy="0 0 0" xyz="-0.173508 0.122615 -0.149258"/>
      <geometry>
        <mesh filename="package://kerby_description/meshes/hd_motor_j3_1.stl" scale="0.001 0.001 0.001"/>
      </geometry>
    </collision>
  </link>
  <link name="pivot_droit_1">
    <inertial>
      <origin rpy="0 0 0" xyz="0.0009668399350314201 0.11623489359260658 0.013375805290350871"/>
      <mass value="1.6615144825592312"/>
      <inertia ixx="0.007103" ixy="-5.6e-05" ixz="0.013196" iyy="0.220618" iyz="-0.000815" izz="0.220639"/>
    </inertial>
    <visual>
      <origin rpy="0 0 0" xyz="-0.006607 -0.250474 0.021516"/>
      <geometry>
        <mesh filename="package://kerby_description/meshes/pivot_droit_1.stl" scale="0.001 0.001 0.001"/>
      </geometry>
      <material name="black"/>
    </visual>
    <collision>
      <origin rpy="0 0 0" xyz="-0.006607 -0.250474 0.021516"/>
      <geometry>
        <mesh filename="package://kerby_description/meshes/pivot_droit_1.stl" scale="0.001 0.001 0.001"/>
      </geometry>
    </collision>
  </link>
  <link name="pivot_gauche_1">
    <inertial>
      <origin rpy="0 0 0" xyz="-0.0009674901728771402 -0.11623517112525206 0.013375805290350576"/>
      <mass value="1.6615144825592312"/>
      <inertia ixx="0.007103" ixy="-5.6e-05" ixz="-0.013196" iyy="0.220618" iyz="0.000815" izz="0.220639"/>
    </inertial>
    <visual>
      <origin rpy="0 0 0" xyz="-0.006607 0.210526 0.021516"/>
      <geometry>
        <mesh filename="package://kerby_description/meshes/pivot_gauche_1.stl" scale="0.001 0.001 0.001"/>
      </geometry>
      <material name="black"/>
    </visual>
    <collision>
      <origin rpy="0 0 0" xyz="-0.006607 0.210526 0.021516"/>
      <geometry>
        <mesh filename="package://kerby_description/meshes/pivot_gauche_1.stl" scale="0.001 0.001 0.001"/>
      </geometry>
    </collision>
  </link>
  <link name="hd_link1_1">
    <inertial>
      <origin rpy="0 0 0" xyz="0.0001907779404468346 0.014210297972432132 0.0484216801173539"/>
      <mass value="0.3391136619658369"/>
      <inertia ixx="0.001801" ixy="1e-05" ixz="-8e-06" iyy="0.001217" iyz="-0.000142" izz="0.00078"/>
    </inertial>
    <visual>
      <origin rpy="0 0 0" xyz="0.228643 -0.019974 -0.035484"/>
      <geometry>
        <mesh filename="package://kerby_description/meshes/hd_link1_1.stl" scale="0.001 0.001 0.001"/>
      </geometry>
      <material name="silver"/>
    </visual>
    <collision>
      <origin rpy="0 0 0" xyz="0.228643 -0.019974 -0.035484"/>
      <geometry>
        <mesh filename="package://kerby_description/meshes/hd_link1_1.stl" scale="0.001 0.001 0.001"/>
      </geometry>
    </collision>
  </link>
  <joint name="steering1" type="continuous">
    <origin rpy="0 0 0" xyz="0.414777 0.143408 -0.042046"/>
    <parent link="pivot_droit_1"/>
    <child link="steering_1"/>
    <axis xyz="-0.061399 0.0 -0.998113"/>
  </joint>
  <joint name="steering2" type="continuous">
    <origin rpy="0 0 0" xyz="0.416803 -0.143408 0.009108"/>
    <parent link="pivot_gauche_1"/>
    <child link="steering_2"/>
    <axis xyz="-0.061399 0.0 0.998113"/>
  </joint>
  <joint name="steering3" type="continuous">
    <origin rpy="0 0 0" xyz="-0.414778 -0.143408 -0.042046"/>
    <parent link="pivot_gauche_1"/>
    <child link="steering_3"/>
    <axis xyz="0.061399 -0.0 -0.998113"/>
  </joint>
  <joint name="steering4" type="continuous">
    <origin rpy="0 0 0" xyz="-0.416804 0.143408 0.009108"/>
    <parent link="pivot_droit_1"/>
    <child link="steering_4"/>
    <axis xyz="0.061399 -0.0 0.998113"/>
  </joint>
  <joint name="driving4" type="continuous">
    <origin rpy="0 0 0" xyz="-0.017133 0.01669 -0.269456"/>
    <parent link="steering_4"/>
    <child link="wheel3_1"/>
    <axis xyz="-0.033267 0.999444 0.002046"/>
  </joint>
  <joint name="driving1" type="continuous">
    <origin rpy="0 0 0" xyz="-0.017133 0.01669 -0.269457"/>
    <parent link="steering_1"/>
    <child link="wheel4_1"/>
    <axis xyz="-0.033267 0.999444 0.002046"/>
  </joint>
  <joint name="driving3" type="continuous">
    <origin rpy="0 0 0" xyz="0.017134 -0.016691 -0.269457"/>
    <parent link="steering_3"/>
    <child link="wheel2_1"/>
    <axis xyz="0.033267 -0.999444 0.002046"/>
  </joint>
  <joint name="driving2" type="continuous">
    <origin rpy="0 0 0" xyz="0.017133 -0.016691 -0.269456"/>
    <parent link="steering_2"/>
    <child link="wheel1_1"/>
    <axis xyz="0.033267 -0.999444 0.002046"/>
  </joint>
  <joint name="joint2" type="revolute">
    <origin rpy="0 0 0" xyz="0.0 -0.0577 0.117"/>
    <parent link="hd_link1_1"/>
    <child link="hd_link2_1"/>
    <axis xyz="0.0 1.0 0.0"/>
    <limit effort="100.0" lower="-3.141592653589793" upper="1.5707963267948966" velocity="0.10471975511965977"/>
  </joint>
  <joint name="joint3" type="revolute">
    <origin rpy="0 0 0" xyz="0.012143 0.088 0.399912"/>
    <parent link="hd_link2_1"/>
    <child link="hd_link3_1"/>
    <axis xyz="-0.0 1.0 0.0"/>
    <limit effort="100.0" lower="-0.7853981633974483" upper="0.7853981633974483" velocity="0.15707963267948966"/>
  </joint>
  <joint name="joint4" type="revolute">
    <origin rpy="0 0 0" xyz="-0.315008 -0.029644 0.03814"/>
    <parent link="hd_link3_1"/>
    <child link="hd_link4_1"/>
    <axis xyz="0.999926 0.0 -0.012203"/>
    <limit effort="100.0" lower="-6.283185307179586" upper="6.283185307179586" velocity="0.6283185307179586"/>
  </joint>
  <joint name="joint5" type="revolute">
    <origin rpy="0 0 0" xyz="-0.093693 -0.042 0.001143"/>
    <parent link="hd_link4_1"/>
    <child link="hd_link5_1"/>
    <axis xyz="0.0 -1.0 0.0"/>
    <limit effort="100.0" lower="-1.5707963267948966" upper="1.5707963267948966" velocity="0.20943951023931953"/>
  </joint>
  <joint name="joint6" type="revolute">
    <origin rpy="0 0 0" xyz="-0.027 0.04196 0.000118"/>
    <parent link="hd_link5_1"/>
    <child link="hd_link6_1"/>
    <axis xyz="-0.99999 -0.0 0.00438"/>
    <limit effort="100.0" lower="-3.141592653589793" upper="3.141592653589793" velocity="0.6283185307179586"/>
  </joint>
  <joint name="finger1" type="prismatic">
    <origin rpy="0 0 0" xyz="-0.579286 0.743677 0.019718"/>
    <parent link="hd_link6_1"/>
    <child link="hd_finger2_1"/>
    <axis xyz="0.007905 0.999801 0.018314"/>
    <limit effort="100" lower="0.0" upper="0.0" velocity="100"/>
  </joint>
  <joint name="finger2" type="prismatic">
    <origin rpy="0 0 0" xyz="-0.5559 0.743598 0.063804"/>
    <parent link="hd_link6_1"/>
    <child link="hd_finger1_1"/>
    <axis xyz="0.007905 0.999801 0.018314"/>
    <limit effort="100" lower="0.0" upper="0.0" velocity="100"/>
    <mimic joint="finger1" multiplier="-1" offset="0"/>
  </joint>
  <joint name="moteurJ3" type="fixed">
    <origin rpy="0 0 0" xyz="0.402151 -0.084889 -0.003226"/>
    <parent link="hd_link2_1"/>
    <child link="hd_motor_j3_1"/>
  </joint>
  <joint name="pivot_gauche" type="continuous">
    <origin rpy="0 0 0" xyz="0.006607 0.250474 -0.021516"/>
    <parent link="base_link"/>
    <child link="pivot_droit_1"/>
    <axis xyz="-0.0 1.0 0.0"/>
  </joint>
  <joint name="pivot_droit" type="continuous">
    <origin rpy="0 0 0" xyz="0.006607 -0.210526 -0.021516"/>
    <parent link="base_link"/>
    <child link="pivot_gauche_1"/>
    <axis xyz="0.0 1.0 0.0"/>
  </joint>
  <joint name="joint1" type="revolute">
    <origin rpy="0 0 0" xyz="-0.228643 0.019974 0.035484"/>
    <parent link="base_link"/>
    <child link="hd_link1_1"/>
    <axis xyz="-0.0 0.0 -1.0"/>
    <limit effort="100.0" lower="-4.71238898038469" upper="4.71238898038469" velocity="0.3141592653589793"/>
  </joint>
</robot>
