<?xml version="1.0" ?>
<robot name="kerby" xmlns:xacro="http://www.ros.org/wiki/xacro">

<xacro:include filename="$(find kerby_description)/urdf/materials.xacro" />
<xacro:include filename="$(find kerby_description)/urdf/kerby.trans" />
<xacro:include filename="$(find kerby_description)/urdf/kerby.gazebo" />


<xacro:property name="rpm_to_Radps" value="${2*pi/60.0}" />     <!-- rotations per minute to Rad per second conversion -->
<xacro:property name="velocity_scaling" value="10.0" />     <!-- allows to scale all max velocities down at once -->

<xacro:macro name="aaa_joint_limits" params="lower:=0.0 upper:=0.0 velocity:=${rpm_to_Radps} effort:=100.0">
  <limit lower="${lower}" upper="${upper}" velocity="${velocity}" effort="${effort}"/>
</xacro:macro>

<xacro:property name="joint1_limits">
  <xacro:aaa_joint_limits lower="${-1.5*pi}" upper="${1.5*pi}" velocity="${3 * rpm_to_Radps * velocity_scaling}" />
</xacro:property>

<xacro:property name="joint2_limits">
  <xacro:aaa_joint_limits lower="${-pi}" upper="${pi/2}" velocity="${1 * rpm_to_Radps * velocity_scaling}" />
</xacro:property>

<xacro:property name="joint3_limits">
  <xacro:aaa_joint_limits lower="${-pi/4}" upper="${pi/4}" velocity="${1.5 * rpm_to_Radps * velocity_scaling}" />
</xacro:property>

<xacro:property name="joint4_limits">
  <xacro:aaa_joint_limits lower="${-2*pi}" upper="${2*pi}" velocity="${6 * rpm_to_Radps * velocity_scaling}" />
</xacro:property>

<xacro:property name="joint5_limits">
  <xacro:aaa_joint_limits lower="${-pi/2}" upper="${pi/2}" velocity="${2 * rpm_to_Radps * velocity_scaling}" />
</xacro:property>

<xacro:property name="joint6_limits">
  <xacro:aaa_joint_limits lower="${-pi}" upper="${pi}" velocity="${6 * rpm_to_Radps * velocity_scaling}" />
</xacro:property>



<link name="base_link">
  <inertial>
    <origin xyz="0.05362398614035063 0.01974617698532859 0.037120813316089823" rpy="0 0 0"/>
    <mass value="6.257043020156179"/>
    <inertia ixx="0.340644" iyy="0.466541" izz="0.402706" ixy="0.000337" iyz="0.00055" ixz="-0.092411"/>
  </inertial>
  <visual>
    <origin xyz="0 0 0" rpy="0 0 0"/>
    <geometry>
      <mesh filename="package://kerby_description/meshes/base_link.stl" scale="0.001 0.001 0.001"/>
    </geometry>
    <material name="blue"/>
  </visual>
  <collision>
    <origin xyz="0 0 0" rpy="0 0 0"/>
    <geometry>
      <mesh filename="package://kerby_description/meshes/base_link.stl" scale="0.001 0.001 0.001"/>
    </geometry>
  </collision>
</link>

<link name="hd_link2_1">
  <inertial>
    <origin xyz="0.007428383283974271 0.060838810370171845 0.14389716626077925" rpy="0 0 0"/>
    <mass value="2.4452075265656514"/>
    <inertia ixx="0.038674" iyy="0.03827" izz="0.003075" ixy="7.8e-05" iyz="0.001607" ixz="-0.00107"/>
  </inertial>
  <visual>
    <origin xyz="0.228643 0.037726 -0.152484" rpy="0 0 0"/>
    <geometry>
      <mesh filename="package://kerby_description/meshes/hd_link2_1.stl" scale="0.001 0.001 0.001"/>
    </geometry>
    <material name="black"/>
  </visual>
  <collision>
    <origin xyz="0.228643 0.037726 -0.152484" rpy="0 0 0"/>
    <geometry>
      <mesh filename="package://kerby_description/meshes/hd_link2_1.stl" scale="0.001 0.001 0.001"/>
    </geometry>
  </collision>
</link>

<link name="hd_link3_1">
  <inertial>
    <origin xyz="-0.18506431602380205 -0.028188690485378982 0.03515465538516083" rpy="0 0 0"/>
    <mass value="0.3993227194340243"/>
    <inertia ixx="0.000842" iyy="0.00625" izz="0.00637" ixy="4.5e-05" iyz="-5e-06" ixz="0.000238"/>
  </inertial>
  <visual>
    <origin xyz="0.2165 -0.050274 -0.552396" rpy="0 0 0"/>
    <geometry>
      <mesh filename="package://kerby_description/meshes/hd_link3_1.stl" scale="0.001 0.001 0.001"/>
    </geometry>
    <material name="black"/>
  </visual>
  <collision>
    <origin xyz="0.2165 -0.050274 -0.552396" rpy="0 0 0"/>
    <geometry>
      <mesh filename="package://kerby_description/meshes/hd_link3_1.stl" scale="0.001 0.001 0.001"/>
    </geometry>
  </collision>
</link>

<link name="hd_link4_1">
  <inertial>
    <origin xyz="-0.02651321084424607 0.002896584112952065 -0.0003217450612928996" rpy="0 0 0"/>
    <mass value="0.16590781468918114"/>
    <inertia ixx="0.000197" iyy="0.000349" izz="0.000476" ixy="3.9e-05" iyz="5e-06" ixz="4e-06"/>
  </inertial>
  <visual>
    <origin xyz="0.531508 -0.02063 -0.590536" rpy="0 0 0"/>
    <geometry>
      <mesh filename="package://kerby_description/meshes/hd_link4_1.stl" scale="0.001 0.001 0.001"/>
    </geometry>
    <material name="silver"/>
  </visual>
  <collision>
    <origin xyz="0.531508 -0.02063 -0.590536" rpy="0 0 0"/>
    <geometry>
      <mesh filename="package://kerby_description/meshes/hd_link4_1.stl" scale="0.001 0.001 0.001"/>
    </geometry>
  </collision>
</link>

<link name="hd_link5_1">
  <inertial>
    <origin xyz="-0.0032697164246294763 0.03846028201984416 -9.33050693235904e-05" rpy="0 0 0"/>
    <mass value="0.06877842327462745"/>
    <inertia ixx="4.9e-05" iyy="2.9e-05" izz="4.3e-05" ixy="1e-06" iyz="0.0" ixz="-0.0"/>
  </inertial>
  <visual>
    <origin xyz="0.625201 0.02137 -0.591679" rpy="0 0 0"/>
    <geometry>
      <mesh filename="package://kerby_description/meshes/hd_link5_1.stl" scale="0.001 0.001 0.001"/>
    </geometry>
    <material name="silver"/>
  </visual>
  <collision>
    <origin xyz="0.625201 0.02137 -0.591679" rpy="0 0 0"/>
    <geometry>
      <mesh filename="package://kerby_description/meshes/hd_link5_1.stl" scale="0.001 0.001 0.001"/>
    </geometry>
  </collision>
</link>

<link name="hd_link6_1">
  <inertial>
    <origin xyz="-0.03519419436746607 -0.0007187354689699374 0.0009221743273718497" rpy="0 0 0"/>
    <mass value="0.11153016933793788"/>
    <inertia ixx="0.000117" iyy="0.000166" izz="0.000263" ixy="-2e-06" iyz="-1e-06" ixz="1e-06"/>
  </inertial>
  <visual>
    <origin xyz="0.652201 -0.02059 -0.591797" rpy="0 0 0"/>
    <geometry>
      <mesh filename="package://kerby_description/meshes/hd_link6_1.stl" scale="0.001 0.001 0.001"/>
    </geometry>
    <material name="silver"/>
  </visual>
  <collision>
    <origin xyz="0.652201 -0.02059 -0.591797" rpy="0 0 0"/>
    <geometry>
      <mesh filename="package://kerby_description/meshes/hd_link6_1.stl" scale="0.001 0.001 0.001"/>
    </geometry>
  </collision>
</link>

<link name="hd_motor_j3_1">
  <inertial>
    <origin xyz="-0.3146867524268133 0.14188869096939155 0.25591208107402835" rpy="0 0 0"/>
    <mass value="0.11925838600046076"/>
    <inertia ixx="0.00051" iyy="0.000525" izz="2.9e-05" ixy="-0.0" iyz="-0.0" ixz="-8.7e-05"/>
  </inertial>
  <visual>
    <origin xyz="-0.173508 0.122615 -0.149258" rpy="0 0 0"/>
    <geometry>
      <mesh filename="package://kerby_description/meshes/hd_motor_j3_1.stl" scale="0.001 0.001 0.001"/>
    </geometry>
    <material name="silver"/>
  </visual>
  <collision>
    <origin xyz="-0.173508 0.122615 -0.149258" rpy="0 0 0"/>
    <geometry>
      <mesh filename="package://kerby_description/meshes/hd_motor_j3_1.stl" scale="0.001 0.001 0.001"/>
    </geometry>
  </collision>
</link>

<link name="hd_link1_1">
  <inertial>
    <origin xyz="0.0001907779404468346 0.014210297972432132 0.0484216801173539" rpy="0 0 0"/>
    <mass value="0.3391136619658369"/>
    <inertia ixx="0.001801" iyy="0.001217" izz="0.00078" ixy="1e-05" iyz="-0.000142" ixz="-8e-06"/>
  </inertial>
  <visual>
    <origin xyz="0.228643 -0.019974 -0.035484" rpy="0 0 0"/>
    <geometry>
      <mesh filename="package://kerby_description/meshes/hd_link1_1.stl" scale="0.001 0.001 0.001"/>
    </geometry>
    <material name="silver"/>
  </visual>
  <collision>
    <origin xyz="0.228643 -0.019974 -0.035484" rpy="0 0 0"/>
    <geometry>
      <mesh filename="package://kerby_description/meshes/hd_link1_1.stl" scale="0.001 0.001 0.001"/>
    </geometry>
  </collision>
</link>

<!-- <link name="fake_gripper">
  <visual>
    <origin xyz="0.652201 -0.02059 -0.591797" rpy="0 0 0"/>
    <geometry>
      <mesh filename="package://kerby_description/meshes/hd_link6_1.stl" scale="0.001 0.001 0.001"/>
    </geometry>
    <material name="silver"/>
  </visual>
  <collision>
    <origin xyz="0.652201 -0.02059 -0.591797" rpy="0 0 0"/>
    <geometry>
      <mesh filename="package://kerby_description/meshes/hd_link6_1.stl" scale="0.001 0.001 0.001"/>
    </geometry>
  </collision>
</link> -->


<joint name="joint2" type="revolute">
  <origin xyz="0.0 -0.0577 0.117" rpy="0 0 0"/>
  <parent link="hd_link1_1"/>
  <child link="hd_link2_1"/>
  <axis xyz="0.0 1.0 0.0"/>
  <xacro:insert_block name="joint2_limits" />
</joint>

<joint name="joint3" type="revolute">
  <origin xyz="0.012143 0.088 0.399912" rpy="0 0 0"/>
  <parent link="hd_link2_1"/>
  <child link="hd_link3_1"/>
  <axis xyz="-0.0 1.0 0.0"/>
  <xacro:insert_block name="joint3_limits" />
</joint>

<joint name="joint4" type="revolute">
  <origin xyz="-0.315008 -0.029644 0.03814" rpy="0 0 0"/>
  <parent link="hd_link3_1"/>
  <child link="hd_link4_1"/>
  <axis xyz="0.999926 0.0 -0.012203"/>
  <xacro:insert_block name="joint4_limits" />
</joint>

<joint name="joint5" type="revolute">
  <origin xyz="-0.093693 -0.042 0.001143" rpy="0 0 0"/>
  <parent link="hd_link4_1"/>
  <child link="hd_link5_1"/>
  <axis xyz="0.0 -1.0 0.0"/>
  <xacro:insert_block name="joint5_limits" />
</joint>

<joint name="joint6" type="revolute">
  <origin xyz="-0.027 0.04196 0.000118" rpy="0 0 0"/>
  <parent link="hd_link5_1"/>
  <child link="hd_link6_1"/>
  <axis xyz="-0.99999 -0.0 0.00438"/>
  <xacro:insert_block name="joint6_limits" />
</joint>

<joint name="moteurJ3" type="fixed">
  <origin xyz="0.402151 -0.084889 -0.003226" rpy="0 0 0"/>
  <parent link="hd_link2_1"/>
  <child link="hd_motor_j3_1"/>
</joint>

<joint name="joint1" type="revolute">
  <origin xyz="-0.228643 0.019974 0.035484" rpy="0 0 0"/>
  <parent link="base_link"/>
  <child link="hd_link1_1"/>
  <axis xyz="-0.0 0.0 -1.0"/>
  <xacro:insert_block name="joint1_limits" />
</joint>

</robot>
