<?xml version="1.0" ?>
<robot name="URDF3" xmlns:xacro="http://www.ros.org/wiki/xacro">

<xacro:include filename="$(find URDF3_description_old)/urdf/materials.xacro" />
<xacro:include filename="$(find URDF3_description_old)/urdf/URDF3.trans" />
<xacro:include filename="$(find URDF3_description_old)/urdf/URDF3.gazebo" />
<link name="base_link">
  <inertial>
    <origin xyz="0.03184736119847057 0.11611948375996509 0.5257231117475785" rpy="0 0 0"/>
    <mass value="1.001112718637754"/>
    <inertia ixx="0.00171" iyy="0.003332" izz="0.00171" ixy="-0.0" iyz="-0.0" ixz="0.0"/>
  </inertial>
  <visual>
    <origin xyz="0 0 0" rpy="0 0 0"/>
    <geometry>
      <mesh filename="package://URDF3_description_old/meshes/base_link.stl" scale="0.001 0.001 0.001"/>
    </geometry>
    <material name="silver"/>
  </visual>
  <collision>
    <origin xyz="0 0 0" rpy="0 0 0"/>
    <geometry>
      <mesh filename="package://URDF3_description_old/meshes/base_link.stl" scale="0.001 0.001 0.001"/>
    </geometry>
  </collision>
</link>

<link name="link_1_1">
  <inertial>
    <origin xyz="0.023341198278564033 0.09194824498494399 0.012657353235789981" rpy="0 0 0"/>
    <mass value="13.941603234564111"/>
    <inertia ixx="0.039361" iyy="0.035501" izz="0.048628" ixy="-0.009386" iyz="-0.00509" ixz="-0.007119"/>
  </inertial>
  <visual>
    <origin xyz="-0.031847 -0.122344 -0.525723" rpy="0 0 0"/>
    <geometry>
      <mesh filename="package://URDF3_description_old/meshes/link_1_1.stl" scale="0.001 0.001 0.001"/>
    </geometry>
    <material name="silver"/>
  </visual>
  <collision>
    <origin xyz="-0.031847 -0.122344 -0.525723" rpy="0 0 0"/>
    <geometry>
      <mesh filename="package://URDF3_description_old/meshes/link_1_1.stl" scale="0.001 0.001 0.001"/>
    </geometry>
  </collision>
</link>

<link name="link_2_1">
  <inertial>
    <origin xyz="-0.08423236126609454 0.10484933887324938 0.12845475041634613" rpy="0 0 0"/>
    <mass value="3.1130721114751427"/>
    <inertia ixx="0.055243" iyy="0.044626" izz="0.033179" ixy="0.012697" iyz="-0.023414" ixz="0.016949"/>
  </inertial>
  <visual>
    <origin xyz="-0.136017 -0.240844 -0.582212" rpy="0 0 0"/>
    <geometry>
      <mesh filename="package://URDF3_description_old/meshes/link_2_1.stl" scale="0.001 0.001 0.001"/>
    </geometry>
    <material name="silver"/>
  </visual>
  <collision>
    <origin xyz="-0.136017 -0.240844 -0.582212" rpy="0 0 0"/>
    <geometry>
      <mesh filename="package://URDF3_description_old/meshes/link_2_1.stl" scale="0.001 0.001 0.001"/>
    </geometry>
  </collision>
</link>

<!-- link_3_1 -->
<link name="link_3_1">
  <inertial>
    <origin xyz="-0.06826321589803486 0.0031860302353051706 -0.06700391432202124" rpy="0 0 0"/>
    <mass value="13.941603234564111"/>
    <inertia ixx="0.04444" iyy="0.052244" izz="0.026806" ixy="0.000162" iyz="0.00239" ixz="-0.005885"/>
  </inertial>
  <visual>
    <origin xyz="0.009923 -0.450543 -0.851336" rpy="0 0 0"/>
    <geometry>
      <mesh filename="package://URDF3_description_old/meshes/link_2_1.stl" scale="0.001 0.001 0.001"/> 
    </geometry>
    <material name="silver"/>
  </visual>
  <collision>
    <origin xyz="0.009923 -0.450543 -0.851336" rpy="0 0 0"/>
    <geometry>
      <mesh filename="package://URDF3_description_old/meshes/link_2_1.stl" scale="0.001 0.001 0.001"/>
    </geometry>
  </collision>
</link>

<link name="link_4_1">
  <inertial>
    <origin xyz="0.06826857852526715 0.018082704005362826 -0.1317154088631698" rpy="0 0 0"/>
    <mass value="2.3441890740360654"/>
    <inertia ixx="0.022767" iyy="0.026136" izz="0.00899" ixy="-0.001236" iyz="0.002399" ixz="0.009066"/>
  </inertial>
  <visual>
    <origin xyz="0.058012 -0.464764 -0.69143" rpy="0 0 0"/>
    <geometry>
      <mesh filename="package://URDF3_description_old/meshes/link_4_1.stl" scale="0.001 0.001 0.001"/>
    </geometry>
    <material name="silver"/>
  </visual>
  <collision>
    <origin xyz="0.058012 -0.464764 -0.69143" rpy="0 0 0"/>
    <geometry>
      <mesh filename="package://URDF3_description_old/meshes/link_4_1.stl" scale="0.001 0.001 0.001"/>
    </geometry>
  </collision>
</link>

<link name="link_5_1">
  <inertial>
    <origin xyz="0.08406339839369913 0.021222594623964308 0.040526597381842444" rpy="0 0 0"/>
    <mass value="13.941603234564111"/>
    <inertia ixx="0.036907" iyy="0.037003" izz="0.04958" ixy="-0.010349" iyz="-0.002873" ixz="-0.006458"/>
  </inertial>
  <visual>
    <origin xyz="-0.05552 -0.498268 -0.44646" rpy="0 0 0"/>
    <geometry>
      <mesh filename="package://URDF3_description_old/meshes/link_5_1.stl" scale="0.001 0.001 0.001"/>
    </geometry>
    <material name="silver"/>
  </visual>
  <collision>
    <origin xyz="-0.05552 -0.498268 -0.44646" rpy="0 0 0"/>
    <geometry>
      <mesh filename="package://URDF3_description_old/meshes/link_5_1.stl" scale="0.001 0.001 0.001"/>
    </geometry>
  </collision>
</link>

<link name="link_6_1">
  <inertial>
    <origin xyz="0.006837540580146045 0.05695067603122561 -0.006998568430104213" rpy="0 0 0"/>
    <mass value="1.7329993951645233"/>
    <inertia ixx="0.003586" iyy="0.002091" izz="0.002336" ixy="-0.000155" iyz="-9e-06" ixz="0.000189"/>
  </inertial>
  <visual>
    <origin xyz="-0.173597 -0.608893 -0.4901" rpy="0 0 0"/>
    <geometry>
      <mesh filename="package://URDF3_description_old/meshes/link_6_1.stl" scale="0.001 0.001 0.001"/>
    </geometry>
    <material name="silver"/>
  </visual>
  <collision>
    <origin xyz="-0.173597 -0.608893 -0.4901" rpy="0 0 0"/>
    <geometry>
      <mesh filename="package://URDF3_description_old/meshes/link_6_1.stl" scale="0.001 0.001 0.001"/>
    </geometry>
  </collision>
</link>

<link name="link_8_1">
  <inertial>
    <origin xyz="0.0026692345132580397 0.03327415040633053 -0.021137572053926135" rpy="0 0 0"/>
    <mass value="0.11098435196969862"/>
    <inertia ixx="0.000117" iyy="1.4e-05" izz="0.000107" ixy="-1e-05" iyz="-6e-06" ixz="1e-06"/>
  </inertial>
  <visual>
    <origin xyz="-0.164598 -0.704941 -0.462242" rpy="0 0 0"/>
    <geometry>
      <mesh filename="package://URDF3_description_old/meshes/link_8_1.stl" scale="0.001 0.001 0.001"/>
    </geometry>
    <material name="silver"/>
  </visual>
  <collision>
    <origin xyz="-0.164598 -0.704941 -0.462242" rpy="0 0 0"/>
    <geometry>
      <mesh filename="package://URDF3_description_old/meshes/link_8_1.stl" scale="0.001 0.001 0.001"/>
    </geometry>
  </collision>
</link>

<link name="link_9_1">
  <inertial>
    <origin xyz="0.023381811558127963 -0.0033544825244882226 -0.0059474732427042265" rpy="0 0 0"/>
    <mass value="0.21136162569656056"/>
    <inertia ixx="3.7e-05" iyy="5.6e-05" izz="3.4e-05" ixy="2e-06" iyz="-2e-06" ixz="0.0"/>
  </inertial>
  <visual>
    <origin xyz="-0.174456 -0.790723 -0.454577" rpy="0 0 0"/>
    <geometry>
      <mesh filename="package://URDF3_description_old/meshes/link_9_1.stl" scale="0.001 0.001 0.001"/>
    </geometry>
    <material name="silver"/>
  </visual>
  <collision>
    <origin xyz="-0.174456 -0.790723 -0.454577" rpy="0 0 0"/>
    <geometry>
      <mesh filename="package://URDF3_description_old/meshes/link_9_1.stl" scale="0.001 0.001 0.001"/>
    </geometry>
  </collision>
</link>

<link name="link_7_1">
  <inertial>
    <origin xyz="-0.0016395643205586174 0.037769158300166694 0.01148371660438574" rpy="0 0 0"/>
    <mass value="0.11098435196969862"/>
    <inertia ixx="0.000116" iyy="2.3e-05" izz="9.9e-05" ixy="-1.4e-05" iyz="2.6e-05" ixz="6e-06"/>
  </inertial>
  <visual>
    <origin xyz="-0.160639 -0.70845 -0.491772" rpy="0 0 0"/>
    <geometry>
      <mesh filename="package://URDF3_description_old/meshes/link_7_1.stl" scale="0.001 0.001 0.001"/>
    </geometry>
    <material name="silver"/>
  </visual>
  <collision>
    <origin xyz="-0.160639 -0.70845 -0.491772" rpy="0 0 0"/>
    <geometry>
      <mesh filename="package://URDF3_description_old/meshes/link_7_1.stl" scale="0.001 0.001 0.001"/>
    </geometry>
  </collision>
</link>

<link name="link_10_1">
  <inertial>
    <origin xyz="0.02092110031858113 -0.0011584807674569486 0.012421166468737477" rpy="0 0 0"/>
    <mass value="0.21136162569656056"/>
    <inertia ixx="3.7e-05" iyy="5.6e-05" izz="3.4e-05" ixy="2e-06" iyz="-2e-06" ixz="0.0"/>
  </inertial>
  <visual>
    <origin xyz="-0.171225 -0.793474 -0.478602" rpy="0 0 0"/>
    <geometry>
      <mesh filename="package://URDF3_description_old/meshes/link_10_1.stl" scale="0.001 0.001 0.001"/>
    </geometry>
    <material name="silver"/>
  </visual>
  <collision>
    <origin xyz="-0.171225 -0.793474 -0.478602" rpy="0 0 0"/>
    <geometry>
      <mesh filename="package://URDF3_description_old/meshes/link_10_1.stl" scale="0.001 0.001 0.001"/>
    </geometry>
  </collision>
</link>

<joint name="Revolute 23" type="continuous">
  <origin xyz="0.031847 0.122344 0.525723" rpy="0 0 0"/>
  <parent link="base_link"/>
  <child link="link_1_1"/>
  <axis xyz="-0.0 1.0 -0.0"/>
</joint>

<joint name="Revolute 24" type="continuous">
  <origin xyz="0.10417 0.1185 0.056489" rpy="0 0 0"/>
  <parent link="link_1_1"/>
  <child link="link_2_1"/>
  <axis xyz="0.879067 0.0 0.476699"/>
</joint>

<joint name="Revolute 25" type="continuous">
  <origin xyz="-0.14594 0.209699 0.269124" rpy="0 0 0"/>
  <parent link="link_2_1"/>
  <child link="link_3_1"/>
  <axis xyz="-0.879067 -0.0 -0.476699"/>
</joint>

<joint name="Revolute 26" type="continuous">
  <origin xyz="-0.048089 0.014221 -0.159906" rpy="0 0 0"/>
  <parent link="link_3_1"/>
  <child link="link_4_1"/>
  <axis xyz="0.473254 0.120008 -0.872713"/>
</joint>

<joint name="Revolute 27" type="continuous">
  <origin xyz="0.113532 0.033504 -0.24497" rpy="0 0 0"/>
  <parent link="link_4_1"/>
  <child link="link_5_1"/>
  <axis xyz="0.880882 -0.054511 0.470187"/>
</joint>

<joint name="Revolute 28" type="continuous">
  <origin xyz="0.118077 0.110625 0.04364" rpy="0 0 0"/>
  <parent link="link_5_1"/>
  <child link="link_6_1"/>
  <axis xyz="0.115545 0.98806 -0.101919"/>
</joint>

<joint name="Revolute 29" type="continuous">
  <origin xyz="-0.008999 0.096048 -0.027858" rpy="0 0 0"/>
  <parent link="link_6_1"/>
  <child link="link_8_1"/>
  <axis xyz="-0.9845 0.100287 -0.14388"/>
</joint>

<joint name="Revolute 30" type="continuous">
  <origin xyz="0.009858 0.085782 -0.007665" rpy="0 0 0"/>
  <parent link="link_8_1"/>
  <child link="link_9_1"/>
  <axis xyz="-0.9845 0.100287 -0.14388"/>
</joint>

<joint name="Revolute 31" type="continuous">
  <origin xyz="-0.012958 0.099557 0.001672" rpy="0 0 0"/>
  <parent link="link_6_1"/>
  <child link="link_7_1"/>
  <axis xyz="-0.9845 0.100287 -0.14388"/>
</joint>

<joint name="Revolute 32" type="continuous">
  <origin xyz="0.010586 0.085024 -0.01317" rpy="0 0 0"/>
  <parent link="link_7_1"/>
  <child link="link_10_1"/>
  <axis xyz="0.9845 -0.100287 0.14388"/>
</joint>

</robot>
